Workbook

Sheet summary_pivot
A1: model | B1: experiment_id | C1: experiment_name | D1: Label-aware greedy | E1: Label-aware greedy_std | F1: Multilabel stratified (paper-style) | G1: Multilabel stratified (paper-style)_std | H1: Baseline (simple random split) | I1: Baseline (simple random split)_std | J1: Label-aware greedy + Aug | K1: Label-aware greedy + Aug_std | L1: Multilabel stratified (paper-style) + Aug | M1: Multilabel stratified (paper-style) + Aug_std | N1: Baseline (simple random split) + Aug | O1: Baseline (simple random split) + Aug_std | P1: best_f1 | Q1: best_condition
A2: BEREL 3.0 | B2: exp10_svm_ready | C2: SVM Router Fusion CRF (Ready) | D2: 0.78135932 | E2: 0.01594638 | F2: 0.76120338 | G2: 0.023438365 | H2: 0.78419159 | I2: 0.020954917 | J2: 0.87777558 | K2: 0.013409569 | L2: 0.87469151 | M2: 0.010639531 | N2: 0.88735287 | O2: 0.0093084302 | P2: 0.88735287 | Q2: Baseline (simple random split) + Aug
A3: BEREL 3.0 | B3: exp10_cascade | C3: Cascaded Pipeline (CRF + Consistency) | D3: 0.75964719 | E3: 0.069407677 | F3: 0.75881808 | G3: 0.079643434 | H3: 0.72446006 | I3: 0.093579043 | J3: 0.87180197 | K3: 0.011478608 | L3: 0.86411496 | M3: 0.0075925471 | N3: 0.87459376 | O3: 0.0064579804 | P3: 0.87459376 | Q3: Baseline (simple random split) + Aug
A4: AlephBERT-Gimmel | B4: exp10_svm_ready | C4: SVM Router Fusion CRF (Ready) | D4: 0.79729071 | E4: 0.013271656 | F4: 0.74562561 | G4: 0.018327833 | H4: 0.73344026 | I4: 0.011717628 | J4: 0.87398503 | K4: 0.01364935 | L4: 0.87076254 | M4: 0.0084170004 | N4: 0.83574787 | O4: 0.008402729 | P4: 0.87398503 | Q4: Label-aware greedy + Aug
A5: HeRo | B5: exp10_svm_ready | C5: SVM Router Fusion CRF (Ready) | D5: 0.84138366 | E5: 0.018129231 | F5: 0.85371583 | G5: 0.006841639 | H5: 0.82707085 | I5: 0.01168618 | J5: 0.86897547 | K5: 0.010663347 | L5: 0.87369134 | M5: 0.0093822528 | N5: 0.86734539 | O5: 0.014798319 | P5: 0.87369134 | Q5: Multilabel stratified (paper-style) + Aug
A6: DictaBERT | B6: exp10_svm_ready | C6: SVM Router Fusion CRF (Ready) | D6: 0.82665558 | E6: 0.020754616 | F6: 0.82198659 | G6: 0.012943632 | H6: 0.78950032 | I6: 0.010604951 | J6: 0.86890598 | K6: 0.0097520324 | L6: 0.87294791 | M6: 0.010027284 | N6: 0.85225964 | O6: 0.010914019 | P6: 0.87294791 | Q6: Multilabel stratified (paper-style) + Aug
A7: BEREL 3.0 | B7: exp10_fusion_ready | C7: Fusion Regular-CRF + Cascaded-CRF (Ready) | D7: 0.76677714 | E7: 0.021271764 | F7: 0.73836075 | G7: 0.030923184 | H7: 0.74157498 | I7: 0.021460137 | J7: 0.85089554 | K7: 0.014624099 | L7: 0.85564174 | M7: 0.010812009 | N7: 0.8591659 | O7: 0.0095760198 | P7: 0.8591659 | Q7: Baseline (simple random split) + Aug
A8: DictaBERT | B8: exp10_cascade | C8: Cascaded Pipeline (CRF + Consistency) | D8: 0.7904055 | E8: 0.0222464 | F8: 0.79922902 | G8: 0.016694659 | H8: 0.77570969 | I8: 0.013626755 | J8: 0.83971062 | K8: 0.015851245 | L8: 0.85755154 | M8: 0.010822389 | N8: 0.83244357 | O8: 0.0084011973 | P8: 0.85755154 | Q8: Multilabel stratified (paper-style) + Aug
A9: BEREL 3.0 | B9: exp06_svm_ready | C9: SVM Router Fusion (Ready) | D9: 0.78997538 | E9: 0.028101796 | F9: 0.79533462 | G9: 0.030389165 | H9: 0.77142141 | I9: 0.024770366 | J9: 0.84437107 | K9: 0.011922921 | L9: 0.85182051 | M9: 0.0079883507 | N9: 0.85735749 | O9: 0.0077227635 | P9: 0.85735749 | Q9: Baseline (simple random split) + Aug
A10: BEREL 3.0 | B10: exp10_regular | C10: Regular NER (BERT-CRF) | D10: 0.72486772 | E10: 1.1390648e-16 | F10: 0.69601677 | G10: 0 | H10: 0.73061224 | I10: 2.2781296e-16 | J10: 0.83952617 | K10: 0.015894113 | L10: 0.85548025 | M10: 0.012142817 | N10: 0.85595045 | O10: 0.0099128316 | P10: 0.85595045 | Q10: Baseline (simple random split) + Aug
A11: AlephBERT-Gimmel | B11: exp10_cascade | C11: Cascaded Pipeline (CRF + Consistency) | D11: 0.78180777 | E11: 0.011607625 | F11: 0.7530115 | G11: 0.024318848 | H11: 0.73026683 | I11: 0.018493162 | J11: 0.83715432 | K11: 0.011866646 | L11: 0.85494756 | M11: 0.0069781525 | N11: 0.82458479 | O11: 0.009767519 | P11: 0.85494756 | Q11: Multilabel stratified (paper-style) + Aug
A12: HeRo | B12: exp10_cascade | C12: Cascaded Pipeline (CRF + Consistency) | D12: 0.80525442 | E12: 0.014875892 | F12: 0.83146625 | G12: 0.009637587 | H12: 0.78860228 | I12: 0.011503372 | J12: 0.84050667 | K12: 0.015092719 | L12: 0.85487533 | M12: 0.010851851 | N12: 0.84420698 | O12: 0.014640829 | P12: 0.85487533 | Q12: Multilabel stratified (paper-style) + Aug
A13: AlephBERT-Gimmel | B13: exp10_fusion_ready | C13: Fusion Regular-CRF + Cascaded-CRF (Ready) | D13: 0.76802837 | E13: 0.010778955 | F13: 0.71980571 | G13: 0.017308817 | H13: 0.72051773 | I13: 0.013938167 | J13: 0.84029797 | K13: 0.015782132 | L13: 0.8515181 | M13: 0.01010029 | N13: 0.80526015 | O13: 0.0095471939 | P13: 0.8515181 | Q13: Multilabel stratified (paper-style) + Aug
... A37: DictaBERT | B37: exp01 | C37: Regular NER | D37: 0.75409836 | E37: 2.2781296e-16 | F37: 0.73799127 | G37: 3.4171944e-16 | H37: 0.67181552 | I37: 0.011076771 | J37: 0.80152098 | K37: 0.010604771 | L37: 0.8082628 | M37: 0.0097207099 | N37: 0.78054156 | O37: 0.011008323 | P37: 0.8082628 | Q37: Multilabel stratified (paper-style) + Aug

Sheet all_runs
A1: model_key | B1: model_id | C1: model_name | D1: experiment_id | E1: experiment_name | F1: data_source | G1: condition_key | H1: condition_group_key | I1: condition_group_short | J1: condition_label | K1: condition_short | L1: condition_description | M1: seed | N1: is_baseline | O1: f1 | P1: precision | Q1: recall | R1: status | S1: result_file | T1: metrics_file | U1: base_artifacts_reused | V1: base_mode | W1: elapsed_seconds
A2: dictabert | B2: dicta-il/dictabert | C2: DictaBERT | D2: exp01 | E2: Regular NER | F2: exp07 | G2: exp07_before_exp01_baseline__seed42 | H2: exp07_before_exp01_baseline | I2: Baseline (simple random split) | J2: [Exp07] Baseline (simple random split) [seed 42] | K2: Baseline (simple random split) [s42] | L2: Regular NER with DictaBERT | M2: 42 | N2: TRUE | O2: 0.7188755 | P2: 0.66791045 | Q2: 0.77826087 | R2: ok_reused_base | S2: /content/drive/MyDrive/thesis_project/thesis/outputs/exp01/regular_ner_20260601_205916.json | T2: /content/drive/MyDrive/thesis_project/thesis/outputs/exp01/regular_ner_results_20260601_205916.xlsx | U2: TRUE | V2: auto | W2: 7.1
A3: dictabert | B3: dicta-il/dictabert | C3: DictaBERT | D3: exp01 | E3: Regular NER | F3: exp07 | G3: exp07_before_exp01_baseline__seed43 | H3: exp07_before_exp01_baseline | I3: Baseline (simple random split) | J3: [Exp07] Baseline (simple random split) [seed 43] | K3: Baseline (simple random split) [s43] | L3: Regular NER with DictaBERT | M3: 43 | N3: TRUE | O3: 0.66933868 | P3: 0.62081784 | Q3: 0.72608696 | R3: ok | S3: /content/drive/MyDrive/thesis_project/thesis/outputs/exp01/regular_ner_20260601_210114.json | T3: /content/drive/MyDrive/thesis_project/thesis/outputs/exp01/regular_ner_results_20260601_210104.xlsx | U3: FALSE | V3: auto | W3: 119.2
A4: dictabert | B4: dicta-il/dictabert | C4: DictaBERT | D4: exp01 | E4: Regular NER | F4: exp07 | G4: exp07_before_exp01_baseline__seed44 | H4: exp07_before_exp01_baseline | I4: Baseline (simple random split) | J4: [Exp07] Baseline (simple random split) [seed 44] | K4: Baseline (simple random split) [s44] | L4: Regular NER with DictaBERT | M4: 44 | N4: TRUE | O4: 0.66933868 | P4: 0.62081784 | Q4: 0.72608696 | R4: ok | S4: /content/drive/MyDrive/thesis_project/thesis/outputs/exp01/regular_ner_20260601_210348.json | T4: /content/drive/MyDrive/thesis_project/thesis/outputs/exp01/regular_ner_results_20260601_210348.xlsx | U4: FALSE | V4: auto | W4: 159.5
A5: dictabert | B5: dicta-il/dictabert | C5: DictaBERT | D5: exp01 | E5: Regular NER | F5: exp07 | G5: exp07_before_exp01_baseline__seed45 | H5: exp07_before_exp01_baseline | I5: Baseline (simple random split) | J5: [Exp07] Baseline (simple random split) [seed 45] | K5: Baseline (simple random split) [s45] | L5: Regular NER with DictaBERT | M5: 45 | N5: TRUE | O5: 0.66933868 | P5: 0.62081784 | Q5: 0.72608696 | R5: ok | S5: /content/drive/MyDrive/thesis_project/thesis/outputs/exp01/regular_ner_20260601_210627.json | T5: /content/drive/MyDrive/thesis_project/thesis/outputs/exp01/regular_ner_results_20260601_210616.xlsx | U5: FALSE | V5: auto | W5: 155.6
A6: dictabert | B6: dicta-il/dictabert | C6: DictaBERT | D6: exp01 | E6: Regular NER | F6: exp07 | G6: exp07_before_exp01_baseline__seed46 | H6: exp07_before_exp01_baseline | I6: Baseline (simple random split) | J6: [Exp07] Baseline (simple random split) [seed 46] | K6: Baseline (simple random split) [s46] | L6: Regular NER with DictaBERT | M6: 46 | N6: TRUE | O6: 0.66933868 | P6: 0.62081784 | Q6: 0.72608696 | R6: ok | S6: /content/drive/MyDrive/thesis_project/thesis/outputs/exp01/regular_ner_20260601_210903.json | T6: /content/drive/MyDrive/thesis_project/thesis/outputs/exp01/regular_ner_results_20260601_210851.xlsx | U6: FALSE | V6: auto | W6: 166.9
A7: dictabert | B7: dicta-il/dictabert | C7: DictaBERT | D7: exp01 | E7: Regular NER | F7: exp07 | G7: exp07_before_exp01_baseline__seed47 | H7: exp07_before_exp01_baseline | I7: Baseline (simple random split) | J7: [Exp07] Baseline (simple random split) [seed 47] | K7: Baseline (simple random split) [s47] | L7: Regular NER with DictaBERT | M7: 47 | N7: TRUE | O7: 0.66933868 | P7: 0.62081784 | Q7: 0.72608696 | R7: ok | S7: /content/drive/MyDrive/thesis_project/thesis/outputs/exp01/regular_ner_20260601_211152.json | T7: /content/drive/MyDrive/thesis_project/thesis/outputs/exp01/regular_ner_results_20260601_211141.xlsx | U7: FALSE | V7: auto | W7: 180.9
A8: dictabert | B8: dicta-il/dictabert | C8: DictaBERT | D8: exp01 | E8: Regular NER | F8: exp07 | G8: exp07_before_exp01_baseline__seed48 | H8: exp07_before_exp01_baseline | I8: Baseline (simple random split) | J8: [Exp07] Baseline (simple random split) [seed 48] | K8: Baseline (simple random split) [s48] | L8: Regular NER with DictaBERT | M8: 48 | N8: TRUE | O8: 0.66933868 | P8: 0.62081784 | Q8: 0.72608696 | R8: ok | S8: /content/drive/MyDrive/thesis_project/thesis/outputs/exp01/regular_ner_20260601_211437.json | T8: /content/drive/MyDrive/thesis_project/thesis/outputs/exp01/regular_ner_results_20260601_211428.xlsx | U8: FALSE | V8: auto | W8: 164.8
A9: dictabert | B9: dicta-il/dictabert | C9: DictaBERT | D9: exp01 | E9: Regular NER | F9: exp07 | G9: exp07_before_exp01_baseline__seed49 | H9: exp07_before_exp01_baseline | I9: Baseline (simple random split) | J9: [Exp07] Baseline (simple random split) [seed 49] | K9: Baseline (simple random split) [s49] | L9: Regular NER with DictaBERT | M9: 49 | N9: TRUE | O9: 0.66933868 | P9: 0.62081784 | Q9: 0.72608696 | R9: ok | S9: /content/drive/MyDrive/thesis_project/thesis/outputs/exp01/regular_ner_20260601_211724.json | T9: /content/drive/MyDrive/thesis_project/thesis/outputs/exp01/regular_ner_results_20260601_211723.xlsx | U9: FALSE | V9: auto | W9: 161.6
A10: dictabert | B10: dicta-il/dictabert | C10: DictaBERT | D10: exp01 | E10: Regular NER | F10: exp07 | G10: exp07_before_exp01_baseline__seed50 | H10: exp07_before_exp01_baseline | I10: Baseline (simple random split) | J10: [Exp07] Baseline (simple random split) [seed 50] | K10: Baseline (simple random split) [s50] | L10: Regular NER with DictaBERT | M10: 50 | N10: TRUE | O10: 0.66933868 | P10: 0.62081784 | Q10: 0.72608696 | R10: ok | S10: /content/drive/MyDrive/thesis_project/thesis/outputs/exp01/regular_ner_20260601_212004.json | T10: /content/drive/MyDrive/thesis_project/thesis/outputs/exp01/regular_ner_results_20260601_212003.xlsx | U10: FALSE | V10: auto | W10: 157.8
A11: dictabert | B11: dicta-il/dictabert | C11: DictaBERT | D11: exp01 | E11: Regular NER | F11: exp07 | G11: exp07_before_exp01_baseline__seed51 | H11: exp07_before_exp01_baseline | I11: Baseline (simple random split) | J11: [Exp07] Baseline (simple random split) [seed 51] | K11: Baseline (simple random split) [s51] | L11: Regular NER with DictaBERT | M11: 51 | N11: TRUE | O11: 0.66933868 | P11: 0.62081784 | Q11: 0.72608696 | R11: ok | S11: /content/drive/MyDrive/thesis_project/thesis/outputs/exp01/regular_ner_20260601_212256.json | T11: /content/drive/MyDrive/thesis_project/thesis/outputs/exp01/regular_ner_results_20260601_212246.xlsx | U11: FALSE | V11: auto | W11: 183.9
A12: dictabert | B12: dicta-il/dictabert | C12: DictaBERT | D12: exp01 | E12: Regular NER | F12: exp07 | G12: exp07_before_exp01_baseline__seed52 | H12: exp07_before_exp01_baseline | I12: Baseline (simple random split) | J12: [Exp07] Baseline (simple random split) [seed 52] | K12: Baseline (simple random split) [s52] | L12: Regular NER with DictaBERT | M12: 52 | N12: TRUE | O12: 0.66933868 | P12: 0.62081784 | Q12: 0.72608696 | R12: ok | S12: /content/drive/MyDrive/thesis_project/thesis/outputs/exp01/regular_ner_20260601_212556.json | T12: /content/drive/MyDrive/thesis_project/thesis/outputs/exp01/regular_ner_results_20260601_212546.xlsx | U12: FALSE | V12: auto | W12: 170.9
A13: dictabert | B13: dicta-il/dictabert | C13: DictaBERT | D13: exp01 | E13: Regular NER | F13: exp07 | G13: exp07_before_exp01_baseline__seed53 | H13: exp07_before_exp01_baseline | I13: Baseline (simple random split) | J13: [Exp07] Baseline (simple random split) [seed 53] | K13: Baseline (simple random split) [s53] | L13: Regular NER with DictaBERT | M13: 53 | N13: TRUE | O13: 0.66933868 | P13: 0.62081784 | Q13: 0.72608696 | R13: ok | S13: /content/drive/MyDrive/thesis_project/thesis/outputs/exp01/regular_ner_20260601_212841.json | T13: /content/drive/MyDrive/thesis_project/thesis/outputs/exp01/regular_ner_results_20260601_212832.xlsx | U13: FALSE | V13: auto | W13: 145
... A121: dictabert | B121: dicta-il/dictabert | C121: DictaBERT | D121: exp01 | E121: Regular NER | F121: exp07+aug | G121: exp07aug_after_multilabel_iterative_paper__seed61 | H121: exp07aug_after_multilabel_iterative_paper | I121: Multilabel stratified (paper-style) + Aug | J121: [Exp07+Aug] Multilabel stratified (paper-style) + Augmented [seed 61] | K121: Multilabel stratified (paper-style) + Aug [s61] | L121: Paper-style iterative stratification: rarest-label-first with tie-breaks by per-label need, then fold capacity, then random + LLM mask-fill augmentation | M121: 61 | N121: FALSE | O121: 0.80525164 | P121: 0.78297872 | Q121: 0.82882883 | R121: ok | S121: /content/drive/MyDrive/thesis_project/thesis/outputs/exp01/regular_ner_20260602_202416.json | T121: /content/drive/MyDrive/thesis_project/thesis/outputs/exp01/regular_ner_results_20260602_202416.xlsx | U121: FALSE | V121: auto | W121: 263.7
A122: dictabert | B122: dicta-il/dictabert | C122: DictaBERT | D122: exp04 | E122: AUC Cascaded Pipeline | F122: exp07 | G122: exp07_before_exp01_baseline__seed42 | H122: exp07_before_exp01_baseline | I122: Baseline (simple random split) | J122: [Exp07] Baseline (simple random split) [seed 42] | K122: Baseline (simple random split) [s42] | L122: Regular NER with DictaBERT | M122: 42 | N122: TRUE | O122: 0.74895397 | R122: ok_reused_base | S122: /content/drive/MyDrive/thesis_project/thesis/outputs/exp04/auc_cascaded_pipeline_20260601_210001.json | T122: /content/drive/MyDrive/thesis_project/thesis/outputs/exp04/cascaded_pipeline_results_20260601_210000.xlsx | U122: TRUE | V122: auto | W122: 0.8
A123: dictabert | B123: dicta-il/dictabert | C123: DictaBERT | D123: exp04 | E123: AUC Cascaded Pipeline | F123: exp07 | G123: exp07_before_exp01_baseline__seed43 | H123: exp07_before_exp01_baseline | I123: Baseline (simple random split) | J123: [Exp07] Baseline (simple random split) [seed 43] | K123: Baseline (simple random split) [s43] | L123: Regular NER with DictaBERT | M123: 43 | N123: TRUE | O123: 0.71910112 | R123: ok_reused_base | S123: /content/drive/MyDrive/thesis_project/thesis/outputs/exp04/auc_cascaded_pipeline_20260601_210200.json | T123: /content/drive/MyDrive/thesis_project/thesis/outputs/exp04/cascaded_pipeline_results_20260601_210159.xlsx | U123: TRUE | V123: auto | W123: 1
A124: dictabert | B124: dicta-il/dictabert | C124: DictaBERT | D124: exp04 | E124: AUC Cascaded Pipeline | F124: exp07 | G124: exp07_before_exp01_baseline__seed44 | H124: exp07_before_exp01_baseline | I124: Baseline (simple random split) | J124: [Exp07] Baseline (simple random split) [seed 44] | K124: Baseline (simple random split) [s44] | L124: Regular NER with DictaBERT | M124: 44 | N124: TRUE | O124: 0.70229008 | R124: ok_reused_base | S124: /content/drive/MyDrive/thesis_project/thesis/outputs/exp04/auc_cascaded_pipeline_20260601_210439.json | T124: /content/drive/MyDrive/thesis_project/thesis/outputs/exp04/cascaded_pipeline_results_20260601_210438.xlsx | U124: TRUE | V124: auto | W124: 0.7
A125: dictabert | B125: dicta-il/dictabert | C125: DictaBERT | D125: exp04 | E125: AUC Cascaded Pipeline | F125: exp07 | G125: exp07_before_exp01_baseline__seed45 | H125: exp07_before_exp01_baseline | I125: Baseline (simple random split) | J125: [Exp07] Baseline (simple random split) [seed 45] | K125: Baseline (simple random split) [s45] | L125: Regular NER with DictaBERT | M125: 45 | N125: TRUE | O125: 0.72881356 | R125: ok_reused_base | S125: /content/drive/MyDrive/thesis_project/thesis/outputs/exp04/auc_cascaded_pipeline_20260601_210715.json | T125: /content/drive/MyDrive/thesis_project/thesis/outputs/exp04/cascaded_pipeline_results_20260601_210714.xlsx | U125: TRUE | V125: auto | W125: 1
A126: dictabert | B126: dicta-il/dictabert | C126: DictaBERT | D126: exp04 | E126: AUC Cascaded Pipeline | F126: exp07 | G126: exp07_before_exp01_baseline__seed46 | H126: exp07_before_exp01_baseline | I126: Baseline (simple random split) | J126: [Exp07] Baseline (simple random split) [seed 46] | K126: Baseline (simple random split) [s46] | L126: Regular NER with DictaBERT | M126: 46 | N126: TRUE | O126: 0.69767442 | R126: ok_reused_base | S126: /content/drive/MyDrive/thesis_project/thesis/outputs/exp04/auc_cascaded_pipeline_20260601_211002.json | T126: /content/drive/MyDrive/thesis_project/thesis/outputs/exp04/cascaded_pipeline_results_20260601_211001.xlsx | U126: TRUE | V126: auto | W126: 0.7
A127: dictabert | B127: dicta-il/dictabert | C127: DictaBERT | D127: exp04 | E127: AUC Cascaded Pipeline | F127: exp07 | G127: exp07_before_exp01_baseline__seed47 | H127: exp07_before_exp01_baseline | I127: Baseline (simple random split) | J127: [Exp07] Baseline (simple random split) [seed 47] | K127: Baseline (simple random split) [s47] | L127: Regular NER with DictaBERT | M127: 47 | N127: TRUE | O127: 0.75527426 | R127: ok_reused_base | S127: /content/drive/MyDrive/thesis_project/thesis/outputs/exp04/auc_cascaded_pipeline_20260601_211301.json | T127: /content/drive/MyDrive/thesis_project/thesis/outputs/exp04/cascaded_pipeline_results_20260601_211251.xlsx | U127: TRUE | V127: auto | W127: 1
A128: dictabert | B128: dicta-il/dictabert | C128: DictaBERT | D128: exp04 | E128: AUC Cascaded Pipeline | F128: exp07 | G128: exp07_before_exp01_baseline__seed48 | H128: exp07_before_exp01_baseline | I128: Baseline (simple random split) | J128: [Exp07] Baseline (simple random split) [seed 48] | K128: Baseline (simple random split) [s48] | L128: Regular NER with DictaBERT | M128: 48 | N128: TRUE | O128: 0.73221757 | R128: ok_reused_base | S128: /content/drive/MyDrive/thesis_project/thesis/outputs/exp04/auc_cascaded_pipeline_20260601_211546.json | T128: /content/drive/MyDrive/thesis_project/thesis/outputs/exp04/cascaded_pipeline_results_20260601_211536.xlsx | U128: TRUE | V128: auto | W128: 0.8
A129: dictabert | B129: dicta-il/dictabert | C129: DictaBERT | D129: exp04 | E129: AUC Cascaded Pipeline | F129: exp07 | G129: exp07_before_exp01_baseline__seed49 | H129: exp07_before_exp01_baseline | I129: Baseline (simple random split) | J129: [Exp07] Baseline (simple random split) [seed 49] | K129: Baseline (simple random split) [s49] | L129: Regular NER with DictaBERT | M129: 49 | N129: TRUE | O129: 0.7348643 | R129: ok_reused_base | S129: /content/drive/MyDrive/thesis_project/thesis/outputs/exp04/auc_cascaded_pipeline_20260601_211829.json | T129: /content/drive/MyDrive/thesis_project/thesis/outputs/exp04/cascaded_pipeline_results_20260601_211828.xlsx | U129: TRUE | V129: auto | W129: 0.9
A130: dictabert | B130: dicta-il/dictabert | C130: DictaBERT | D130: exp04 | E130: AUC Cascaded Pipeline | F130: exp07 | G130: exp07_before_exp01_baseline__seed50 | H130: exp07_before_exp01_baseline | I130: Baseline (simple random split) | J130: [Exp07] Baseline (simple random split) [seed 50] | K130: Baseline (simple random split) [s50] | L130: Regular NER with DictaBERT | M130: 50 | N130: TRUE | O130: 0.74895397 | R130: ok_reused_base | S130: /content/drive/MyDrive/thesis_project/thesis/outputs/exp04/auc_cascaded_pipeline_20260601_212107.json | T130: /content/drive/MyDrive/thesis_project/thesis/outputs/exp04/cascaded_pipeline_results_20260601_212106.xlsx | U130: TRUE | V130: auto | W130: 0.7
A131: dictabert | B131: dicta-il/dictabert | C131: DictaBERT | D131: exp04 | E131: AUC Cascaded Pipeline | F131: exp07 | G131: exp07_before_exp01_baseline__seed51 | H131: exp07_before_exp01_baseline | I131: Baseline (simple random split) | J131: [Exp07] Baseline (simple random split) [seed 51] | K131: Baseline (simple random split) [s51] | L131: Regular NER with DictaBERT | M131: 51 | N131: TRUE | O131: 0.71398747 | R131: ok_reused_base | S131: /content/drive/MyDrive/thesis_project/thesis/outputs/exp04/auc_cascaded_pipeline_20260601_212411.json | T131: /content/drive/MyDrive/thesis_project/thesis/outputs/exp04/cascaded_pipeline_results_20260601_212400.xlsx | U131: TRUE | V131: auto | W131: 1
A132: dictabert | B132: dicta-il/dictabert | C132: DictaBERT | D132: exp04 | E132: AUC Cascaded Pipeline | F132: exp07 | G132: exp07_before_exp01_baseline__seed52 | H132: exp07_before_exp01_baseline | I132: Baseline (simple random split) | J132: [Exp07] Baseline (simple random split) [seed 52] | K132: Baseline (simple random split) [s52] | L132: Regular NER with DictaBERT | M132: 52 | N132: TRUE | O132: 0.71092077 | R132: ok_reused_base | S132: /content/drive/MyDrive/thesis_project/thesis/outputs/exp04/auc_cascaded_pipeline_20260601_212702.json | T132: /content/drive/MyDrive/thesis_project/thesis/outputs/exp04/cascaded_pipeline_results_20260601_212701.xlsx | U132: TRUE | V132: auto | W132: 0.7
A133: dictabert | B133: dicta-il/dictabert | C133: DictaBERT | D133: exp04 | E133: AUC Cascaded Pipeline | F133: exp07 | G133: exp07_before_exp01_baseline__seed53 | H133: exp07_before_exp01_baseline | I133: Baseline (simple random split) | J133: [Exp07] Baseline (simple random split) [seed 53] | K133: Baseline (simple random split) [s53] | L133: Regular NER with DictaBERT | M133: 53 | N133: TRUE | O133: 0.74369748 | R133: ok_reused_base | S133: /content/drive/MyDrive/thesis_project/thesis/outputs/exp04/auc_cascaded_pipeline_20260601_212927.json | T133: /content/drive/MyDrive/thesis_project/thesis/outputs/exp04/cascaded_pipeline_results_20260601_212926.xlsx | U133: TRUE | V133: auto | W133: 0.9
... A241: dictabert | B241: dicta-il/dictabert | C241: DictaBERT | D241: exp04 | E241: AUC Cascaded Pipeline | F241: exp07+aug | G241: exp07aug_after_multilabel_iterative_paper__seed61 | H241: exp07aug_after_multilabel_iterative_paper | I241: Multilabel stratified (paper-style) + Aug | J241: [Exp07+Aug] Multilabel stratified (paper-style) + Augmented [seed 61] | K241: Multilabel stratified (paper-style) + Aug [s61] | L241: Paper-style iterative stratification: rarest-label-first with tie-breaks by per-label need, then fold capacity, then random + LLM mask-fill augmentation | M241: 61 | N241: FALSE | O241: 0.81127983 | R241: ok_reused_base | S241: /content/drive/MyDrive/thesis_project/thesis/outputs/exp04/auc_cascaded_pipeline_20260602_202652.json | T241: /content/drive/MyDrive/thesis_project/thesis/outputs/exp04/cascaded_pipeline_results_20260602_202651.xlsx | U241: TRUE | V241: auto | W241: 0
A242: dictabert | B242: dicta-il/dictabert | C242: DictaBERT | D242: exp05_ready | E242: AUC Cascaded Step-3 Consistency (Ready) | F242: exp07 | G242: exp07_before_exp01_baseline__seed42 | H242: exp07_before_exp01_baseline | I242: Baseline (simple random split) | J242: [Exp07] Baseline (simple random split) [seed 42] | K242: Baseline (simple random split) [s42] | L242: Regular NER with DictaBERT | M242: 42 | N242: TRUE | O242: 0.75156576 | P242: 0.72289157 | Q242: 0.7826087 | R242: ok | S242: /content/drive/MyDrive/thesis_project/thesis/outputs/exp05_ready/cascaded_step3_consistent_ready_20260717_102530.json | T242: /content/drive/MyDrive/thesis_project/thesis/outputs/exp05_ready/cascaded_step3_consistent_ready_results_20260717_102527.xlsx | U242: TRUE | V242: auto | W242: 7.7
A243: dictabert | B243: dicta-il/dictabert | C243: DictaBERT | D243: exp05_ready | E243: AUC Cascaded Step-3 Consistency (Ready) | F243: exp07 | G243: exp07_before_exp01_baseline__seed43 | H243: exp07_before_exp01_baseline | I243: Baseline (simple random split) | J243: [Exp07] Baseline (simple random split) [seed 43] | K243: Baseline (simple random split) [s43] | L243: Regular NER with DictaBERT | M243: 43 | N243: TRUE | O243: 0.7309417 | P243: 0.75462963 | Q243: 0.70869565 | R243: ok | S243: /content/drive/MyDrive/thesis_project/thesis/outputs/exp05_ready/cascaded_step3_consistent_ready_20260602_202818.json | T243: /content/drive/MyDrive/thesis_project/thesis/outputs/exp05_ready/cascaded_step3_consistent_ready_results_20260602_202817.xlsx | U243: TRUE | V243: auto | W243: 2.3
A244: dictabert | B244: dicta-il/dictabert | C244: DictaBERT | D244: exp05_ready | E244: AUC Cascaded Step-3 Consistency (Ready) | F244: exp07 | G244: exp07_before_exp01_baseline__seed44 | H244: exp07_before_exp01_baseline | I244: Baseline (simple random split) | J244: [Exp07] Baseline (simple random split) [seed 44] | K244: Baseline (simple random split) [s44] | L244: Regular NER with DictaBERT | M244: 44 | N244: TRUE | O244: 0.71102662 | P244: 0.63175676 | Q244: 0.81304348 | R244: ok | S244: /content/drive/MyDrive/thesis_project/thesis/outputs/exp05_ready/cascaded_step3_consistent_ready_20260602_202820.json | T244: /content/drive/MyDrive/thesis_project/thesis/outputs/exp05_ready/cascaded_step3_consistent_ready_results_20260602_202819.xlsx | U244: TRUE | V244: auto | W244: 1.9
A245: dictabert | B245: dicta-il/dictabert | C245: DictaBERT | D245: exp05_ready | E245: AUC Cascaded Step-3 Consistency (Ready) | F245: exp07 | G245: exp07_before_exp01_baseline__seed45 | H245: exp07_before_exp01_baseline | I245: Baseline (simple random split) | J245: [Exp07] Baseline (simple random split) [seed 45] | K245: Baseline (simple random split) [s45] | L245: Regular NER with DictaBERT | M245: 45 | N245: TRUE | O245: 0.73572939 | P245: 0.71604938 | Q245: 0.75652174 | R245: ok | S245: /content/drive/MyDrive/thesis_project/thesis/outputs/exp05_ready/cascaded_step3_consistent_ready_20260602_202822.json | T245: /content/drive/MyDrive/thesis_project/thesis/outputs/exp05_ready/cascaded_step3_consistent_ready_results_20260602_202822.xlsx | U245: TRUE | V245: auto | W245: 2.4
A246: dictabert | B246: dicta-il/dictabert | C246: DictaBERT | D246: exp05_ready | E246: AUC Cascaded Step-3 Consistency (Ready) | F246: exp07 | G246: exp07_before_exp01_baseline__seed46 | H246: exp07_before_exp01_baseline | I246: Baseline (simple random split) | J246: [Exp07] Baseline (simple random split) [seed 46] | K246: Baseline (simple random split) [s46] | L246: Regular NER with DictaBERT | M246: 46 | N246: TRUE | O246: 0.70315789 | P246: 0.68163265 | Q246: 0.72608696 | R246: ok | S246: /content/drive/MyDrive/thesis_project/thesis/outputs/exp05_ready/cascaded_step3_consistent_ready_20260602_202824.json | T246: /content/drive/MyDrive/thesis_project/thesis/outputs/exp05_ready/cascaded_step3_consistent_ready_results_20260602_202824.xlsx | U246: TRUE | V246: auto | W246: 2.3
A247: dictabert | B247: dicta-il/dictabert | C247: DictaBERT | D247: exp05_ready | E247: AUC Cascaded Step-3 Consistency (Ready) | F247: exp07 | G247: exp07_before_exp01_baseline__seed47 | H247: exp07_before_exp01_baseline | I247: Baseline (simple random split) | J247: [Exp07] Baseline (simple random split) [seed 47] | K247: Baseline (simple random split) [s47] | L247: Regular NER with DictaBERT | M247: 47 | N247: TRUE | O247: 0.7605042 | P247: 0.73577236 | Q247: 0.78695652 | R247: ok | S247: /content/drive/MyDrive/thesis_project/thesis/outputs/exp05_ready/cascaded_step3_consistent_ready_20260602_202826.json | T247: /content/drive/MyDrive/thesis_project/thesis/outputs/exp05_ready/cascaded_step3_consistent_ready_results_20260602_202825.xlsx | U247: TRUE | V247: auto | W247: 1.4
A248: dictabert | B248: dicta-il/dictabert | C248: DictaBERT | D248: exp05_ready | E248: AUC Cascaded Step-3 Consistency (Ready) | F248: exp07 | G248: exp07_before_exp01_baseline__seed48 | H248: exp07_before_exp01_baseline | I248: Baseline (simple random split) | J248: [Exp07] Baseline (simple random split) [seed 48] | K248: Baseline (simple random split) [s48] | L248: Regular NER with DictaBERT | M248: 48 | N248: TRUE | O248: 0.73903967 | P248: 0.71084337 | Q248: 0.76956522 | R248: ok | S248: /content/drive/MyDrive/thesis_project/thesis/outputs/exp05_ready/cascaded_step3_consistent_ready_20260602_202827.json | T248: /content/drive/MyDrive/thesis_project/thesis/outputs/exp05_ready/cascaded_step3_consistent_ready_results_20260602_202827.xlsx | U248: TRUE | V248: auto | W248: 1.4
A249: dictabert | B249: dicta-il/dictabert | C249: DictaBERT | D249: exp05_ready | E249: AUC Cascaded Step-3 Consistency (Ready) | F249: exp07 | G249: exp07_before_exp01_baseline__seed49 | H249: exp07_before_exp01_baseline | I249: Baseline (simple random split) | J249: [Exp07] Baseline (simple random split) [seed 49] | K249: Baseline (simple random split) [s49] | L249: Regular NER with DictaBERT | M249: 49 | N249: TRUE | O249: 0.74166667 | P249: 0.712 | Q249: 0.77391304 | R249: ok | S249: /content/drive/MyDrive/thesis_project/thesis/outputs/exp05_ready/cascaded_step3_consistent_ready_20260602_202828.json | T249: /content/drive/MyDrive/thesis_project/thesis/outputs/exp05_ready/cascaded_step3_consistent_ready_results_20260602_202828.xlsx | U249: TRUE | V249: auto | W249: 1.4
A250: dictabert | B250: dicta-il/dictabert | C250: DictaBERT | D250: exp05_ready | E250: AUC Cascaded Step-3 Consistency (Ready) | F250: exp07 | G250: exp07_before_exp01_baseline__seed50 | H250: exp07_before_exp01_baseline | I250: Baseline (simple random split) | J250: [Exp07] Baseline (simple random split) [seed 50] | K250: Baseline (simple random split) [s50] | L250: Regular NER with DictaBERT | M250: 50 | N250: TRUE | O250: 0.75991649 | P250: 0.73092369 | Q250: 0.79130435 | R250: ok | S250: /content/drive/MyDrive/thesis_project/thesis/outputs/exp05_ready/cascaded_step3_consistent_ready_20260602_202830.json | T250: /content/drive/MyDrive/thesis_project/thesis/outputs/exp05_ready/cascaded_step3_consistent_ready_results_20260602_202830.xlsx | U250: TRUE | V250: auto | W250: 1.4
A251: dictabert | B251: dicta-il/dictabert | C251: DictaBERT | D251: exp05_ready | E251: AUC Cascaded Step-3 Consistency (Ready) | F251: exp07 | G251: exp07_before_exp01_baseline__seed51 | H251: exp07_before_exp01_baseline | I251: Baseline (simple random split) | J251: [Exp07] Baseline (simple random split) [seed 51] | K251: Baseline (simple random split) [s51] | L251: Regular NER with DictaBERT | M251: 51 | N251: TRUE | O251: 0.71666667 | P251: 0.688 | Q251: 0.74782609 | R251: ok | S251: /content/drive/MyDrive/thesis_project/thesis/outputs/exp05_ready/cascaded_step3_consistent_ready_20260602_202832.json | T251: /content/drive/MyDrive/thesis_project/thesis/outputs/exp05_ready/cascaded_step3_consistent_ready_results_20260602_202831.xlsx | U251: TRUE | V251: auto | W251: 1.8
A252: dictabert | B252: dicta-il/dictabert | C252: DictaBERT | D252: exp05_ready | E252: AUC Cascaded Step-3 Consistency (Ready) | F252: exp07 | G252: exp07_before_exp01_baseline__seed52 | H252: exp07_before_exp01_baseline | I252: Baseline (simple random split) | J252: [Exp07] Baseline (simple random split) [seed 52] | K252: Baseline (simple random split) [s52] | L252: Regular NER with DictaBERT | M252: 52 | N252: TRUE | O252: 0.72649573 | P252: 0.71428571 | Q252: 0.73913043 | R252: ok | S252: /content/drive/MyDrive/thesis_project/thesis/outputs/exp05_ready/cascaded_step3_consistent_ready_20260602_202833.json | T252: /content/drive/MyDrive/thesis_project/thesis/outputs/exp05_ready/cascaded_step3_consistent_ready_results_20260602_202833.xlsx | U252: TRUE | V252: auto | W252: 1.6
A253: dictabert | B253: dicta-il/dictabert | C253: DictaBERT | D253: exp05_ready | E253: AUC Cascaded Step-3 Consistency (Ready) | F253: exp07 | G253: exp07_before_exp01_baseline__seed53 | H253: exp07_before_exp01_baseline | I253: Baseline (simple random split) | J253: [Exp07] Baseline (simple random split) [seed 53] | K253: Baseline (simple random split) [s53] | L253: Regular NER with DictaBERT | M253: 53 | N253: TRUE | O253: 0.74633124 | P253: 0.72064777 | Q253: 0.77391304 | R253: ok | S253: /content/drive/MyDrive/thesis_project/thesis/outputs/exp05_ready/cascaded_step3_consistent_ready_20260602_202835.json | T253: /content/drive/MyDrive/thesis_project/thesis/outputs/exp05_ready/cascaded_step3_consistent_ready_results_20260602_202834.xlsx | U253: TRUE | V253: auto | W253: 1.3
... A721: berel | B721: dicta-il/BEREL_3.0 | C721: BEREL 3.0 | D721: exp01 | E721: Regular NER | F721: exp07+aug | G721: exp07aug_after_multilabel_iterative_paper__seed61 | H721: exp07aug_after_multilabel_iterative_paper | I721: Multilabel stratified (paper-style) + Aug | J721: [Exp07+Aug] Multilabel stratified (paper-style) + Augmented [seed 61] | K721: Multilabel stratified (paper-style) + Aug [s61] | L721: Paper-style iterative stratification: rarest-label-first with tie-breaks by per-label need, then fold capacity, then random + LLM mask-fill augmentation | M721: 61 | N721: FALSE | O721: 0.84257206 | P721: 0.82969432 | Q721: 0.85585586 | R721: ok | S721: /content/drive/MyDrive/thesis_project/thesis/outputs/exp01/regular_ner_20260603_112254.json | T721: /content/drive/MyDrive/thesis_project/thesis/outputs/exp01/regular_ner_results_20260603_112254.xlsx | U721: FALSE | V721: auto | W721: 253.8
...

Sheet deltas_exp07
A1: model | B1: experiment_id | C1: experiment_name | D1: variant | E1: baseline_f1 | F1: variant_f1 | G1: delta_f1 | H1: baseline_precision | I1: variant_precision | J1: baseline_recall | K1: variant_recall
A2: DictaBERT | B2: exp01 | C2: Regular NER | D2: Label-aware greedy | E2: 0.67181552 | F2: 0.75409836 | G2: 0.082282842 | H2: 0.62317247 | I2: 0.70050761 | J2: 0.72869565 | K2: 0.81656805
A3: DictaBERT | B3: exp01 | C3: Regular NER | D3: Multilabel stratified (paper-style) | E3: 0.67181552 | F3: 0.73799127 | G3: 0.066175748 | H3: 0.62317247 | I3: 0.71610169 | J3: 0.72869565 | K3: 0.76126126
A4: DictaBERT | B4: exp04 | C4: AUC Cascaded Pipeline | D4: Label-aware greedy | E4: 0.73106191 | F4: 0.72685318 | G4: -0.0042087309
A5: DictaBERT | B5: exp04 | C5: AUC Cascaded Pipeline | D5: Multilabel stratified (paper-style) | E5: 0.73106191 | F5: 0.76418619 | G5: 0.033124275
A6: DictaBERT | B6: exp05_ready | C6: AUC Cascaded Step-3 Consistency (Ready) | D6: Label-aware greedy | E6: 0.73744218 | F6: 0.73443891 | G6: -0.0030032691 | H6: 0.70629028 | I6: 0.69016433 | J6: 0.77326087 | K6: 0.78579882
A7: DictaBERT | B7: exp05_ready | C7: AUC Cascaded Step-3 Consistency (Ready) | D7: Multilabel stratified (paper-style) | E7: 0.73744218 | F7: 0.76395529 | G7: 0.02651311 | H7: 0.70629028 | I7: 0.73058927 | J7: 0.77326087 | K7: 0.8027027
A8: DictaBERT | B8: exp06_ready | C8: Fusion Regular+Cascaded (Ready) | D8: Label-aware greedy | E8: 0.68608841 | F8: 0.73789067 | G8: 0.05180226 | H8: 0.66145053 | I8: 0.69268504 | J8: 0.71304348 | K8: 0.78964497
A9: DictaBERT | B9: exp06_ready | C9: Fusion Regular+Cascaded (Ready) | D9: Multilabel stratified (paper-style) | E9: 0.68608841 | F9: 0.74547408 | G9: 0.059385671 | H9: 0.66145053 | I9: 0.7376467 | J9: 0.71304348 | K9: 0.7536036
A10: DictaBERT | B10: exp06_svm_ready | C10: SVM Router Fusion (Ready) | D10: Label-aware greedy | E10: 0.76571232 | F10: 0.81102868 | G10: 0.045316364 | H10: 0.7336966 | I10: 0.77879083 | J10: 0.80086957 | K10: 0.84615385
A11: DictaBERT | B11: exp06_svm_ready | C11: SVM Router Fusion (Ready) | D11: Multilabel stratified (paper-style) | E11: 0.76571232 | F11: 0.80724124 | G11: 0.041528914 | H11: 0.7336966 | I11: 0.79198191 | J11: 0.80086957 | K11: 0.8231982
A12: DictaBERT | B12: exp10_regular | C12: Regular NER (BERT-CRF) | D12: Label-aware greedy | E12: 0.74967002 | F12: 0.75749319 | G12: 0.0078231694 | H12: 0.71553356 | I12: 0.70918367 | J12: 0.78722944 | K12: 0.8128655
A13: DictaBERT | B13: exp10_regular | C13: Regular NER (BERT-CRF) | D13: Multilabel stratified (paper-style) | E13: 0.74967002 | F13: 0.7751606 | G13: 0.025490581 | H13: 0.71553356 | I13: 0.75103734 | J13: 0.78722944 | K13: 0.80088496
A14: DictaBERT | B14: exp10_cascade | C14: Cascaded Pipeline (CRF + Consistency) | D14: Label-aware greedy | E14: 0.77570969 | F14: 0.7904055 | G14: 0.014695811
A15: DictaBERT | B15: exp10_cascade | C15: Cascaded Pipeline (CRF + Consistency) | D15: Multilabel stratified (paper-style) | E15: 0.77570969 | F15: 0.79922902 | G15: 0.023519334
A16: DictaBERT | B16: exp10_fusion_ready | C16: Fusion Regular-CRF + Cascaded-CRF (Ready) | D16: Label-aware greedy | E16: 0.75307747 | F16: 0.77294573 | G16: 0.019868265 | H16: 0.72054357 | I16: 0.72299398 | J16: 0.78874459 | K16: 0.83070175
A17: DictaBERT | B17: exp10_fusion_ready | C17: Fusion Regular-CRF + Cascaded-CRF (Ready) | D17: Multilabel stratified (paper-style) | E17: 0.75307747 | F17: 0.76761709 | G17: 0.014539628 | H17: 0.72054357 | I17: 0.74332846 | J17: 0.78874459 | K17: 0.79358407
A18: DictaBERT | B18: exp10_svm_ready | C18: SVM Router Fusion CRF (Ready) | D18: Label-aware greedy | E18: 0.78950032 | F18: 0.82665558 | G18: 0.037155263 | H18: 0.75364938 | I18: 0.78621014 | J18: 0.82900433 | K18: 0.87163743
A19: DictaBERT | B19: exp10_svm_ready | C19: SVM Router Fusion CRF (Ready) | D19: Multilabel stratified (paper-style) | E19: 0.78950032 | F19: 0.82198659 | G19: 0.032486271 | H19: 0.75364938 | I19: 0.80113352 | J19: 0.82900433 | K19: 0.84402655
A20: BEREL 3.0 | B20: exp01 | C20: Regular NER | D20: Label-aware greedy | E20: 0.70511025 | F20: 0.70744681 | G20: 0.0023365566 | H20: 0.64499456 | I20: 0.64251208 | J20: 0.7776087 | K20: 0.78698225
A21: BEREL 3.0 | B21: exp01 | C21: Regular NER | D21: Multilabel stratified (paper-style) | E21: 0.70511025 | F21: 0.73057105 | G21: 0.025460794 | H21: 0.64499456 | I21: 0.69366792 | J21: 0.7776087 | K21: 0.77162162
A22: BEREL 3.0 | B22: exp04 | C22: AUC Cascaded Pipeline | D22: Label-aware greedy | E22: 0.62779773 | F22: 0.64704888 | G22: 0.01925115
A23: BEREL 3.0 | B23: exp04 | C23: AUC Cascaded Pipeline | D23: Multilabel stratified (paper-style) | E23: 0.62779773 | F23: 0.63439021 | G23: 0.0065924868
A24: BEREL 3.0 | B24: exp05_ready | C24: AUC Cascaded Step-3 Consistency (Ready) | D24: Label-aware greedy | E24: 0.63513909 | F24: 0.6522487 | G24: 0.017109608 | H24: 0.61015776 | I24: 0.60532742 | J24: 0.6676087 | K24: 0.70798817
A25: BEREL 3.0 | B25: exp05_ready | C25: AUC Cascaded Step-3 Consistency (Ready) | D25: Multilabel stratified (paper-style) | E25: 0.63513909 | F25: 0.63902807 | G25: 0.0038889815 | H25: 0.61015776 | I25: 0.60735366 | J25: 0.6676087 | K25: 0.68108108
A26: BEREL 3.0 | B26: exp06_ready | C26: Fusion Regular+Cascaded (Ready) | D26: Label-aware greedy | E26: 0.71044712 | F26: 0.71525238 | G26: 0.0048052684 | H26: 0.69649941 | I26: 0.67073467 | J26: 0.7273913 | K26: 0.76715976
A27: BEREL 3.0 | B27: exp06_ready | C27: Fusion Regular+Cascaded (Ready) | D27: Multilabel stratified (paper-style) | E27: 0.71044712 | F27: 0.73881673 | G27: 0.028369616 | H27: 0.69649941 | I27: 0.73617241 | J27: 0.7273913 | K27: 0.74391892
A28: BEREL 3.0 | B28: exp06_svm_ready | C28: SVM Router Fusion (Ready) | D28: Label-aware greedy | E28: 0.77142141 | F28: 0.78997538 | G28: 0.018553973 | H28: 0.75011689 | I28: 0.76383709 | J28: 0.79456522 | K28: 0.81893491
A29: BEREL 3.0 | B29: exp06_svm_ready | C29: SVM Router Fusion (Ready) | D29: Multilabel stratified (paper-style) | E29: 0.77142141 | F29: 0.79533462 | G29: 0.023913214 | H29: 0.75011689 | I29: 0.78076811 | J29: 0.79456522 | K29: 0.81126126
A30: BEREL 3.0 | B30: exp10_regular | C30: Regular NER (BERT-CRF) | D30: Label-aware greedy | E30: 0.73061224 | F30: 0.72486772 | G30: -0.00574452 | H30: 0.69111969 | I30: 0.66183575 | J30: 0.77489177 | K30: 0.80116959
A31: BEREL 3.0 | B31: exp10_regular | C31: Regular NER (BERT-CRF) | D31: Multilabel stratified (paper-style) | E31: 0.73061224 | F31: 0.69601677 | G31: -0.034595473 | H31: 0.69111969 | I31: 0.66135458 | J31: 0.77489177 | K31: 0.73451327
A32: BEREL 3.0 | B32: exp10_cascade | C32: Cascaded Pipeline (CRF + Consistency) | D32: Label-aware greedy | E32: 0.72446006 | F32: 0.75964719 | G32: 0.035187134
A33: BEREL 3.0 | B33: exp10_cascade | C33: Cascaded Pipeline (CRF + Consistency) | D33: Multilabel stratified (paper-style) | E33: 0.72446006 | F33: 0.75881808 | G33: 0.034358018
A34: BEREL 3.0 | B34: exp10_fusion_ready | C34: Fusion Regular-CRF + Cascaded-CRF (Ready) | D34: Label-aware greedy | E34: 0.74157498 | F34: 0.76677714 | G34: 0.025202163 | H34: 0.78916464 | I34: 0.77253048 | J34: 0.71428571 | K34: 0.7751462
A35: BEREL 3.0 | B35: exp10_fusion_ready | C35: Fusion Regular-CRF + Cascaded-CRF (Ready) | D35: Multilabel stratified (paper-style) | E35: 0.74157498 | F35: 0.73836075 | G35: -0.0032142319 | H35: 0.78916464 | I35: 0.75633581 | J35: 0.71428571 | K35: 0.73738938
A36: BEREL 3.0 | B36: exp10_svm_ready | C36: SVM Router Fusion CRF (Ready) | D36: Label-aware greedy | E36: 0.78419159 | F36: 0.78135932 | G36: -0.002832267 | H36: 0.78843504 | I36: 0.75392623 | J36: 0.78354978 | K36: 0.81491228
A37: BEREL 3.0 | B37: exp10_svm_ready | C37: SVM Router Fusion CRF (Ready) | D37: Multilabel stratified (paper-style) | E37: 0.78419159 | F37: 0.76120338 | G37: -0.02298821 | H37: 0.78843504 | I37: 0.73795622 | J37: 0.78354978 | K37: 0.78849558
A38: HeRo | B38: exp01 | C38: Regular NER | D38: Label-aware greedy | E38: 0.74452227 | F38: 0.75482094 | G38: 0.010298669 | H38: 0.69877762 | I38: 0.70618557 | J38: 0.79673913 | K38: 0.81065089
A39: HeRo | B39: exp01 | C39: Regular NER | D39: Multilabel stratified (paper-style) | E39: 0.74452227 | F39: 0.76923077 | G39: 0.024708501 | H39: 0.69877762 | I39: 0.75107296 | J39: 0.79673913 | K39: 0.78828829
A40: HeRo | B40: exp04 | C40: AUC Cascaded Pipeline | D40: Label-aware greedy | E40: 0.73960007 | F40: 0.75913558 | G40: 0.019535518
...

Sheet deltas_exp07_aug
A1: model | B1: experiment_id | C1: experiment_name | D1: split_variant | E1: split_only_f1 | F1: split_plus_aug_f1 | G1: delta_f1
A2: DictaBERT | B2: exp01 | C2: Regular NER | D2: Label-aware greedy | E2: 0.75409836 | F2: 0.80152098 | G2: 0.047422619
A3: DictaBERT | B3: exp01 | C3: Regular NER | D3: Multilabel stratified (paper-style) | E3: 0.73799127 | F3: 0.8082628 | G3: 0.070271537
A4: DictaBERT | B4: exp01 | C4: Regular NER | D4: Baseline (simple random split) | E4: 0.67181552 | F4: 0.78054156 | G4: 0.10872605
A5: DictaBERT | B5: exp04 | C5: AUC Cascaded Pipeline | D5: Label-aware greedy | E5: 0.72685318 | F5: 0.79726934 | G5: 0.07041616
A6: DictaBERT | B6: exp04 | C6: AUC Cascaded Pipeline | D6: Multilabel stratified (paper-style) | E6: 0.76418619 | F6: 0.8231002 | G6: 0.058914008
A7: DictaBERT | B7: exp04 | C7: AUC Cascaded Pipeline | D7: Baseline (simple random split) | E7: 0.73106191 | F7: 0.78903842 | G7: 0.057976502
A8: DictaBERT | B8: exp05_ready | C8: AUC Cascaded Step-3 Consistency (Ready) | D8: Label-aware greedy | E8: 0.73443891 | F8: 0.80508365 | G8: 0.070644734
A9: DictaBERT | B9: exp05_ready | C9: AUC Cascaded Step-3 Consistency (Ready) | D9: Multilabel stratified (paper-style) | E9: 0.76395529 | F9: 0.82769692 | G9: 0.063741624
A10: DictaBERT | B10: exp05_ready | C10: AUC Cascaded Step-3 Consistency (Ready) | D10: Baseline (simple random split) | E10: 0.73744218 | F10: 0.78995314 | G10: 0.052510957
A11: DictaBERT | B11: exp06_ready | C11: Fusion Regular+Cascaded (Ready) | D11: Label-aware greedy | E11: 0.73789067 | F11: 0.8068222 | G11: 0.068931527
A12: DictaBERT | B12: exp06_ready | C12: Fusion Regular+Cascaded (Ready) | D12: Multilabel stratified (paper-style) | E12: 0.74547408 | F12: 0.81407098 | G12: 0.068596899
A13: DictaBERT | B13: exp06_ready | C13: Fusion Regular+Cascaded (Ready) | D13: Baseline (simple random split) | E13: 0.68608841 | F13: 0.78834552 | G13: 0.10225711
... A109: AlephBERT-Gimmel | B109: exp10_svm_ready | C109: SVM Router Fusion CRF (Ready) | D109: Baseline (simple random split) | E109: 0.73344026 | F109: 0.83574787 | G109: 0.10230761

Sheet paired_tests
A1: model | B1: experiment_id | C1: comparison | D1: condition | E1: n_pairs | F1: split_only_f1_mean | G1: split_only_f1_sd | H1: split_plus_aug_f1_mean | I1: split_plus_aug_f1_sd | J1: delta_mean_f1 | K1: t_statistic | L1: t_p_value | M1: t_p_lt_0_05 | N1: wilcoxon_statistic | O1: wilcoxon_p_value | P1: wilcoxon_p_lt_0_05
A2: AlephBERT-Gimmel | B2: exp01 | C2: exp07+aug vs exp07 | D2: after_label_aware_split | E2: 20 | F2: 0.65753425 | G2: 2.2781296e-16 | H2: 0.81278979 | I2: 0.010493311 | J2: 0.15525555 | K2: 66.168241 | L2: 6.2467389e-24 | M2: TRUE | N2: 0 | O2: 8.807368e-05 | P2: TRUE
A3: AlephBERT-Gimmel | B3: exp01 | C3: exp07+aug vs exp07 | D3: after_multilabel_iterative_paper | E3: 20 | F3: 0.62735344 | G3: 0.0044879969 | H3: 0.83362573 | I3: 0.0062291992 | J3: 0.20627229 | K3: 107.04308 | L3: 6.868897e-28 | M3: TRUE | N3: 0 | O3: 8.8198702e-05 | P3: TRUE
A4: AlephBERT-Gimmel | B4: exp01 | C4: exp07+aug vs exp07 | D4: before_exp01_baseline | E4: 20 | F4: 0.66407607 | G4: 0.00094151067 | H4: 0.78109951 | I4: 0.0079348035 | J4: 0.11702343 | K4: 68.899396 | L4: 2.9055089e-24 | M4: TRUE | N4: 0 | O4: 8.8323859e-05 | P4: TRUE
A5: AlephBERT-Gimmel | B5: exp04 | C5: exp07+aug vs exp07 | D5: after_label_aware_split | E5: 20 | F5: 0.71846002 | G5: 0.023684015 | H5: 0.79948866 | I5: 0.012902439 | J5: 0.081028634 | K5: 16.251209 | L5: 1.3340278e-12 | M5: TRUE | N5: 0 | O5: 1.9073486e-06 | P5: TRUE
A6: AlephBERT-Gimmel | B6: exp04 | C6: exp07+aug vs exp07 | D6: after_multilabel_iterative_paper | E6: 20 | F6: 0.72815697 | G6: 0.030732392 | H6: 0.83754064 | I6: 0.0090291163 | J6: 0.10938367 | K6: 14.303595 | L6: 1.2663179e-11 | M6: TRUE | N6: 0 | O6: 1.9073486e-06 | P6: TRUE
A7: AlephBERT-Gimmel | B7: exp04 | C7: exp07+aug vs exp07 | D7: before_exp01_baseline | E7: 20 | F7: 0.68910043 | G7: 0.036390663 | H7: 0.77985129 | I7: 0.012173331 | J7: 0.090750853 | K7: 11.601964 | L7: 4.5702535e-10 | M7: TRUE | N7: 0 | O7: 1.9073486e-06 | P7: TRUE
A8: AlephBERT-Gimmel | B8: exp05_ready | C8: exp07+aug vs exp07 | D8: after_label_aware_split | E8: 20 | F8: 0.72315463 | G8: 0.024964895 | H8: 0.79900579 | I8: 0.011169069 | J8: 0.075851163 | K8: 13.198678 | L8: 5.1060264e-11 | M8: TRUE | N8: 0 | O8: 1.9073486e-06 | P8: TRUE
A9: AlephBERT-Gimmel | B9: exp05_ready | C9: exp07+aug vs exp07 | D9: after_multilabel_iterative_paper | E9: 20 | F9: 0.72819086 | G9: 0.030997996 | H9: 0.83896085 | I9: 0.009740644 | J9: 0.11076999 | K9: 15.042204 | L9: 5.238555e-12 | M9: TRUE | N9: 0 | O9: 1.9073486e-06 | P9: TRUE
A10: AlephBERT-Gimmel | B10: exp05_ready | C10: exp07+aug vs exp07 | D10: before_exp01_baseline | E10: 20 | F10: 0.68951942 | G10: 0.035452766 | H10: 0.78390506 | I10: 0.011048798 | J10: 0.09438563 | K10: 12.334953 | L10: 1.6252034e-10 | M10: TRUE | N10: 0 | O10: 1.9073486e-06 | P10: TRUE
A11: AlephBERT-Gimmel | B11: exp06_ready | C11: exp07+aug vs exp07 | D11: after_label_aware_split | E11: 20 | F11: 0.70971459 | G11: 0.022044055 | H11: 0.81492869 | I11: 0.011708687 | J11: 0.10521411 | K11: 18.465594 | L11: 1.3521231e-13 | M11: TRUE | N11: 0 | O11: 1.9073486e-06 | P11: TRUE
A12: AlephBERT-Gimmel | B12: exp06_ready | C12: exp07+aug vs exp07 | D12: after_multilabel_iterative_paper | E12: 20 | F12: 0.70211746 | G12: 0.020099577 | H12: 0.83203844 | I12: 0.0082406378 | J12: 0.12992098 | K12: 26.822115 | L12: 1.4494762e-16 | M12: TRUE | N12: 0 | O12: 1.9073486e-06 | P12: TRUE
A13: AlephBERT-Gimmel | B13: exp06_ready | C13: exp07+aug vs exp07 | D13: before_exp01_baseline | E13: 20 | F13: 0.6912304 | G13: 0.019936274 | H13: 0.78457273 | I13: 0.012871956 | J13: 0.093342329 | K13: 19.44426 | L13: 5.3124027e-14 | M13: TRUE | N13: 0 | O13: 1.9073486e-06 | P13: TRUE
... A109: HeRo | B109: exp10_svm_ready | C109: exp07+aug vs exp07 | D109: before_exp01_baseline | E109: 20 | F109: 0.82707085 | G109: 0.01168618 | H109: 0.86734539 | I109: 0.014798319 | J109: 0.040274542 | K109: 10.354857 | L109: 2.9924065e-09 | M109: TRUE | N109: 0 | O109: 1.9073486e-06 | P109: TRUE

Sheet variant_summary
A1: data_source | B1: condition | C1: description | D1: num_runs | E1: f1_mean | F1: f1_std | G1: f1_min | H1: f1_max
A2: exp07+aug | B2: Multilabel stratified (paper-style) + Aug | C2: Paper-style iterative stratification: rarest-label-first with tie-breaks by per-label need, then fold capacity, then random + LLM mask-fill augmentation | D2: 720 | E2: 0.84370927 | F2: 0.019069257 | G2: 0.78761062 | H2: 0.89760349
A3: exp07+aug | B3: Label-aware greedy + Aug | C3: Statistical stratified sentence split preserving non-O label distribution (with best-effort train coverage) + LLM mask-fill augmentation | D3: 720 | E3: 0.8284352 | F3: 0.028566062 | G3: 0.73684211 | H3: 0.8988764
A4: exp07+aug | B4: Baseline (simple random split) + Aug | C4: Regular NER with DictaBERT + LLM mask-fill augmentation | D4: 720 | E4: 0.82010985 | F4: 0.031576195 | G4: 0.74468085 | H4: 0.90376569
A5: exp07 | B5: Label-aware greedy | C5: Statistical stratified sentence split preserving non-O label distribution (with best-effort train coverage) | D5: 720 | E5: 0.75506842 | F5: 0.05557786 | G5: 0.40883978 | H5: 0.87818697
A6: exp07 | B6: Multilabel stratified (paper-style) | C6: Paper-style iterative stratification: rarest-label-first with tie-breaks by per-label need, then fold capacity, then random | D6: 720 | E6: 0.75215259 | F6: 0.06653242 | G6: 0.4 | H6: 0.8671024
A7: exp07 | B7: Baseline (simple random split) | C7: Regular NER with DictaBERT | D7: 720 | E7: 0.73230429 | F7: 0.05552337 | G7: 0.46330275 | H7: 0.85892116

Sheet experiment_details
A1: model_name | B1: experiment_id | C1: experiment_name | D1: data_source | E1: condition_group_key | F1: condition_group_short | G1: condition_label | H1: condition_description | I1: seed | J1: f1 | K1: precision | L1: recall | M1: status | N1: result_file | O1: metrics_file | P1: elapsed_seconds
A2: DictaBERT | B2: exp01 | C2: Regular NER | D2: exp07 | E2: exp07_before_exp01_baseline | F2: Baseline (simple random split) | G2: [Exp07] Baseline (simple random split) [seed 42] | H2: Regular NER with DictaBERT | I2: 42 | J2: 0.7188755 | K2: 0.66791045 | L2: 0.77826087 | M2: ok_reused_base | N2: /content/drive/MyDrive/thesis_project/thesis/outputs/exp01/regular_ner_20260601_205916.json | O2: /content/drive/MyDrive/thesis_project/thesis/outputs/exp01/regular_ner_results_20260601_205916.xlsx | P2: 7.1
A3: DictaBERT | B3: exp01 | C3: Regular NER | D3: exp07 | E3: exp07_before_exp01_baseline | F3: Baseline (simple random split) | G3: [Exp07] Baseline (simple random split) [seed 43] | H3: Regular NER with DictaBERT | I3: 43 | J3: 0.66933868 | K3: 0.62081784 | L3: 0.72608696 | M3: ok | N3: /content/drive/MyDrive/thesis_project/thesis/outputs/exp01/regular_ner_20260601_210114.json | O3: /content/drive/MyDrive/thesis_project/thesis/outputs/exp01/regular_ner_results_20260601_210104.xlsx | P3: 119.2
A4: DictaBERT | B4: exp01 | C4: Regular NER | D4: exp07 | E4: exp07_before_exp01_baseline | F4: Baseline (simple random split) | G4: [Exp07] Baseline (simple random split) [seed 44] | H4: Regular NER with DictaBERT | I4: 44 | J4: 0.66933868 | K4: 0.62081784 | L4: 0.72608696 | M4: ok | N4: /content/drive/MyDrive/thesis_project/thesis/outputs/exp01/regular_ner_20260601_210348.json | O4: /content/drive/MyDrive/thesis_project/thesis/outputs/exp01/regular_ner_results_20260601_210348.xlsx | P4: 159.5
A5: DictaBERT | B5: exp01 | C5: Regular NER | D5: exp07 | E5: exp07_before_exp01_baseline | F5: Baseline (simple random split) | G5: [Exp07] Baseline (simple random split) [seed 45] | H5: Regular NER with DictaBERT | I5: 45 | J5: 0.66933868 | K5: 0.62081784 | L5: 0.72608696 | M5: ok | N5: /content/drive/MyDrive/thesis_project/thesis/outputs/exp01/regular_ner_20260601_210627.json | O5: /content/drive/MyDrive/thesis_project/thesis/outputs/exp01/regular_ner_results_20260601_210616.xlsx | P5: 155.6
A6: DictaBERT | B6: exp01 | C6: Regular NER | D6: exp07 | E6: exp07_before_exp01_baseline | F6: Baseline (simple random split) | G6: [Exp07] Baseline (simple random split) [seed 46] | H6: Regular NER with DictaBERT | I6: 46 | J6: 0.66933868 | K6: 0.62081784 | L6: 0.72608696 | M6: ok | N6: /content/drive/MyDrive/thesis_project/thesis/outputs/exp01/regular_ner_20260601_210903.json | O6: /content/drive/MyDrive/thesis_project/thesis/outputs/exp01/regular_ner_results_20260601_210851.xlsx | P6: 166.9
A7: DictaBERT | B7: exp01 | C7: Regular NER | D7: exp07 | E7: exp07_before_exp01_baseline | F7: Baseline (simple random split) | G7: [Exp07] Baseline (simple random split) [seed 47] | H7: Regular NER with DictaBERT | I7: 47 | J7: 0.66933868 | K7: 0.62081784 | L7: 0.72608696 | M7: ok | N7: /content/drive/MyDrive/thesis_project/thesis/outputs/exp01/regular_ner_20260601_211152.json | O7: /content/drive/MyDrive/thesis_project/thesis/outputs/exp01/regular_ner_results_20260601_211141.xlsx | P7: 180.9
A8: DictaBERT | B8: exp01 | C8: Regular NER | D8: exp07 | E8: exp07_before_exp01_baseline | F8: Baseline (simple random split) | G8: [Exp07] Baseline (simple random split) [seed 48] | H8: Regular NER with DictaBERT | I8: 48 | J8: 0.66933868 | K8: 0.62081784 | L8: 0.72608696 | M8: ok | N8: /content/drive/MyDrive/thesis_project/thesis/outputs/exp01/regular_ner_20260601_211437.json | O8: /content/drive/MyDrive/thesis_project/thesis/outputs/exp01/regular_ner_results_20260601_211428.xlsx | P8: 164.8
A9: DictaBERT | B9: exp01 | C9: Regular NER | D9: exp07 | E9: exp07_before_exp01_baseline | F9: Baseline (simple random split) | G9: [Exp07] Baseline (simple random split) [seed 49] | H9: Regular NER with DictaBERT | I9: 49 | J9: 0.66933868 | K9: 0.62081784 | L9: 0.72608696 | M9: ok | N9: /content/drive/MyDrive/thesis_project/thesis/outputs/exp01/regular_ner_20260601_211724.json | O9: /content/drive/MyDrive/thesis_project/thesis/outputs/exp01/regular_ner_results_20260601_211723.xlsx | P9: 161.6
A10: DictaBERT | B10: exp01 | C10: Regular NER | D10: exp07 | E10: exp07_before_exp01_baseline | F10: Baseline (simple random split) | G10: [Exp07] Baseline (simple random split) [seed 50] | H10: Regular NER with DictaBERT | I10: 50 | J10: 0.66933868 | K10: 0.62081784 | L10: 0.72608696 | M10: ok | N10: /content/drive/MyDrive/thesis_project/thesis/outputs/exp01/regular_ner_20260601_212004.json | O10: /content/drive/MyDrive/thesis_project/thesis/outputs/exp01/regular_ner_results_20260601_212003.xlsx | P10: 157.8
A11: DictaBERT | B11: exp01 | C11: Regular NER | D11: exp07 | E11: exp07_before_exp01_baseline | F11: Baseline (simple random split) | G11: [Exp07] Baseline (simple random split) [seed 51] | H11: Regular NER with DictaBERT | I11: 51 | J11: 0.66933868 | K11: 0.62081784 | L11: 0.72608696 | M11: ok | N11: /content/drive/MyDrive/thesis_project/thesis/outputs/exp01/regular_ner_20260601_212256.json | O11: /content/drive/MyDrive/thesis_project/thesis/outputs/exp01/regular_ner_results_20260601_212246.xlsx | P11: 183.9
A12: DictaBERT | B12: exp01 | C12: Regular NER | D12: exp07 | E12: exp07_before_exp01_baseline | F12: Baseline (simple random split) | G12: [Exp07] Baseline (simple random split) [seed 52] | H12: Regular NER with DictaBERT | I12: 52 | J12: 0.66933868 | K12: 0.62081784 | L12: 0.72608696 | M12: ok | N12: /content/drive/MyDrive/thesis_project/thesis/outputs/exp01/regular_ner_20260601_212556.json | O12: /content/drive/MyDrive/thesis_project/thesis/outputs/exp01/regular_ner_results_20260601_212546.xlsx | P12: 170.9
A13: DictaBERT | B13: exp01 | C13: Regular NER | D13: exp07 | E13: exp07_before_exp01_baseline | F13: Baseline (simple random split) | G13: [Exp07] Baseline (simple random split) [seed 53] | H13: Regular NER with DictaBERT | I13: 53 | J13: 0.66933868 | K13: 0.62081784 | L13: 0.72608696 | M13: ok | N13: /content/drive/MyDrive/thesis_project/thesis/outputs/exp01/regular_ner_20260601_212841.json | O13: /content/drive/MyDrive/thesis_project/thesis/outputs/exp01/regular_ner_results_20260601_212832.xlsx | P13: 145
... A121: DictaBERT | B121: exp01 | C121: Regular NER | D121: exp07+aug | E121: exp07aug_after_multilabel_iterative_paper | F121: Multilabel stratified (paper-style) + Aug | G121: [Exp07+Aug] Multilabel stratified (paper-style) + Augmented [seed 61] | H121: Paper-style iterative stratification: rarest-label-first with tie-breaks by per-label need, then fold capacity, then random + LLM mask-fill augmentation | I121: 61 | J121: 0.80525164 | K121: 0.78297872 | L121: 0.82882883 | M121: ok | N121: /content/drive/MyDrive/thesis_project/thesis/outputs/exp01/regular_ner_20260602_202416.json | O121: /content/drive/MyDrive/thesis_project/thesis/outputs/exp01/regular_ner_results_20260602_202416.xlsx | P121: 263.7
A122: DictaBERT | B122: exp04 | C122: AUC Cascaded Pipeline | D122: exp07 | E122: exp07_before_exp01_baseline | F122: Baseline (simple random split) | G122: [Exp07] Baseline (simple random split) [seed 42] | H122: Regular NER with DictaBERT | I122: 42 | J122: 0.74895397 | M122: ok_reused_base | N122: /content/drive/MyDrive/thesis_project/thesis/outputs/exp04/auc_cascaded_pipeline_20260601_210001.json | O122: /content/drive/MyDrive/thesis_project/thesis/outputs/exp04/cascaded_pipeline_results_20260601_210000.xlsx | P122: 0.8
A123: DictaBERT | B123: exp04 | C123: AUC Cascaded Pipeline | D123: exp07 | E123: exp07_before_exp01_baseline | F123: Baseline (simple random split) | G123: [Exp07] Baseline (simple random split) [seed 43] | H123: Regular NER with DictaBERT | I123: 43 | J123: 0.71910112 | M123: ok_reused_base | N123: /content/drive/MyDrive/thesis_project/thesis/outputs/exp04/auc_cascaded_pipeline_20260601_210200.json | O123: /content/drive/MyDrive/thesis_project/thesis/outputs/exp04/cascaded_pipeline_results_20260601_210159.xlsx | P123: 1
A124: DictaBERT | B124: exp04 | C124: AUC Cascaded Pipeline | D124: exp07 | E124: exp07_before_exp01_baseline | F124: Baseline (simple random split) | G124: [Exp07] Baseline (simple random split) [seed 44] | H124: Regular NER with DictaBERT | I124: 44 | J124: 0.70229008 | M124: ok_reused_base | N124: /content/drive/MyDrive/thesis_project/thesis/outputs/exp04/auc_cascaded_pipeline_20260601_210439.json | O124: /content/drive/MyDrive/thesis_project/thesis/outputs/exp04/cascaded_pipeline_results_20260601_210438.xlsx | P124: 0.7
A125: DictaBERT | B125: exp04 | C125: AUC Cascaded Pipeline | D125: exp07 | E125: exp07_before_exp01_baseline | F125: Baseline (simple random split) | G125: [Exp07] Baseline (simple random split) [seed 45] | H125: Regular NER with DictaBERT | I125: 45 | J125: 0.72881356 | M125: ok_reused_base | N125: /content/drive/MyDrive/thesis_project/thesis/outputs/exp04/auc_cascaded_pipeline_20260601_210715.json | O125: /content/drive/MyDrive/thesis_project/thesis/outputs/exp04/cascaded_pipeline_results_20260601_210714.xlsx | P125: 1
