Workbook

Sheet dataset_details
A1: benchmark_key | B1: benchmark_label | C1: regime | D1: variant | E1: variant_label | F1: seed | G1: pool_n_sentences | H1: split_ratio_train | I1: train_n_sentences | J1: train_n_tokens | K1: train_n_entity_spans | L1: train_entity_spans_by_type | M1: train_entity_tokens_by_type | N1: eval_n_sentences | O1: eval_n_tokens | P1: eval_n_entity_spans | Q1: eval_entity_spans_by_type | R1: eval_entity_tokens_by_type
A2: conll2003_bert | B2: CoNLL-2003 + bert-base-uncased | C2: small_300 | D2: before_exp01_baseline | E2: Baseline (simple random split) | F2: 42 | G2: 300 | H2: 0.7 | I2: 210 | J2: 3027 | K2: 376 | L2: {"LOC": 124, "MISC": 59, "ORG": 98, "PER": 95} | M2: {"LOC": 141, "MISC": 77, "ORG": 159, "PER": 153} | N2: 90 | O2: 1194 | P2: 133 | Q2: {"LOC": 43, "MISC": 16, "ORG": 44, "PER": 30} | R2: {"LOC": 49, "MISC": 19, "ORG": 56, "PER": 51}
A3: conll2003_bert | B3: CoNLL-2003 + bert-base-uncased | C3: small_300 | D3: before_exp01_baseline | E3: Baseline (simple random split) | F3: 43 | G3: 300 | H3: 0.7 | I3: 210 | J3: 3072 | K3: 356 | L3: {"LOC": 112, "MISC": 54, "ORG": 105, "PER": 85} | M3: {"LOC": 127, "MISC": 71, "ORG": 165, "PER": 134} | N3: 90 | O3: 1149 | P3: 153 | Q3: {"LOC": 55, "MISC": 21, "ORG": 37, "PER": 40} | R3: {"LOC": 63, "MISC": 25, "ORG": 50, "PER": 70}
A4: conll2003_bert | B4: CoNLL-2003 + bert-base-uncased | C4: small_300 | D4: before_exp01_baseline | E4: Baseline (simple random split) | F4: 44 | G4: 300 | H4: 0.7 | I4: 210 | J4: 2852 | K4: 358 | L4: {"LOC": 116, "MISC": 50, "ORG": 98, "PER": 94} | M4: {"LOC": 129, "MISC": 62, "ORG": 150, "PER": 145} | N4: 90 | O4: 1369 | P4: 151 | Q4: {"LOC": 51, "MISC": 25, "ORG": 44, "PER": 31} | R4: {"LOC": 61, "MISC": 34, "ORG": 65, "PER": 59}
A5: conll2003_bert | B5: CoNLL-2003 + bert-base-uncased | C5: small_300 | D5: before_exp01_baseline | E5: Baseline (simple random split) | F5: 45 | G5: 300 | H5: 0.7 | I5: 210 | J5: 2947 | K5: 362 | L5: {"LOC": 120, "MISC": 51, "ORG": 107, "PER": 84} | M5: {"LOC": 136, "MISC": 61, "ORG": 160, "PER": 137} | N5: 90 | O5: 1274 | P5: 147 | Q5: {"LOC": 47, "MISC": 24, "ORG": 35, "PER": 41} | R5: {"LOC": 54, "MISC": 35, "ORG": 55, "PER": 67}
A6: conll2003_bert | B6: CoNLL-2003 + bert-base-uncased | C6: small_300 | D6: before_exp01_baseline | E6: Baseline (simple random split) | F6: 46 | G6: 300 | H6: 0.7 | I6: 210 | J6: 3074 | K6: 377 | L6: {"LOC": 121, "MISC": 59, "ORG": 104, "PER": 93} | M6: {"LOC": 142, "MISC": 77, "ORG": 162, "PER": 148} | N6: 90 | O6: 1147 | P6: 132 | Q6: {"LOC": 46, "MISC": 16, "ORG": 38, "PER": 32} | R6: {"LOC": 48, "MISC": 19, "ORG": 53, "PER": 56}
A7: conll2003_bert | B7: CoNLL-2003 + bert-base-uncased | C7: small_300 | D7: before_exp01_baseline | E7: Baseline (simple random split) | F7: 47 | G7: 300 | H7: 0.7 | I7: 210 | J7: 2940 | K7: 341 | L7: {"LOC": 112, "MISC": 51, "ORG": 101, "PER": 77} | M7: {"LOC": 131, "MISC": 69, "ORG": 152, "PER": 123} | N7: 90 | O7: 1281 | P7: 168 | Q7: {"LOC": 55, "MISC": 24, "ORG": 41, "PER": 48} | R7: {"LOC": 59, "MISC": 27, "ORG": 63, "PER": 81}
A8: conll2003_bert | B8: CoNLL-2003 + bert-base-uncased | C8: small_300 | D8: before_exp01_baseline | E8: Baseline (simple random split) | F8: 48 | G8: 300 | H8: 0.7 | I8: 210 | J8: 2938 | K8: 359 | L8: {"LOC": 116, "MISC": 53, "ORG": 102, "PER": 88} | M8: {"LOC": 135, "MISC": 68, "ORG": 147, "PER": 146} | N8: 90 | O8: 1283 | P8: 150 | Q8: {"LOC": 51, "MISC": 22, "ORG": 40, "PER": 37} | R8: {"LOC": 55, "MISC": 28, "ORG": 68, "PER": 58}
A9: conll2003_bert | B9: CoNLL-2003 + bert-base-uncased | C9: small_300 | D9: before_exp01_baseline | E9: Baseline (simple random split) | F9: 49 | G9: 300 | H9: 0.7 | I9: 210 | J9: 3080 | K9: 359 | L9: {"LOC": 118, "MISC": 52, "ORG": 93, "PER": 96} | M9: {"LOC": 132, "MISC": 69, "ORG": 145, "PER": 157} | N9: 90 | O9: 1141 | P9: 150 | Q9: {"LOC": 49, "MISC": 23, "ORG": 49, "PER": 29} | R9: {"LOC": 58, "MISC": 27, "ORG": 70, "PER": 47}
A10: conll2003_bert | B10: CoNLL-2003 + bert-base-uncased | C10: small_300 | D10: before_exp01_baseline | E10: Baseline (simple random split) | F10: 50 | G10: 300 | H10: 0.7 | I10: 210 | J10: 3007 | K10: 378 | L10: {"LOC": 127, "MISC": 54, "ORG": 101, "PER": 96} | M10: {"LOC": 143, "MISC": 67, "ORG": 157, "PER": 156} | N10: 90 | O10: 1214 | P10: 131 | Q10: {"LOC": 40, "MISC": 21, "ORG": 41, "PER": 29} | R10: {"LOC": 47, "MISC": 29, "ORG": 58, "PER": 48}
A11: conll2003_bert | B11: CoNLL-2003 + bert-base-uncased | C11: small_300 | D11: before_exp01_baseline | E11: Baseline (simple random split) | F11: 51 | G11: 300 | H11: 0.7 | I11: 210 | J11: 2858 | K11: 365 | L11: {"LOC": 132, "MISC": 55, "ORG": 91, "PER": 87} | M11: {"LOC": 149, "MISC": 69, "ORG": 143, "PER": 140} | N11: 90 | O11: 1363 | P11: 144 | Q11: {"LOC": 35, "MISC": 20, "ORG": 51, "PER": 38} | R11: {"LOC": 41, "MISC": 27, "ORG": 72, "PER": 64}
A12: conll2003_bert | B12: CoNLL-2003 + bert-base-uncased | C12: small_300 | D12: before_exp01_baseline | E12: Baseline (simple random split) | F12: 52 | G12: 300 | H12: 0.7 | I12: 210 | J12: 2864 | K12: 342 | L12: {"LOC": 110, "MISC": 45, "ORG": 97, "PER": 90} | M12: {"LOC": 127, "MISC": 60, "ORG": 154, "PER": 144} | N12: 90 | O12: 1357 | P12: 167 | Q12: {"LOC": 57, "MISC": 30, "ORG": 45, "PER": 35} | R12: {"LOC": 63, "MISC": 36, "ORG": 61, "PER": 60}
A13: conll2003_bert | B13: CoNLL-2003 + bert-base-uncased | C13: small_300 | D13: before_exp01_baseline | E13: Baseline (simple random split) | F13: 53 | G13: 300 | H13: 0.7 | I13: 210 | J13: 3125 | K13: 367 | L13: {"LOC": 129, "MISC": 59, "ORG": 85, "PER": 94} | M13: {"LOC": 142, "MISC": 74, "ORG": 133, "PER": 158} | N13: 90 | O13: 1096 | P13: 142 | Q13: {"LOC": 38, "MISC": 16, "ORG": 57, "PER": 31} | R13: {"LOC": 48, "MISC": 22, "ORG": 82, "PER": 46}
... A121: bc5cdr_pubmedbert | B121: BC5CDR + PubMedBERT | C121: small_300 | D121: after_multilabel_iterative_paper | E121: Multilabel stratified (paper-style) | F121: 61 | G121: 300 | H121: 0.7 | I121: 210 | J121: 4436 | K121: 290 | L121: {"ORG": 99, "PER": 191} | M121: {"ORG": 119, "PER": 367} | N121: 90 | O121: 1831 | P121: 137 | Q121: {"ORG": 52, "PER": 85} | R121: {"ORG": 60, "PER": 156}

Sheet summary_pivot
A1: benchmark | B1: experiment_id | C1: regime | D1: split_variant | E1: f1_mean | F1: f1_std | G1: n_seeds
A2: BC5CDR + PubMedBERT | B2: exp10_cascade | C2: small_300 | D2: Baseline (simple random split) | E2: 0.62173846 | F2: 0.045572292 | G2: 40
A3: BC5CDR + PubMedBERT | B3: exp10_cascade | C3: small_300 | D3: Multilabel stratified (paper-style) | E3: 0.62764395 | F3: 0.03097933 | G3: 40
A4: BC5CDR + PubMedBERT | B4: exp10_regular | C4: small_300 | D4: Baseline (simple random split) | E4: 0.74763303 | F4: 0.067302727 | G4: 40
A5: BC5CDR + PubMedBERT | B5: exp10_regular | C5: small_300 | D5: Multilabel stratified (paper-style) | E5: 0.74730314 | F5: 0.074337283 | G5: 40
A6: BC5CDR + PubMedBERT | B6: exp10_svm_ready | C6: small_300 | D6: Baseline (simple random split) | E6: 0.7606799 | F6: 0.067153102 | G6: 40
A7: BC5CDR + PubMedBERT | B7: exp10_svm_ready | C7: small_300 | D7: Multilabel stratified (paper-style) | E7: 0.76595126 | F7: 0.071015353 | G7: 40
A8: CoNLL-2003 + bert-base-uncased | B8: exp10_cascade | C8: small_300 | D8: Baseline (simple random split) | E8: 0.67403304 | F8: 0.12569874 | G8: 40
A9: CoNLL-2003 + bert-base-uncased | B9: exp10_cascade | C9: small_300 | D9: Multilabel stratified (paper-style) | E9: 0.70850563 | F9: 0.07355812 | G9: 40
A10: CoNLL-2003 + bert-base-uncased | B10: exp10_regular | C10: small_300 | D10: Baseline (simple random split) | E10: 0.69111911 | F10: 0.11154515 | G10: 40
A11: CoNLL-2003 + bert-base-uncased | B11: exp10_regular | C11: small_300 | D11: Multilabel stratified (paper-style) | E11: 0.70771167 | F11: 0.095865284 | G11: 40
A12: CoNLL-2003 + bert-base-uncased | B12: exp10_svm_ready | C12: small_300 | D12: Baseline (simple random split) | E12: 0.74117305 | F12: 0.10257745 | G12: 40
A13: CoNLL-2003 + bert-base-uncased | B13: exp10_svm_ready | C13: small_300 | D13: Multilabel stratified (paper-style) | E13: 0.7548556 | F13: 0.084578066 | G13: 40
... A19: NEMO + DictaBERT | B19: exp10_svm_ready | C19: small_300 | D19: Multilabel stratified (paper-style) | E19: 0.6605081 | F19: 0.11378707 | G19: 40

Sheet summary_by_train_mode
A1: NON-AUGMENTED RESULTS | I1: AUGMENTED RESULTS
A2: benchmark | B2: experiment_id | C2: regime | D2: split_variant | E2: f1_mean | F2: f1_std | G2: n_seeds | I2: benchmark | J2: experiment_id | K2: regime | L2: split_variant | M2: f1_mean | N2: f1_std | O2: n_seeds
A3: BC5CDR + PubMedBERT | B3: exp10_cascade | C3: small_300 | D3: Baseline (simple random split) | E3: =AVERAGEIFS(all_runs!$S$2:$S$721,all_runs!$B$2:$B$721,$A3,all_runs!$E$2:$E$721,$B3,all_runs!$H$2:$H$721,$C3,all_runs!$J$2:$J$721,$D3,all_runs!$AB$2:$AB$721,"<>augmented") -> 0.60246709 | F3: {=_xlfn.STDEV.S(_xlfn._xlws.FILTER(all_runs!$S$2:$S$721,(all_runs!$B$2:$B$721=$A3)*(all_runs!$E$2:$E$721=$B3)*(all_runs!$H$2:$H$721=$C3)*(all_runs!$J$2:$J$721=$D3)*(all_runs!$AB$2:$AB$721<>"augmented")))} -> 0.052403855 | G3: =COUNTIFS(all_runs!$B$2:$B$721,$A3,all_runs!$E$2:$E$721,$B3,all_runs!$H$2:$H$721,$C3,all_runs!$J$2:$J$721,$D3,all_runs!$AB$2:$AB$721,"<>augmented") -> 20 | I3: BC5CDR + PubMedBERT | J3: exp10_cascade | K3: small_300 | L3: Baseline (simple random split) | M3: =AVERAGEIFS(all_runs!$S$2:$S$721,all_runs!$B$2:$B$721,$I3,all_runs!$E$2:$E$721,$J3,all_runs!$H$2:$H$721,$K3,all_runs!$J$2:$J$721,$L3,all_runs!$AB$2:$AB$721,"augmented") -> 0.64100983 | N3: {=_xlfn.STDEV.S(_xlfn._xlws.FILTER(all_runs!$S$2:$S$721,(all_runs!$B$2:$B$721=$I3)*(all_runs!$E$2:$E$721=$J3)*(all_runs!$H$2:$H$721=$K3)*(all_runs!$J$2:$J$721=$L3)*(all_runs!$AB$2:$AB$721="augmented")))} -> 0.027109881 | O3: =COUNTIFS(all_runs!$B$2:$B$721,$I3,all_runs!$E$2:$E$721,$J3,all_runs!$H$2:$H$721,$K3,all_runs!$J$2:$J$721,$L3,all_runs!$AB$2:$AB$721,"augmented") -> 20
A4: BC5CDR + PubMedBERT | B4: exp10_cascade | C4: small_300 | D4: Multilabel stratified (paper-style) | E4: =AVERAGEIFS(all_runs!$S$2:$S$721,all_runs!$B$2:$B$721,$A4,all_runs!$E$2:$E$721,$B4,all_runs!$H$2:$H$721,$C4,all_runs!$J$2:$J$721,$D4,all_runs!$AB$2:$AB$721,"<>augmented") -> 0.6063987 | F4: {=_xlfn.STDEV.S(_xlfn._xlws.FILTER(all_runs!$S$2:$S$721,(all_runs!$B$2:$B$721=$A4)*(all_runs!$E$2:$E$721=$B4)*(all_runs!$H$2:$H$721=$C4)*(all_runs!$J$2:$J$721=$D4)*(all_runs!$AB$2:$AB$721<>"augmented")))} -> 0.024495259 | G4: =COUNTIFS(all_runs!$B$2:$B$721,$A4,all_runs!$E$2:$E$721,$B4,all_runs!$H$2:$H$721,$C4,all_runs!$J$2:$J$721,$D4,all_runs!$AB$2:$AB$721,"<>augmented") -> 20 | I4: BC5CDR + PubMedBERT | J4: exp10_cascade | K4: small_300 | L4: Multilabel stratified (paper-style) | M4: =AVERAGEIFS(all_runs!$S$2:$S$721,all_runs!$B$2:$B$721,$I4,all_runs!$E$2:$E$721,$J4,all_runs!$H$2:$H$721,$K4,all_runs!$J$2:$J$721,$L4,all_runs!$AB$2:$AB$721,"augmented") -> 0.64888919 | N4: {=_xlfn.STDEV.S(_xlfn._xlws.FILTER(all_runs!$S$2:$S$721,(all_runs!$B$2:$B$721=$I4)*(all_runs!$E$2:$E$721=$J4)*(all_runs!$H$2:$H$721=$K4)*(all_runs!$J$2:$J$721=$L4)*(all_runs!$AB$2:$AB$721="augmented")))} -> 0.020486561 | O4: =COUNTIFS(all_runs!$B$2:$B$721,$I4,all_runs!$E$2:$E$721,$J4,all_runs!$H$2:$H$721,$K4,all_runs!$J$2:$J$721,$L4,all_runs!$AB$2:$AB$721,"augmented") -> 20
A5: BC5CDR + PubMedBERT | B5: exp10_regular | C5: small_300 | D5: Baseline (simple random split) | E5: =AVERAGEIFS(all_runs!$S$2:$S$721,all_runs!$B$2:$B$721,$A5,all_runs!$E$2:$E$721,$B5,all_runs!$H$2:$H$721,$C5,all_runs!$J$2:$J$721,$D5,all_runs!$AB$2:$AB$721,"<>augmented") -> 0.68791002 | F5: {=_xlfn.STDEV.S(_xlfn._xlws.FILTER(all_runs!$S$2:$S$721,(all_runs!$B$2:$B$721=$A5)*(all_runs!$E$2:$E$721=$B5)*(all_runs!$H$2:$H$721=$C5)*(all_runs!$J$2:$J$721=$D5)*(all_runs!$AB$2:$AB$721<>"augmented")))} -> 0.032834187 | G5: =COUNTIFS(all_runs!$B$2:$B$721,$A5,all_runs!$E$2:$E$721,$B5,all_runs!$H$2:$H$721,$C5,all_runs!$J$2:$J$721,$D5,all_runs!$AB$2:$AB$721,"<>augmented") -> 20 | I5: BC5CDR + PubMedBERT | J5: exp10_regular | K5: small_300 | L5: Baseline (simple random split) | M5: =AVERAGEIFS(all_runs!$S$2:$S$721,all_runs!$B$2:$B$721,$I5,all_runs!$E$2:$E$721,$J5,all_runs!$H$2:$H$721,$K5,all_runs!$J$2:$J$721,$L5,all_runs!$AB$2:$AB$721,"augmented") -> 0.80735604 | N5: {=_xlfn.STDEV.S(_xlfn._xlws.FILTER(all_runs!$S$2:$S$721,(all_runs!$B$2:$B$721=$I5)*(all_runs!$E$2:$E$721=$J5)*(all_runs!$H$2:$H$721=$K5)*(all_runs!$J$2:$J$721=$L5)*(all_runs!$AB$2:$AB$721="augmented")))} -> 0.026655219 | O5: =COUNTIFS(all_runs!$B$2:$B$721,$I5,all_runs!$E$2:$E$721,$J5,all_runs!$H$2:$H$721,$K5,all_runs!$J$2:$J$721,$L5,all_runs!$AB$2:$AB$721,"augmented") -> 20
A6: BC5CDR + PubMedBERT | B6: exp10_regular | C6: small_300 | D6: Multilabel stratified (paper-style) | E6: =AVERAGEIFS(all_runs!$S$2:$S$721,all_runs!$B$2:$B$721,$A6,all_runs!$E$2:$E$721,$B6,all_runs!$H$2:$H$721,$C6,all_runs!$J$2:$J$721,$D6,all_runs!$AB$2:$AB$721,"<>augmented") -> 0.68303504 | F6: {=_xlfn.STDEV.S(_xlfn._xlws.FILTER(all_runs!$S$2:$S$721,(all_runs!$B$2:$B$721=$A6)*(all_runs!$E$2:$E$721=$B6)*(all_runs!$H$2:$H$721=$C6)*(all_runs!$J$2:$J$721=$D6)*(all_runs!$AB$2:$AB$721<>"augmented")))} -> 0.046267696 | G6: =COUNTIFS(all_runs!$B$2:$B$721,$A6,all_runs!$E$2:$E$721,$B6,all_runs!$H$2:$H$721,$C6,all_runs!$J$2:$J$721,$D6,all_runs!$AB$2:$AB$721,"<>augmented") -> 20 | I6: BC5CDR + PubMedBERT | J6: exp10_regular | K6: small_300 | L6: Multilabel stratified (paper-style) | M6: =AVERAGEIFS(all_runs!$S$2:$S$721,all_runs!$B$2:$B$721,$I6,all_runs!$E$2:$E$721,$J6,all_runs!$H$2:$H$721,$K6,all_runs!$J$2:$J$721,$L6,all_runs!$AB$2:$AB$721,"augmented") -> 0.81157125 | N6: {=_xlfn.STDEV.S(_xlfn._xlws.FILTER(all_runs!$S$2:$S$721,(all_runs!$B$2:$B$721=$I6)*(all_runs!$E$2:$E$721=$J6)*(all_runs!$H$2:$H$721=$K6)*(all_runs!$J$2:$J$721=$L6)*(all_runs!$AB$2:$AB$721="augmented")))} -> 0.022508898 | O6: =COUNTIFS(all_runs!$B$2:$B$721,$I6,all_runs!$E$2:$E$721,$J6,all_runs!$H$2:$H$721,$K6,all_runs!$J$2:$J$721,$L6,all_runs!$AB$2:$AB$721,"augmented") -> 20
A7: BC5CDR + PubMedBERT | B7: exp10_svm_ready | C7: small_300 | D7: Baseline (simple random split) | E7: =AVERAGEIFS(all_runs!$S$2:$S$721,all_runs!$B$2:$B$721,$A7,all_runs!$E$2:$E$721,$B7,all_runs!$H$2:$H$721,$C7,all_runs!$J$2:$J$721,$D7,all_runs!$AB$2:$AB$721,"<>augmented") -> 0.70804581 | F7: {=_xlfn.STDEV.S(_xlfn._xlws.FILTER(all_runs!$S$2:$S$721,(all_runs!$B$2:$B$721=$A7)*(all_runs!$E$2:$E$721=$B7)*(all_runs!$H$2:$H$721=$C7)*(all_runs!$J$2:$J$721=$D7)*(all_runs!$AB$2:$AB$721<>"augmented")))} -> 0.051462267 | G7: =COUNTIFS(all_runs!$B$2:$B$721,$A7,all_runs!$E$2:$E$721,$B7,all_runs!$H$2:$H$721,$C7,all_runs!$J$2:$J$721,$D7,all_runs!$AB$2:$AB$721,"<>augmented") -> 20 | I7: BC5CDR + PubMedBERT | J7: exp10_svm_ready | K7: small_300 | L7: Baseline (simple random split) | M7: =AVERAGEIFS(all_runs!$S$2:$S$721,all_runs!$B$2:$B$721,$I7,all_runs!$E$2:$E$721,$J7,all_runs!$H$2:$H$721,$K7,all_runs!$J$2:$J$721,$L7,all_runs!$AB$2:$AB$721,"augmented") -> 0.81331399 | N7: {=_xlfn.STDEV.S(_xlfn._xlws.FILTER(all_runs!$S$2:$S$721,(all_runs!$B$2:$B$721=$I7)*(all_runs!$E$2:$E$721=$J7)*(all_runs!$H$2:$H$721=$K7)*(all_runs!$J$2:$J$721=$L7)*(all_runs!$AB$2:$AB$721="augmented")))} -> 0.027852241 | O7: =COUNTIFS(all_runs!$B$2:$B$721,$I7,all_runs!$E$2:$E$721,$J7,all_runs!$H$2:$H$721,$K7,all_runs!$J$2:$J$721,$L7,all_runs!$AB$2:$AB$721,"augmented") -> 20
A8: BC5CDR + PubMedBERT | B8: exp10_svm_ready | C8: small_300 | D8: Multilabel stratified (paper-style) | E8: =AVERAGEIFS(all_runs!$S$2:$S$721,all_runs!$B$2:$B$721,$A8,all_runs!$E$2:$E$721,$B8,all_runs!$H$2:$H$721,$C8,all_runs!$J$2:$J$721,$D8,all_runs!$AB$2:$AB$721,"<>augmented") -> 0.70808852 | F8: {=_xlfn.STDEV.S(_xlfn._xlws.FILTER(all_runs!$S$2:$S$721,(all_runs!$B$2:$B$721=$A8)*(all_runs!$E$2:$E$721=$B8)*(all_runs!$H$2:$H$721=$C8)*(all_runs!$J$2:$J$721=$D8)*(all_runs!$AB$2:$AB$721<>"augmented")))} -> 0.051352003 | G8: =COUNTIFS(all_runs!$B$2:$B$721,$A8,all_runs!$E$2:$E$721,$B8,all_runs!$H$2:$H$721,$C8,all_runs!$J$2:$J$721,$D8,all_runs!$AB$2:$AB$721,"<>augmented") -> 20 | I8: BC5CDR + PubMedBERT | J8: exp10_svm_ready | K8: small_300 | L8: Multilabel stratified (paper-style) | M8: =AVERAGEIFS(all_runs!$S$2:$S$721,all_runs!$B$2:$B$721,$I8,all_runs!$E$2:$E$721,$J8,all_runs!$H$2:$H$721,$K8,all_runs!$J$2:$J$721,$L8,all_runs!$AB$2:$AB$721,"augmented") -> 0.82381399 | N8: {=_xlfn.STDEV.S(_xlfn._xlws.FILTER(all_runs!$S$2:$S$721,(all_runs!$B$2:$B$721=$I8)*(all_runs!$E$2:$E$721=$J8)*(all_runs!$H$2:$H$721=$K8)*(all_runs!$J$2:$J$721=$L8)*(all_runs!$AB$2:$AB$721="augmented")))} -> 0.025809682 | O8: =COUNTIFS(all_runs!$B$2:$B$721,$I8,all_runs!$E$2:$E$721,$J8,all_runs!$H$2:$H$721,$K8,all_runs!$J$2:$J$721,$L8,all_runs!$AB$2:$AB$721,"augmented") -> 20
A9: CoNLL-2003 + bert-base-uncased | B9: exp10_cascade | C9: small_300 | D9: Baseline (simple random split) | E9: =AVERAGEIFS(all_runs!$S$2:$S$721,all_runs!$B$2:$B$721,$A9,all_runs!$E$2:$E$721,$B9,all_runs!$H$2:$H$721,$C9,all_runs!$J$2:$J$721,$D9,all_runs!$AB$2:$AB$721,"<>augmented") -> 0.57401274 | F9: {=_xlfn.STDEV.S(_xlfn._xlws.FILTER(all_runs!$S$2:$S$721,(all_runs!$B$2:$B$721=$A9)*(all_runs!$E$2:$E$721=$B9)*(all_runs!$H$2:$H$721=$C9)*(all_runs!$J$2:$J$721=$D9)*(all_runs!$AB$2:$AB$721<>"augmented")))} -> 0.098690914 | G9: =COUNTIFS(all_runs!$B$2:$B$721,$A9,all_runs!$E$2:$E$721,$B9,all_runs!$H$2:$H$721,$C9,all_runs!$J$2:$J$721,$D9,all_runs!$AB$2:$AB$721,"<>augmented") -> 20 | I9: CoNLL-2003 + bert-base-uncased | J9: exp10_cascade | K9: small_300 | L9: Baseline (simple random split) | M9: =AVERAGEIFS(all_runs!$S$2:$S$721,all_runs!$B$2:$B$721,$I9,all_runs!$E$2:$E$721,$J9,all_runs!$H$2:$H$721,$K9,all_runs!$J$2:$J$721,$L9,all_runs!$AB$2:$AB$721,"augmented") -> 0.77405335 | N9: {=_xlfn.STDEV.S(_xlfn._xlws.FILTER(all_runs!$S$2:$S$721,(all_runs!$B$2:$B$721=$I9)*(all_runs!$E$2:$E$721=$J9)*(all_runs!$H$2:$H$721=$K9)*(all_runs!$J$2:$J$721=$L9)*(all_runs!$AB$2:$AB$721="augmented")))} -> 0.040383855 | O9: =COUNTIFS(all_runs!$B$2:$B$721,$I9,all_runs!$E$2:$E$721,$J9,all_runs!$H$2:$H$721,$K9,all_runs!$J$2:$J$721,$L9,all_runs!$AB$2:$AB$721,"augmented") -> 20
A10: CoNLL-2003 + bert-base-uncased | B10: exp10_cascade | C10: small_300 | D10: Multilabel stratified (paper-style) | E10: =AVERAGEIFS(all_runs!$S$2:$S$721,all_runs!$B$2:$B$721,$A10,all_runs!$E$2:$E$721,$B10,all_runs!$H$2:$H$721,$C10,all_runs!$J$2:$J$721,$D10,all_runs!$AB$2:$AB$721,"<>augmented") -> 0.64210807 | F10: {=_xlfn.STDEV.S(_xlfn._xlws.FILTER(all_runs!$S$2:$S$721,(all_runs!$B$2:$B$721=$A10)*(all_runs!$E$2:$E$721=$B10)*(all_runs!$H$2:$H$721=$C10)*(all_runs!$J$2:$J$721=$D10)*(all_runs!$AB$2:$AB$721<>"augmented")))} -> 0.031472505 | G10: =COUNTIFS(all_runs!$B$2:$B$721,$A10,all_runs!$E$2:$E$721,$B10,all_runs!$H$2:$H$721,$C10,all_runs!$J$2:$J$721,$D10,all_runs!$AB$2:$AB$721,"<>augmented") -> 20 | I10: CoNLL-2003 + bert-base-uncased | J10: exp10_cascade | K10: small_300 | L10: Multilabel stratified (paper-style) | M10: =AVERAGEIFS(all_runs!$S$2:$S$721,all_runs!$B$2:$B$721,$I10,all_runs!$E$2:$E$721,$J10,all_runs!$H$2:$H$721,$K10,all_runs!$J$2:$J$721,$L10,all_runs!$AB$2:$AB$721,"augmented") -> 0.77490319 | N10: {=_xlfn.STDEV.S(_xlfn._xlws.FILTER(all_runs!$S$2:$S$721,(all_runs!$B$2:$B$721=$I10)*(all_runs!$E$2:$E$721=$J10)*(all_runs!$H$2:$H$721=$K10)*(all_runs!$J$2:$J$721=$L10)*(all_runs!$AB$2:$AB$721="augmented")))} -> 0.028887989 | O10: =COUNTIFS(all_runs!$B$2:$B$721,$I10,all_runs!$E$2:$E$721,$J10,all_runs!$H$2:$H$721,$K10,all_runs!$J$2:$J$721,$L10,all_runs!$AB$2:$AB$721,"augmented") -> 20
A11: CoNLL-2003 + bert-base-uncased | B11: exp10_regular | C11: small_300 | D11: Baseline (simple random split) | E11: =AVERAGEIFS(all_runs!$S$2:$S$721,all_runs!$B$2:$B$721,$A11,all_runs!$E$2:$E$721,$B11,all_runs!$H$2:$H$721,$C11,all_runs!$J$2:$J$721,$D11,all_runs!$AB$2:$AB$721,"<>augmented") -> 0.58682867 | F11: {=_xlfn.STDEV.S(_xlfn._xlws.FILTER(all_runs!$S$2:$S$721,(all_runs!$B$2:$B$721=$A11)*(all_runs!$E$2:$E$721=$B11)*(all_runs!$H$2:$H$721=$C11)*(all_runs!$J$2:$J$721=$D11)*(all_runs!$AB$2:$AB$721<>"augmented")))} -> 0.033086539 | G11: =COUNTIFS(all_runs!$B$2:$B$721,$A11,all_runs!$E$2:$E$721,$B11,all_runs!$H$2:$H$721,$C11,all_runs!$J$2:$J$721,$D11,all_runs!$AB$2:$AB$721,"<>augmented") -> 20 | I11: CoNLL-2003 + bert-base-uncased | J11: exp10_regular | K11: small_300 | L11: Baseline (simple random split) | M11: =AVERAGEIFS(all_runs!$S$2:$S$721,all_runs!$B$2:$B$721,$I11,all_runs!$E$2:$E$721,$J11,all_runs!$H$2:$H$721,$K11,all_runs!$J$2:$J$721,$L11,all_runs!$AB$2:$AB$721,"augmented") -> 0.79540954 | N11: {=_xlfn.STDEV.S(_xlfn._xlws.FILTER(all_runs!$S$2:$S$721,(all_runs!$B$2:$B$721=$I11)*(all_runs!$E$2:$E$721=$J11)*(all_runs!$H$2:$H$721=$K11)*(all_runs!$J$2:$J$721=$L11)*(all_runs!$AB$2:$AB$721="augmented")))} -> 0.039330608 | O11: =COUNTIFS(all_runs!$B$2:$B$721,$I11,all_runs!$E$2:$E$721,$J11,all_runs!$H$2:$H$721,$K11,all_runs!$J$2:$J$721,$L11,all_runs!$AB$2:$AB$721,"augmented") -> 20
A12: CoNLL-2003 + bert-base-uncased | B12: exp10_regular | C12: small_300 | D12: Multilabel stratified (paper-style) | E12: =AVERAGEIFS(all_runs!$S$2:$S$721,all_runs!$B$2:$B$721,$A12,all_runs!$E$2:$E$721,$B12,all_runs!$H$2:$H$721,$C12,all_runs!$J$2:$J$721,$D12,all_runs!$AB$2:$AB$721,"<>augmented") -> 0.61788983 | F12: {=_xlfn.STDEV.S(_xlfn._xlws.FILTER(all_runs!$S$2:$S$721,(all_runs!$B$2:$B$721=$A12)*(all_runs!$E$2:$E$721=$B12)*(all_runs!$H$2:$H$721=$C12)*(all_runs!$J$2:$J$721=$D12)*(all_runs!$AB$2:$AB$721<>"augmented")))} -> 0.027045759 | G12: =COUNTIFS(all_runs!$B$2:$B$721,$A12,all_runs!$E$2:$E$721,$B12,all_runs!$H$2:$H$721,$C12,all_runs!$J$2:$J$721,$D12,all_runs!$AB$2:$AB$721,"<>augmented") -> 20 | I12: CoNLL-2003 + bert-base-uncased | J12: exp10_regular | K12: small_300 | L12: Multilabel stratified (paper-style) | M12: =AVERAGEIFS(all_runs!$S$2:$S$721,all_runs!$B$2:$B$721,$I12,all_runs!$E$2:$E$721,$J12,all_runs!$H$2:$H$721,$K12,all_runs!$J$2:$J$721,$L12,all_runs!$AB$2:$AB$721,"augmented") -> 0.7975335 | N12: {=_xlfn.STDEV.S(_xlfn._xlws.FILTER(all_runs!$S$2:$S$721,(all_runs!$B$2:$B$721=$I12)*(all_runs!$E$2:$E$721=$J12)*(all_runs!$H$2:$H$721=$K12)*(all_runs!$J$2:$J$721=$L12)*(all_runs!$AB$2:$AB$721="augmented")))} -> 0.033872428 | O12: =COUNTIFS(all_runs!$B$2:$B$721,$I12,all_runs!$E$2:$E$721,$J12,all_runs!$H$2:$H$721,$K12,all_runs!$J$2:$J$721,$L12,all_runs!$AB$2:$AB$721,"augmented") -> 20
A13: CoNLL-2003 + bert-base-uncased | B13: exp10_svm_ready | C13: small_300 | D13: Baseline (simple random split) | E13: =AVERAGEIFS(all_runs!$S$2:$S$721,all_runs!$B$2:$B$721,$A13,all_runs!$E$2:$E$721,$B13,all_runs!$H$2:$H$721,$C13,all_runs!$J$2:$J$721,$D13,all_runs!$AB$2:$AB$721,"<>augmented") -> 0.64811017 | F13: {=_xlfn.STDEV.S(_xlfn._xlws.FILTER(all_runs!$S$2:$S$721,(all_runs!$B$2:$B$721=$A13)*(all_runs!$E$2:$E$721=$B13)*(all_runs!$H$2:$H$721=$C13)*(all_runs!$J$2:$J$721=$D13)*(all_runs!$AB$2:$AB$721<>"augmented")))} -> 0.041227839 | G13: =COUNTIFS(all_runs!$B$2:$B$721,$A13,all_runs!$E$2:$E$721,$B13,all_runs!$H$2:$H$721,$C13,all_runs!$J$2:$J$721,$D13,all_runs!$AB$2:$AB$721,"<>augmented") -> 20 | I13: CoNLL-2003 + bert-base-uncased | J13: exp10_svm_ready | K13: small_300 | L13: Baseline (simple random split) | M13: =AVERAGEIFS(all_runs!$S$2:$S$721,all_runs!$B$2:$B$721,$I13,all_runs!$E$2:$E$721,$J13,all_runs!$H$2:$H$721,$K13,all_runs!$J$2:$J$721,$L13,all_runs!$AB$2:$AB$721,"augmented") -> 0.83423594 | N13: {=_xlfn.STDEV.S(_xlfn._xlws.FILTER(all_runs!$S$2:$S$721,(all_runs!$B$2:$B$721=$I13)*(all_runs!$E$2:$E$721=$J13)*(all_runs!$H$2:$H$721=$K13)*(all_runs!$J$2:$J$721=$L13)*(all_runs!$AB$2:$AB$721="augmented")))} -> 0.040807797 | O13: =COUNTIFS(all_runs!$B$2:$B$721,$I13,all_runs!$E$2:$E$721,$J13,all_runs!$H$2:$H$721,$K13,all_runs!$J$2:$J$721,$L13,all_runs!$AB$2:$AB$721,"augmented") -> 20
A14: CoNLL-2003 + bert-base-uncased | B14: exp10_svm_ready | C14: small_300 | D14: Multilabel stratified (paper-style) | E14: =AVERAGEIFS(all_runs!$S$2:$S$721,all_runs!$B$2:$B$721,$A14,all_runs!$E$2:$E$721,$B14,all_runs!$H$2:$H$721,$C14,all_runs!$J$2:$J$721,$D14,all_runs!$AB$2:$AB$721,"<>augmented") -> 0.67590087 | F14: {=_xlfn.STDEV.S(_xlfn._xlws.FILTER(all_runs!$S$2:$S$721,(all_runs!$B$2:$B$721=$A14)*(all_runs!$E$2:$E$721=$B14)*(all_runs!$H$2:$H$721=$C14)*(all_runs!$J$2:$J$721=$D14)*(all_runs!$AB$2:$AB$721<>"augmented")))} -> 0.026383569 | G14: =COUNTIFS(all_runs!$B$2:$B$721,$A14,all_runs!$E$2:$E$721,$B14,all_runs!$H$2:$H$721,$C14,all_runs!$J$2:$J$721,$D14,all_runs!$AB$2:$AB$721,"<>augmented") -> 20 | I14: CoNLL-2003 + bert-base-uncased | J14: exp10_svm_ready | K14: small_300 | L14: Multilabel stratified (paper-style) | M14: =AVERAGEIFS(all_runs!$S$2:$S$721,all_runs!$B$2:$B$721,$I14,all_runs!$E$2:$E$721,$J14,all_runs!$H$2:$H$721,$K14,all_runs!$J$2:$J$721,$L14,all_runs!$AB$2:$AB$721,"augmented") -> 0.83381033 | N14: {=_xlfn.STDEV.S(_xlfn._xlws.FILTER(all_runs!$S$2:$S$721,(all_runs!$B$2:$B$721=$I14)*(all_runs!$E$2:$E$721=$J14)*(all_runs!$H$2:$H$721=$K14)*(all_runs!$J$2:$J$721=$L14)*(all_runs!$AB$2:$AB$721="augmented")))} -> 0.029383834 | O14: =COUNTIFS(all_runs!$B$2:$B$721,$I14,all_runs!$E$2:$E$721,$J14,all_runs!$H$2:$H$721,$K14,all_runs!$J$2:$J$721,$L14,all_runs!$AB$2:$AB$721,"augmented") -> 20
... A20: NEMO + DictaBERT | B20: exp10_svm_ready | C20: small_300 | D20: Multilabel stratified (paper-style) | E20: =AVERAGEIFS(all_runs!$S$2:$S$721,all_runs!$B$2:$B$721,$A20,all_runs!$E$2:$E$721,$B20,all_runs!$H$2:$H$721,$C20,all_runs!$J$2:$J$721,$D20,all_runs!$AB$2:$AB$721,"<>augmented") -> 0.56688177 | F20: {=_xlfn.STDEV.S(_xlfn._xlws.FILTER(all_runs!$S$2:$S$721,(all_runs!$B$2:$B$721=$A20)*(all_runs!$E$2:$E$721=$B20)*(all_runs!$H$2:$H$721=$C20)*(all_runs!$J$2:$J$721=$D20)*(all_runs!$AB$2:$AB$721<>"augmented")))} -> 0.067641856 | G20: =COUNTIFS(all_runs!$B$2:$B$721,$A20,all_runs!$E$2:$E$721,$B20,all_runs!$H$2:$H$721,$C20,all_runs!$J$2:$J$721,$D20,all_runs!$AB$2:$AB$721,"<>augmented") -> 20 | I20: NEMO + DictaBERT | J20: exp10_svm_ready | K20: small_300 | L20: Multilabel stratified (paper-style) | M20: =AVERAGEIFS(all_runs!$S$2:$S$721,all_runs!$B$2:$B$721,$I20,all_runs!$E$2:$E$721,$J20,all_runs!$H$2:$H$721,$K20,all_runs!$J$2:$J$721,$L20,all_runs!$AB$2:$AB$721,"augmented") -> 0.75413443 | N20: {=_xlfn.STDEV.S(_xlfn._xlws.FILTER(all_runs!$S$2:$S$721,(all_runs!$B$2:$B$721=$I20)*(all_runs!$E$2:$E$721=$J20)*(all_runs!$H$2:$H$721=$K20)*(all_runs!$J$2:$J$721=$L20)*(all_runs!$AB$2:$AB$721="augmented")))} -> 0.059552645 | O20: =COUNTIFS(all_runs!$B$2:$B$721,$I20,all_runs!$E$2:$E$721,$J20,all_runs!$H$2:$H$721,$K20,all_runs!$J$2:$J$721,$L20,all_runs!$AB$2:$AB$721,"augmented") -> 20

Sheet all_runs
A1: benchmark_key | B1: benchmark_label | C1: model_id | D1: model_name | E1: experiment_id | F1: experiment_name | G1: data_source | H1: regime | I1: variant | J1: variant_label | K1: condition_key | L1: condition_group_key | M1: condition_group_short | N1: condition_label | O1: condition_short | P1: condition_description | Q1: seed | R1: is_baseline | S1: f1 | T1: precision | U1: recall | V1: status | W1: result_file | X1: metrics_file | Y1: base_artifacts_reused | Z1: base_mode | AA1: elapsed_seconds | AB1: train_mode
A2: conll2003_bert | B2: CoNLL-2003 + bert-base-uncased | C2: bert-base-uncased | D2: CoNLL-2003 + bert-base-uncased | E2: exp10_regular | F2: Regular NER (BERT-CRF) | G2: small_300 | H2: small_300 | I2: before_exp01_baseline | J2: Baseline (simple random split) | K2: conll2003_bert__small_300__before_exp01_baseline__seed42 | L2: conll2003_bert__small_300__before_exp01_baseline | M2: small_300 / Baseline (simple random split) | N2: [CoNLL-2003 + bert-base-uncased] [small_300] Baseline (simple random split) [seed 42] | O2: small_300 / Baseline (simple random split) [s42] | P2: Regular NER with DictaBERT | Q2: 42 | R2: TRUE | S2: 0.58823529 | T2: 0.54487179 | U2: 0.63909774 | V2: ok | W2: /content/drive/MyDrive/thesis_project/thesis/outputs/exp10_regular/regular_ner_crf_20260807_070538.json | X2: /content/drive/MyDrive/thesis_project/thesis/outputs/exp10_regular/regular_ner_crf_results_20260807_070535.xlsx | Y2: FALSE | Z2: auto | AA2: 121.8
A3: conll2003_bert | B3: CoNLL-2003 + bert-base-uncased | C3: bert-base-uncased | D3: CoNLL-2003 + bert-base-uncased | E3: exp10_regular | F3: Regular NER (BERT-CRF) | G3: small_300 | H3: small_300 | I3: before_exp01_baseline | J3: Baseline (simple random split) | K3: conll2003_bert__small_300__before_exp01_baseline__seed43 | L3: conll2003_bert__small_300__before_exp01_baseline | M3: small_300 / Baseline (simple random split) | N3: [CoNLL-2003 + bert-base-uncased] [small_300] Baseline (simple random split) [seed 43] | O3: small_300 / Baseline (simple random split) [s43] | P3: Regular NER with DictaBERT | Q3: 43 | R3: TRUE | S3: 0.6163142 | T3: 0.57303371 | U3: 0.66666667 | V3: ok | W3: /content/drive/MyDrive/thesis_project/thesis/outputs/exp10_regular/regular_ner_crf_20260807_070730.json | X3: /content/drive/MyDrive/thesis_project/thesis/outputs/exp10_regular/regular_ner_crf_results_20260807_070730.xlsx | Y3: FALSE | Z3: auto | AA3: 108.2
A4: conll2003_bert | B4: CoNLL-2003 + bert-base-uncased | C4: bert-base-uncased | D4: CoNLL-2003 + bert-base-uncased | E4: exp10_regular | F4: Regular NER (BERT-CRF) | G4: small_300 | H4: small_300 | I4: before_exp01_baseline | J4: Baseline (simple random split) | K4: conll2003_bert__small_300__before_exp01_baseline__seed44 | L4: conll2003_bert__small_300__before_exp01_baseline | M4: small_300 / Baseline (simple random split) | N4: [CoNLL-2003 + bert-base-uncased] [small_300] Baseline (simple random split) [seed 44] | O4: small_300 / Baseline (simple random split) [s44] | P4: Regular NER with DictaBERT | Q4: 44 | R4: TRUE | S4: 0.58385093 | T4: 0.5497076 | U4: 0.62251656 | V4: ok | W4: /content/drive/MyDrive/thesis_project/thesis/outputs/exp10_regular/regular_ner_crf_20260807_070918.json | X4: /content/drive/MyDrive/thesis_project/thesis/outputs/exp10_regular/regular_ner_crf_results_20260807_070918.xlsx | Y4: FALSE | Z4: auto | AA4: 111.2
A5: conll2003_bert | B5: CoNLL-2003 + bert-base-uncased | C5: bert-base-uncased | D5: CoNLL-2003 + bert-base-uncased | E5: exp10_regular | F5: Regular NER (BERT-CRF) | G5: small_300 | H5: small_300 | I5: before_exp01_baseline | J5: Baseline (simple random split) | K5: conll2003_bert__small_300__before_exp01_baseline__seed45 | L5: conll2003_bert__small_300__before_exp01_baseline | M5: small_300 / Baseline (simple random split) | N5: [CoNLL-2003 + bert-base-uncased] [small_300] Baseline (simple random split) [seed 45] | O5: small_300 / Baseline (simple random split) [s45] | P5: Regular NER with DictaBERT | Q5: 45 | R5: TRUE | S5: 0.62745098 | T5: 0.60377358 | U5: 0.65306122 | V5: ok | W5: /content/drive/MyDrive/thesis_project/thesis/outputs/exp10_regular/regular_ner_crf_20260807_071110.json | X5: /content/drive/MyDrive/thesis_project/thesis/outputs/exp10_regular/regular_ner_crf_results_20260807_071109.xlsx | Y5: FALSE | Z5: auto | AA5: 111.2
A6: conll2003_bert | B6: CoNLL-2003 + bert-base-uncased | C6: bert-base-uncased | D6: CoNLL-2003 + bert-base-uncased | E6: exp10_regular | F6: Regular NER (BERT-CRF) | G6: small_300 | H6: small_300 | I6: before_exp01_baseline | J6: Baseline (simple random split) | K6: conll2003_bert__small_300__before_exp01_baseline__seed46 | L6: conll2003_bert__small_300__before_exp01_baseline | M6: small_300 / Baseline (simple random split) | N6: [CoNLL-2003 + bert-base-uncased] [small_300] Baseline (simple random split) [seed 46] | O6: small_300 / Baseline (simple random split) [s46] | P6: Regular NER with DictaBERT | Q6: 46 | R6: TRUE | S6: 0.63043478 | T6: 0.60416667 | U6: 0.65909091 | V6: ok | W6: /content/drive/MyDrive/thesis_project/thesis/outputs/exp10_regular/regular_ner_crf_20260807_071301.json | X6: /content/drive/MyDrive/thesis_project/thesis/outputs/exp10_regular/regular_ner_crf_results_20260807_071300.xlsx | Y6: FALSE | Z6: auto | AA6: 107.8
A7: conll2003_bert | B7: CoNLL-2003 + bert-base-uncased | C7: bert-base-uncased | D7: CoNLL-2003 + bert-base-uncased | E7: exp10_regular | F7: Regular NER (BERT-CRF) | G7: small_300 | H7: small_300 | I7: before_exp01_baseline | J7: Baseline (simple random split) | K7: conll2003_bert__small_300__before_exp01_baseline__seed47 | L7: conll2003_bert__small_300__before_exp01_baseline | M7: small_300 / Baseline (simple random split) | N7: [CoNLL-2003 + bert-base-uncased] [small_300] Baseline (simple random split) [seed 47] | O7: small_300 / Baseline (simple random split) [s47] | P7: Regular NER with DictaBERT | Q7: 47 | R7: TRUE | S7: 0.62889518 | T7: 0.6 | U7: 0.66071429 | V7: ok | W7: /content/drive/MyDrive/thesis_project/thesis/outputs/exp10_regular/regular_ner_crf_20260807_071449.json | X7: /content/drive/MyDrive/thesis_project/thesis/outputs/exp10_regular/regular_ner_crf_results_20260807_071449.xlsx | Y7: FALSE | Z7: auto | AA7: 69.5
A8: conll2003_bert | B8: CoNLL-2003 + bert-base-uncased | C8: bert-base-uncased | D8: CoNLL-2003 + bert-base-uncased | E8: exp10_regular | F8: Regular NER (BERT-CRF) | G8: small_300 | H8: small_300 | I8: before_exp01_baseline | J8: Baseline (simple random split) | K8: conll2003_bert__small_300__before_exp01_baseline__seed48 | L8: conll2003_bert__small_300__before_exp01_baseline | M8: small_300 / Baseline (simple random split) | N8: [CoNLL-2003 + bert-base-uncased] [small_300] Baseline (simple random split) [seed 48] | O8: small_300 / Baseline (simple random split) [s48] | P8: Regular NER with DictaBERT | Q8: 48 | R8: TRUE | S8: 0.60493827 | T8: 0.56321839 | U8: 0.65333333 | V8: ok | W8: /content/drive/MyDrive/thesis_project/thesis/outputs/exp10_regular/regular_ner_crf_20260807_071558.json | X8: /content/drive/MyDrive/thesis_project/thesis/outputs/exp10_regular/regular_ner_crf_results_20260807_071557.xlsx | Y8: FALSE | Z8: auto | AA8: 109.9
A9: conll2003_bert | B9: CoNLL-2003 + bert-base-uncased | C9: bert-base-uncased | D9: CoNLL-2003 + bert-base-uncased | E9: exp10_regular | F9: Regular NER (BERT-CRF) | G9: small_300 | H9: small_300 | I9: before_exp01_baseline | J9: Baseline (simple random split) | K9: conll2003_bert__small_300__before_exp01_baseline__seed49 | L9: conll2003_bert__small_300__before_exp01_baseline | M9: small_300 / Baseline (simple random split) | N9: [CoNLL-2003 + bert-base-uncased] [small_300] Baseline (simple random split) [seed 49] | O9: small_300 / Baseline (simple random split) [s49] | P9: Regular NER with DictaBERT | Q9: 49 | R9: TRUE | S9: 0.55238095 | T9: 0.52727273 | U9: 0.58 | V9: ok | W9: /content/drive/MyDrive/thesis_project/thesis/outputs/exp10_regular/regular_ner_crf_20260807_071747.json | X9: /content/drive/MyDrive/thesis_project/thesis/outputs/exp10_regular/regular_ner_crf_results_20260807_071747.xlsx | Y9: FALSE | Z9: auto | AA9: 67.5
A10: conll2003_bert | B10: CoNLL-2003 + bert-base-uncased | C10: bert-base-uncased | D10: CoNLL-2003 + bert-base-uncased | E10: exp10_regular | F10: Regular NER (BERT-CRF) | G10: small_300 | H10: small_300 | I10: before_exp01_baseline | J10: Baseline (simple random split) | K10: conll2003_bert__small_300__before_exp01_baseline__seed50 | L10: conll2003_bert__small_300__before_exp01_baseline | M10: small_300 / Baseline (simple random split) | N10: [CoNLL-2003 + bert-base-uncased] [small_300] Baseline (simple random split) [seed 50] | O10: small_300 / Baseline (simple random split) [s50] | P10: Regular NER with DictaBERT | Q10: 50 | R10: TRUE | S10: 0.55319149 | T10: 0.51655629 | U10: 0.59541985 | V10: ok | W10: /content/drive/MyDrive/thesis_project/thesis/outputs/exp10_regular/regular_ner_crf_20260807_071856.json | X10: /content/drive/MyDrive/thesis_project/thesis/outputs/exp10_regular/regular_ner_crf_results_20260807_071856.xlsx | Y10: FALSE | Z10: auto | AA10: 110.1
A11: conll2003_bert | B11: CoNLL-2003 + bert-base-uncased | C11: bert-base-uncased | D11: CoNLL-2003 + bert-base-uncased | E11: exp10_regular | F11: Regular NER (BERT-CRF) | G11: small_300 | H11: small_300 | I11: before_exp01_baseline | J11: Baseline (simple random split) | K11: conll2003_bert__small_300__before_exp01_baseline__seed51 | L11: conll2003_bert__small_300__before_exp01_baseline | M11: small_300 / Baseline (simple random split) | N11: [CoNLL-2003 + bert-base-uncased] [small_300] Baseline (simple random split) [seed 51] | O11: small_300 / Baseline (simple random split) [s51] | P11: Regular NER with DictaBERT | Q11: 51 | R11: TRUE | S11: 0.62987013 | T11: 0.59146341 | U11: 0.67361111 | V11: ok | W11: /content/drive/MyDrive/thesis_project/thesis/outputs/exp10_regular/regular_ner_crf_20260807_072046.json | X11: /content/drive/MyDrive/thesis_project/thesis/outputs/exp10_regular/regular_ner_crf_results_20260807_072045.xlsx | Y11: FALSE | Z11: auto | AA11: 70.4
A12: conll2003_bert | B12: CoNLL-2003 + bert-base-uncased | C12: bert-base-uncased | D12: CoNLL-2003 + bert-base-uncased | E12: exp10_regular | F12: Regular NER (BERT-CRF) | G12: small_300 | H12: small_300 | I12: before_exp01_baseline | J12: Baseline (simple random split) | K12: conll2003_bert__small_300__before_exp01_baseline__seed52 | L12: conll2003_bert__small_300__before_exp01_baseline | M12: small_300 / Baseline (simple random split) | N12: [CoNLL-2003 + bert-base-uncased] [small_300] Baseline (simple random split) [seed 52] | O12: small_300 / Baseline (simple random split) [s52] | P12: Regular NER with DictaBERT | Q12: 52 | R12: TRUE | S12: 0.55270655 | T12: 0.52717391 | U12: 0.58083832 | V12: ok | W12: /content/drive/MyDrive/thesis_project/thesis/outputs/exp10_regular/regular_ner_crf_20260807_072156.json | X12: /content/drive/MyDrive/thesis_project/thesis/outputs/exp10_regular/regular_ner_crf_results_20260807_072155.xlsx | Y12: FALSE | Z12: auto | AA12: 108.3
A13: conll2003_bert | B13: CoNLL-2003 + bert-base-uncased | C13: bert-base-uncased | D13: CoNLL-2003 + bert-base-uncased | E13: exp10_regular | F13: Regular NER (BERT-CRF) | G13: small_300 | H13: small_300 | I13: before_exp01_baseline | J13: Baseline (simple random split) | K13: conll2003_bert__small_300__before_exp01_baseline__seed53 | L13: conll2003_bert__small_300__before_exp01_baseline | M13: small_300 / Baseline (simple random split) | N13: [CoNLL-2003 + bert-base-uncased] [small_300] Baseline (simple random split) [seed 53] | O13: small_300 / Baseline (simple random split) [s53] | P13: Regular NER with DictaBERT | Q13: 53 | R13: TRUE | S13: 0.57605178 | T13: 0.53293413 | U13: 0.62676056 | V13: ok | W13: /content/drive/MyDrive/thesis_project/thesis/outputs/exp10_regular/regular_ner_crf_20260807_072343.json | X13: /content/drive/MyDrive/thesis_project/thesis/outputs/exp10_regular/regular_ner_crf_results_20260807_072343.xlsx | Y13: FALSE | Z13: auto | AA13: 107.7
... A41: conll2003_bert | B41: CoNLL-2003 + bert-base-uncased | C41: bert-base-uncased | D41: CoNLL-2003 + bert-base-uncased | E41: exp10_regular | F41: Regular NER (BERT-CRF) | G41: small_300 | H41: small_300 | I41: after_multilabel_iterative_paper | J41: Multilabel stratified (paper-style) | K41: conll2003_bert__small_300__after_multilabel_iterative_paper__seed61 | L41: conll2003_bert__small_300__after_multilabel_iterative_paper | M41: small_300 / Multilabel stratified (paper-style) | N41: [CoNLL-2003 + bert-base-uncased] [small_300] Multilabel stratified (paper-style) [seed 61] | O41: small_300 / Multilabel stratified (paper-style) [s61] | P41: Paper-style iterative stratification: rarest-label-first with tie-breaks by per-label need, then fold capacity, then random | Q41: 61 | R41: FALSE | S41: 0.60674157 | T41: 0.57754011 | U41: 0.63905325 | V41: ok | W41: /content/drive/MyDrive/thesis_project/thesis/outputs/exp10_regular/regular_ner_crf_20260807_100913.json | X41: /content/drive/MyDrive/thesis_project/thesis/outputs/exp10_regular/regular_ner_crf_results_20260807_100912.xlsx | Y41: FALSE | Z41: auto | AA41: 107
A42: conll2003_bert | B42: CoNLL-2003 + bert-base-uncased | C42: bert-base-uncased | D42: CoNLL-2003 + bert-base-uncased | E42: exp10_cascade | F42: Cascaded Pipeline (CRF + Consistency) | G42: small_300 | H42: small_300 | I42: before_exp01_baseline | J42: Baseline (simple random split) | K42: conll2003_bert__small_300__before_exp01_baseline__seed42 | L42: conll2003_bert__small_300__before_exp01_baseline | M42: small_300 / Baseline (simple random split) | N42: [CoNLL-2003 + bert-base-uncased] [small_300] Baseline (simple random split) [seed 42] | O42: small_300 / Baseline (simple random split) [s42] | P42: Regular NER with DictaBERT | Q42: 42 | R42: TRUE | S42: 0.64748201 | V42: ok_reused_base | W42: /content/drive/MyDrive/thesis_project/thesis/outputs/exp10_cascade/cascaded_pipeline_crf_20260807_070708.json | X42: /content/drive/MyDrive/thesis_project/thesis/outputs/exp10_cascade/cascaded_pipeline_crf_results_20260807_070703.xlsx | Y42: TRUE | Z42: auto | AA42: 0.2
A43: conll2003_bert | B43: CoNLL-2003 + bert-base-uncased | C43: bert-base-uncased | D43: CoNLL-2003 + bert-base-uncased | E43: exp10_cascade | F43: Cascaded Pipeline (CRF + Consistency) | G43: small_300 | H43: small_300 | I43: before_exp01_baseline | J43: Baseline (simple random split) | K43: conll2003_bert__small_300__before_exp01_baseline__seed43 | L43: conll2003_bert__small_300__before_exp01_baseline | M43: small_300 / Baseline (simple random split) | N43: [CoNLL-2003 + bert-base-uncased] [small_300] Baseline (simple random split) [seed 43] | O43: small_300 / Baseline (simple random split) [s43] | P43: Regular NER with DictaBERT | Q43: 43 | R43: TRUE | S43: 0.63722397 | V43: ok_reused_base | W43: /content/drive/MyDrive/thesis_project/thesis/outputs/exp10_cascade/cascaded_pipeline_crf_20260807_070856.json | X43: /content/drive/MyDrive/thesis_project/thesis/outputs/exp10_cascade/cascaded_pipeline_crf_results_20260807_070855.xlsx | Y43: TRUE | Z43: auto | AA43: 0.2
A44: conll2003_bert | B44: CoNLL-2003 + bert-base-uncased | C44: bert-base-uncased | D44: CoNLL-2003 + bert-base-uncased | E44: exp10_cascade | F44: Cascaded Pipeline (CRF + Consistency) | G44: small_300 | H44: small_300 | I44: before_exp01_baseline | J44: Baseline (simple random split) | K44: conll2003_bert__small_300__before_exp01_baseline__seed44 | L44: conll2003_bert__small_300__before_exp01_baseline | M44: small_300 / Baseline (simple random split) | N44: [CoNLL-2003 + bert-base-uncased] [small_300] Baseline (simple random split) [seed 44] | O44: small_300 / Baseline (simple random split) [s44] | P44: Regular NER with DictaBERT | Q44: 44 | R44: TRUE | S44: 0.56426332 | V44: ok_reused_base | W44: /content/drive/MyDrive/thesis_project/thesis/outputs/exp10_cascade/cascaded_pipeline_crf_20260807_071047.json | X44: /content/drive/MyDrive/thesis_project/thesis/outputs/exp10_cascade/cascaded_pipeline_crf_results_20260807_071046.xlsx | Y44: TRUE | Z44: auto | AA44: 0.2
A45: conll2003_bert | B45: CoNLL-2003 + bert-base-uncased | C45: bert-base-uncased | D45: CoNLL-2003 + bert-base-uncased | E45: exp10_cascade | F45: Cascaded Pipeline (CRF + Consistency) | G45: small_300 | H45: small_300 | I45: before_exp01_baseline | J45: Baseline (simple random split) | K45: conll2003_bert__small_300__before_exp01_baseline__seed45 | L45: conll2003_bert__small_300__before_exp01_baseline | M45: small_300 / Baseline (simple random split) | N45: [CoNLL-2003 + bert-base-uncased] [small_300] Baseline (simple random split) [seed 45] | O45: small_300 / Baseline (simple random split) [s45] | P45: Regular NER with DictaBERT | Q45: 45 | R45: TRUE | S45: 0.62626263 | V45: ok_reused_base | W45: /content/drive/MyDrive/thesis_project/thesis/outputs/exp10_cascade/cascaded_pipeline_crf_20260807_071239.json | X45: /content/drive/MyDrive/thesis_project/thesis/outputs/exp10_cascade/cascaded_pipeline_crf_results_20260807_071237.xlsx | Y45: TRUE | Z45: auto | AA45: 0.2
A46: conll2003_bert | B46: CoNLL-2003 + bert-base-uncased | C46: bert-base-uncased | D46: CoNLL-2003 + bert-base-uncased | E46: exp10_cascade | F46: Cascaded Pipeline (CRF + Consistency) | G46: small_300 | H46: small_300 | I46: before_exp01_baseline | J46: Baseline (simple random split) | K46: conll2003_bert__small_300__before_exp01_baseline__seed46 | L46: conll2003_bert__small_300__before_exp01_baseline | M46: small_300 / Baseline (simple random split) | N46: [CoNLL-2003 + bert-base-uncased] [small_300] Baseline (simple random split) [seed 46] | O46: small_300 / Baseline (simple random split) [s46] | P46: Regular NER with DictaBERT | Q46: 46 | R46: TRUE | S46: 0.61538462 | V46: ok_reused_base | W46: /content/drive/MyDrive/thesis_project/thesis/outputs/exp10_cascade/cascaded_pipeline_crf_20260807_071427.json | X46: /content/drive/MyDrive/thesis_project/thesis/outputs/exp10_cascade/cascaded_pipeline_crf_results_20260807_071426.xlsx | Y46: TRUE | Z46: auto | AA46: 0.2
A47: conll2003_bert | B47: CoNLL-2003 + bert-base-uncased | C47: bert-base-uncased | D47: CoNLL-2003 + bert-base-uncased | E47: exp10_cascade | F47: Cascaded Pipeline (CRF + Consistency) | G47: small_300 | H47: small_300 | I47: before_exp01_baseline | J47: Baseline (simple random split) | K47: conll2003_bert__small_300__before_exp01_baseline__seed47 | L47: conll2003_bert__small_300__before_exp01_baseline | M47: small_300 / Baseline (simple random split) | N47: [CoNLL-2003 + bert-base-uncased] [small_300] Baseline (simple random split) [seed 47] | O47: small_300 / Baseline (simple random split) [s47] | P47: Regular NER with DictaBERT | Q47: 47 | R47: TRUE | S47: 0.31404959 | V47: ok_reused_base | W47: /content/drive/MyDrive/thesis_project/thesis/outputs/exp10_cascade/cascaded_pipeline_crf_20260807_071536.json | X47: /content/drive/MyDrive/thesis_project/thesis/outputs/exp10_cascade/cascaded_pipeline_crf_results_20260807_071535.xlsx | Y47: TRUE | Z47: auto | AA47: 0.2
A48: conll2003_bert | B48: CoNLL-2003 + bert-base-uncased | C48: bert-base-uncased | D48: CoNLL-2003 + bert-base-uncased | E48: exp10_cascade | F48: Cascaded Pipeline (CRF + Consistency) | G48: small_300 | H48: small_300 | I48: before_exp01_baseline | J48: Baseline (simple random split) | K48: conll2003_bert__small_300__before_exp01_baseline__seed48 | L48: conll2003_bert__small_300__before_exp01_baseline | M48: small_300 / Baseline (simple random split) | N48: [CoNLL-2003 + bert-base-uncased] [small_300] Baseline (simple random split) [seed 48] | O48: small_300 / Baseline (simple random split) [s48] | P48: Regular NER with DictaBERT | Q48: 48 | R48: TRUE | S48: 0.61442006 | V48: ok_reused_base | W48: /content/drive/MyDrive/thesis_project/thesis/outputs/exp10_cascade/cascaded_pipeline_crf_20260807_071726.json | X48: /content/drive/MyDrive/thesis_project/thesis/outputs/exp10_cascade/cascaded_pipeline_crf_results_20260807_071724.xlsx | Y48: TRUE | Z48: auto | AA48: 0.2
A49: conll2003_bert | B49: CoNLL-2003 + bert-base-uncased | C49: bert-base-uncased | D49: CoNLL-2003 + bert-base-uncased | E49: exp10_cascade | F49: Cascaded Pipeline (CRF + Consistency) | G49: small_300 | H49: small_300 | I49: before_exp01_baseline | J49: Baseline (simple random split) | K49: conll2003_bert__small_300__before_exp01_baseline__seed49 | L49: conll2003_bert__small_300__before_exp01_baseline | M49: small_300 / Baseline (simple random split) | N49: [CoNLL-2003 + bert-base-uncased] [small_300] Baseline (simple random split) [seed 49] | O49: small_300 / Baseline (simple random split) [s49] | P49: Regular NER with DictaBERT | Q49: 49 | R49: TRUE | S49: 0.406639 | V49: ok_reused_base | W49: /content/drive/MyDrive/thesis_project/thesis/outputs/exp10_cascade/cascaded_pipeline_crf_20260807_071833.json | X49: /content/drive/MyDrive/thesis_project/thesis/outputs/exp10_cascade/cascaded_pipeline_crf_results_20260807_071833.xlsx | Y49: TRUE | Z49: auto | AA49: 0.2
A50: conll2003_bert | B50: CoNLL-2003 + bert-base-uncased | C50: bert-base-uncased | D50: CoNLL-2003 + bert-base-uncased | E50: exp10_cascade | F50: Cascaded Pipeline (CRF + Consistency) | G50: small_300 | H50: small_300 | I50: before_exp01_baseline | J50: Baseline (simple random split) | K50: conll2003_bert__small_300__before_exp01_baseline__seed50 | L50: conll2003_bert__small_300__before_exp01_baseline | M50: small_300 / Baseline (simple random split) | N50: [CoNLL-2003 + bert-base-uncased] [small_300] Baseline (simple random split) [seed 50] | O50: small_300 / Baseline (simple random split) [s50] | P50: Regular NER with DictaBERT | Q50: 50 | R50: TRUE | S50: 0.5734767 | V50: ok_reused_base | W50: /content/drive/MyDrive/thesis_project/thesis/outputs/exp10_cascade/cascaded_pipeline_crf_20260807_072024.json | X50: /content/drive/MyDrive/thesis_project/thesis/outputs/exp10_cascade/cascaded_pipeline_crf_results_20260807_072023.xlsx | Y50: TRUE | Z50: auto | AA50: 0.2
A51: conll2003_bert | B51: CoNLL-2003 + bert-base-uncased | C51: bert-base-uncased | D51: CoNLL-2003 + bert-base-uncased | E51: exp10_cascade | F51: Cascaded Pipeline (CRF + Consistency) | G51: small_300 | H51: small_300 | I51: before_exp01_baseline | J51: Baseline (simple random split) | K51: conll2003_bert__small_300__before_exp01_baseline__seed51 | L51: conll2003_bert__small_300__before_exp01_baseline | M51: small_300 / Baseline (simple random split) | N51: [CoNLL-2003 + bert-base-uncased] [small_300] Baseline (simple random split) [seed 51] | O51: small_300 / Baseline (simple random split) [s51] | P51: Regular NER with DictaBERT | Q51: 51 | R51: TRUE | S51: 0.425 | V51: ok_reused_base | W51: /content/drive/MyDrive/thesis_project/thesis/outputs/exp10_cascade/cascaded_pipeline_crf_20260807_072134.json | X51: /content/drive/MyDrive/thesis_project/thesis/outputs/exp10_cascade/cascaded_pipeline_crf_results_20260807_072133.xlsx | Y51: TRUE | Z51: auto | AA51: 0.1
A52: conll2003_bert | B52: CoNLL-2003 + bert-base-uncased | C52: bert-base-uncased | D52: CoNLL-2003 + bert-base-uncased | E52: exp10_cascade | F52: Cascaded Pipeline (CRF + Consistency) | G52: small_300 | H52: small_300 | I52: before_exp01_baseline | J52: Baseline (simple random split) | K52: conll2003_bert__small_300__before_exp01_baseline__seed52 | L52: conll2003_bert__small_300__before_exp01_baseline | M52: small_300 / Baseline (simple random split) | N52: [CoNLL-2003 + bert-base-uncased] [small_300] Baseline (simple random split) [seed 52] | O52: small_300 / Baseline (simple random split) [s52] | P52: Regular NER with DictaBERT | Q52: 52 | R52: TRUE | S52: 0.64880952 | V52: ok_reused_base | W52: /content/drive/MyDrive/thesis_project/thesis/outputs/exp10_cascade/cascaded_pipeline_crf_20260807_072322.json | X52: /content/drive/MyDrive/thesis_project/thesis/outputs/exp10_cascade/cascaded_pipeline_crf_results_20260807_072321.xlsx | Y52: TRUE | Z52: auto | AA52: 0.2
A53: conll2003_bert | B53: CoNLL-2003 + bert-base-uncased | C53: bert-base-uncased | D53: CoNLL-2003 + bert-base-uncased | E53: exp10_cascade | F53: Cascaded Pipeline (CRF + Consistency) | G53: small_300 | H53: small_300 | I53: before_exp01_baseline | J53: Baseline (simple random split) | K53: conll2003_bert__small_300__before_exp01_baseline__seed53 | L53: conll2003_bert__small_300__before_exp01_baseline | M53: small_300 / Baseline (simple random split) | N53: [CoNLL-2003 + bert-base-uncased] [small_300] Baseline (simple random split) [seed 53] | O53: small_300 / Baseline (simple random split) [s53] | P53: Regular NER with DictaBERT | Q53: 53 | R53: TRUE | S53: 0.56862745 | V53: ok_reused_base | W53: /content/drive/MyDrive/thesis_project/thesis/outputs/exp10_cascade/cascaded_pipeline_crf_20260807_072510.json | X53: /content/drive/MyDrive/thesis_project/thesis/outputs/exp10_cascade/cascaded_pipeline_crf_results_20260807_072509.xlsx | Y53: TRUE | Z53: auto | AA53: 0.2
... A81: conll2003_bert | B81: CoNLL-2003 + bert-base-uncased | C81: bert-base-uncased | D81: CoNLL-2003 + bert-base-uncased | E81: exp10_cascade | F81: Cascaded Pipeline (CRF + Consistency) | G81: small_300 | H81: small_300 | I81: after_multilabel_iterative_paper | J81: Multilabel stratified (paper-style) | K81: conll2003_bert__small_300__after_multilabel_iterative_paper__seed61 | L81: conll2003_bert__small_300__after_multilabel_iterative_paper | M81: small_300 / Multilabel stratified (paper-style) | N81: [CoNLL-2003 + bert-base-uncased] [small_300] Multilabel stratified (paper-style) [seed 61] | O81: small_300 / Multilabel stratified (paper-style) [s61] | P81: Paper-style iterative stratification: rarest-label-first with tie-breaks by per-label need, then fold capacity, then random | Q81: 61 | R81: FALSE | S81: 0.64880952 | V81: ok_reused_base | W81: /content/drive/MyDrive/thesis_project/thesis/outputs/exp10_cascade/cascaded_pipeline_crf_20260807_101039.json | X81: /content/drive/MyDrive/thesis_project/thesis/outputs/exp10_cascade/cascaded_pipeline_crf_results_20260807_101038.xlsx | Y81: TRUE | Z81: auto | AA81: 0
A82: conll2003_bert | B82: CoNLL-2003 + bert-base-uncased | C82: bert-base-uncased | D82: CoNLL-2003 + bert-base-uncased | E82: exp10_svm_ready | F82: SVM Router Fusion CRF (Ready) | G82: small_300 | H82: small_300 | I82: before_exp01_baseline | J82: Baseline (simple random split) | K82: conll2003_bert__small_300__before_exp01_baseline__seed42 | L82: conll2003_bert__small_300__before_exp01_baseline | M82: small_300 / Baseline (simple random split) | N82: [CoNLL-2003 + bert-base-uncased] [small_300] Baseline (simple random split) [seed 42] | O82: small_300 / Baseline (simple random split) [s42] | P82: Regular NER with DictaBERT | Q82: 42 | R82: TRUE | S82: 0.6953405 | T82: 0.66438356 | U82: 0.72932331 | V82: ok | W82: /content/drive/MyDrive/thesis_project/thesis/outputs/exp10_svm_ready/fusion_svm_crf_ready_20260807_101049.json | X82: /content/drive/MyDrive/thesis_project/thesis/outputs/exp10_svm_ready/fusion_svm_crf_ready_results_20260807_101046.xlsx | Y82: TRUE | Z82: auto | AA82: 6.3
A83: conll2003_bert | B83: CoNLL-2003 + bert-base-uncased | C83: bert-base-uncased | D83: CoNLL-2003 + bert-base-uncased | E83: exp10_svm_ready | F83: SVM Router Fusion CRF (Ready) | G83: small_300 | H83: small_300 | I83: before_exp01_baseline | J83: Baseline (simple random split) | K83: conll2003_bert__small_300__before_exp01_baseline__seed43 | L83: conll2003_bert__small_300__before_exp01_baseline | M83: small_300 / Baseline (simple random split) | N83: [CoNLL-2003 + bert-base-uncased] [small_300] Baseline (simple random split) [seed 43] | O83: small_300 / Baseline (simple random split) [s43] | P83: Regular NER with DictaBERT | Q83: 43 | R83: TRUE | S83: 0.71028037 | T83: 0.67857143 | U83: 0.74509804 | V83: ok | W83: /content/drive/MyDrive/thesis_project/thesis/outputs/exp10_svm_ready/fusion_svm_crf_ready_20260807_101053.json | X83: /content/drive/MyDrive/thesis_project/thesis/outputs/exp10_svm_ready/fusion_svm_crf_ready_results_20260807_101052.xlsx | Y83: TRUE | Z83: auto | AA83: 3.3
A84: conll2003_bert | B84: CoNLL-2003 + bert-base-uncased | C84: bert-base-uncased | D84: CoNLL-2003 + bert-base-uncased | E84: exp10_svm_ready | F84: SVM Router Fusion CRF (Ready) | G84: small_300 | H84: small_300 | I84: before_exp01_baseline | J84: Baseline (simple random split) | K84: conll2003_bert__small_300__before_exp01_baseline__seed44 | L84: conll2003_bert__small_300__before_exp01_baseline | M84: small_300 / Baseline (simple random split) | N84: [CoNLL-2003 + bert-base-uncased] [small_300] Baseline (simple random split) [seed 44] | O84: small_300 / Baseline (simple random split) [s44] | P84: Regular NER with DictaBERT | Q84: 44 | R84: TRUE | S84: 0.64556962 | T84: 0.61818182 | U84: 0.67549669 | V84: ok | W84: /content/drive/MyDrive/thesis_project/thesis/outputs/exp10_svm_ready/fusion_svm_crf_ready_20260807_101055.json | X84: /content/drive/MyDrive/thesis_project/thesis/outputs/exp10_svm_ready/fusion_svm_crf_ready_results_20260807_101054.xlsx | Y84: TRUE | Z84: auto | AA84: 2
A85: conll2003_bert | B85: CoNLL-2003 + bert-base-uncased | C85: bert-base-uncased | D85: CoNLL-2003 + bert-base-uncased | E85: exp10_svm_ready | F85: SVM Router Fusion CRF (Ready) | G85: small_300 | H85: small_300 | I85: before_exp01_baseline | J85: Baseline (simple random split) | K85: conll2003_bert__small_300__before_exp01_baseline__seed45 | L85: conll2003_bert__small_300__before_exp01_baseline | M85: small_300 / Baseline (simple random split) | N85: [CoNLL-2003 + bert-base-uncased] [small_300] Baseline (simple random split) [seed 45] | O85: small_300 / Baseline (simple random split) [s45] | P85: Regular NER with DictaBERT | Q85: 45 | R85: TRUE | S85: 0.66666667 | T85: 0.64150943 | U85: 0.69387755 | V85: ok | W85: /content/drive/MyDrive/thesis_project/thesis/outputs/exp10_svm_ready/fusion_svm_crf_ready_20260807_101057.json | X85: /content/drive/MyDrive/thesis_project/thesis/outputs/exp10_svm_ready/fusion_svm_crf_ready_results_20260807_101056.xlsx | Y85: TRUE | Z85: auto | AA85: 2.3
A86: conll2003_bert | B86: CoNLL-2003 + bert-base-uncased | C86: bert-base-uncased | D86: CoNLL-2003 + bert-base-uncased | E86: exp10_svm_ready | F86: SVM Router Fusion CRF (Ready) | G86: small_300 | H86: small_300 | I86: before_exp01_baseline | J86: Baseline (simple random split) | K86: conll2003_bert__small_300__before_exp01_baseline__seed46 | L86: conll2003_bert__small_300__before_exp01_baseline | M86: small_300 / Baseline (simple random split) | N86: [CoNLL-2003 + bert-base-uncased] [small_300] Baseline (simple random split) [seed 46] | O86: small_300 / Baseline (simple random split) [s46] | P86: Regular NER with DictaBERT | Q86: 46 | R86: TRUE | S86: 0.69117647 | T86: 0.67142857 | U86: 0.71212121 | V86: ok | W86: /content/drive/MyDrive/thesis_project/thesis/outputs/exp10_svm_ready/fusion_svm_crf_ready_20260807_101059.json | X86: /content/drive/MyDrive/thesis_project/thesis/outputs/exp10_svm_ready/fusion_svm_crf_ready_results_20260807_101058.xlsx | Y86: TRUE | Z86: auto | AA86: 1.8
A87: conll2003_bert | B87: CoNLL-2003 + bert-base-uncased | C87: bert-base-uncased | D87: CoNLL-2003 + bert-base-uncased | E87: exp10_svm_ready | F87: SVM Router Fusion CRF (Ready) | G87: small_300 | H87: small_300 | I87: before_exp01_baseline | J87: Baseline (simple random split) | K87: conll2003_bert__small_300__before_exp01_baseline__seed47 | L87: conll2003_bert__small_300__before_exp01_baseline | M87: small_300 / Baseline (simple random split) | N87: [CoNLL-2003 + bert-base-uncased] [small_300] Baseline (simple random split) [seed 47] | O87: small_300 / Baseline (simple random split) [s47] | P87: Regular NER with DictaBERT | Q87: 47 | R87: TRUE | S87: 0.6626506 | T87: 0.67073171 | U87: 0.6547619 | V87: ok | W87: /content/drive/MyDrive/thesis_project/thesis/outputs/exp10_svm_ready/fusion_svm_crf_ready_20260807_101101.json | X87: /content/drive/MyDrive/thesis_project/thesis/outputs/exp10_svm_ready/fusion_svm_crf_ready_results_20260807_101100.xlsx | Y87: TRUE | Z87: auto | AA87: 1.9
A88: conll2003_bert | B88: CoNLL-2003 + bert-base-uncased | C88: bert-base-uncased | D88: CoNLL-2003 + bert-base-uncased | E88: exp10_svm_ready | F88: SVM Router Fusion CRF (Ready) | G88: small_300 | H88: small_300 | I88: before_exp01_baseline | J88: Baseline (simple random split) | K88: conll2003_bert__small_300__before_exp01_baseline__seed48 | L88: conll2003_bert__small_300__before_exp01_baseline | M88: small_300 / Baseline (simple random split) | N88: [CoNLL-2003 + bert-base-uncased] [small_300] Baseline (simple random split) [seed 48] | O88: small_300 / Baseline (simple random split) [s48] | P88: Regular NER with DictaBERT | Q88: 48 | R88: TRUE | S88: 0.64174455 | T88: 0.60233918 | U88: 0.68666667 | V88: ok | W88: /content/drive/MyDrive/thesis_project/thesis/outputs/exp10_svm_ready/fusion_svm_crf_ready_20260807_101103.json | X88: /content/drive/MyDrive/thesis_project/thesis/outputs/exp10_svm_ready/fusion_svm_crf_ready_results_20260807_101102.xlsx | Y88: TRUE | Z88: auto | AA88: 2.3
