Workbook

Sheet summary_pivot
A1: model | B1: experiment_id | C1: experiment_name | D1: Label-aware greedy | E1: Label-aware greedy_std | F1: Multilabel stratified (paper-style) | G1: Multilabel stratified (paper-style)_std | H1: Baseline (simple random split) | I1: Baseline (simple random split)_std | J1: Label-aware greedy + Aug | K1: Label-aware greedy + Aug_std | L1: Multilabel stratified (paper-style) + Aug | M1: Multilabel stratified (paper-style) + Aug_std | N1: Baseline (simple random split) + Aug | O1: Baseline (simple random split) + Aug_std | P1: best_f1 | Q1: best_condition
A2: DictaBERT | B2: exp01 | C2: Regular NER | D2: 0.75409836 | E2: 2.2781296e-16 | F2: 0.73799127 | G2: 3.4171944e-16 | H2: 0.67181552 | I2: 0.011076771 | J2: 0.80152098 | K2: 0.010604771 | L2: 0.8082628 | M2: 0.0097207099 | N2: 0.78054156 | O2: 0.011008323 | P2: 0.8082628 | Q2: Multilabel stratified (paper-style) + Aug
A3: DictaBERT | B3: exp04 | C3: AUC Cascaded Pipeline | D3: 0.72685318 | E3: 0.027115829 | F3: 0.76418619 | G3: 0.024168371 | H3: 0.73106191 | I3: 0.024010883 | J3: 0.79726934 | K3: 0.0174852 | L3: 0.8231002 | M3: 0.008788286 | N3: 0.78903842 | O3: 0.010020143 | P3: 0.8231002 | Q3: Multilabel stratified (paper-style) + Aug
A4: DictaBERT | B4: exp05_ready | C4: AUC Cascaded Step-3 Consistency (Ready) | D4: 0.73443891 | E4: 0.028230272 | F4: 0.76395529 | G4: 0.02395683 | H4: 0.73744218 | I4: 0.024232601 | J4: 0.80508365 | K4: 0.016875653 | L4: 0.82769692 | M4: 0.0090495981 | N4: 0.78995314 | O4: 0.011122802 | P4: 0.82769692 | Q4: Multilabel stratified (paper-style) + Aug
A5: DictaBERT | B5: exp06_ready | C5: Fusion Regular+Cascaded (Ready) | D5: 0.73789067 | E5: 0.010779793 | F5: 0.74547408 | G5: 0.013113579 | H5: 0.68608841 | I5: 0.014169352 | J5: 0.8068222 | K5: 0.011117 | L5: 0.81407098 | M5: 0.011637445 | N5: 0.78834552 | O5: 0.010753397 | P5: 0.81407098 | Q5: Multilabel stratified (paper-style) + Aug
A6: DictaBERT | B6: exp06_svm_ready | C6: SVM Router Fusion (Ready) | D6: 0.81102868 | E6: 0.013041318 | F6: 0.80724124 | G6: 0.010033032 | H6: 0.76571232 | I6: 0.015620879 | J6: 0.84055705 | K6: 0.013059294 | L6: 0.83559819 | M6: 0.0081104779 | N6: 0.81348944 | O6: 0.011593784 | P6: 0.84055705 | Q6: Label-aware greedy + Aug
A7: BEREL 3.0 | B7: exp01 | C7: Regular NER | D7: 0.70744681 | E7: 2.2781296e-16 | F7: 0.73057105 | G7: 0.0060819191 | H7: 0.70511025 | I7: 0.0013526872 | J7: 0.82436639 | K7: 0.01261351 | L7: 0.8466588 | M7: 0.0080643158 | N7: 0.83614723 | O7: 0.0065103702 | P7: 0.8466588 | Q7: Multilabel stratified (paper-style) + Aug
A8: BEREL 3.0 | B8: exp04 | C8: AUC Cascaded Pipeline | D8: 0.64704888 | E8: 0.11132153 | F8: 0.63439021 | G8: 0.1435128 | H8: 0.62779773 | I8: 0.104608 | J8: 0.81595574 | K8: 0.00659939 | L8: 0.83591914 | M8: 0.00860149 | N8: 0.82874574 | O8: 0.012713988 | P8: 0.83591914 | Q8: Multilabel stratified (paper-style) + Aug
A9: BEREL 3.0 | B9: exp05_ready | C9: AUC Cascaded Step-3 Consistency (Ready) | D9: 0.6522487 | E9: 0.11570036 | F9: 0.63902807 | G9: 0.1466003 | H9: 0.63513909 | I9: 0.11034489 | J9: 0.82165325 | K9: 0.0072845942 | L9: 0.84585671 | M9: 0.0083360767 | N9: 0.83827539 | O9: 0.010276886 | P9: 0.84585671 | Q9: Multilabel stratified (paper-style) + Aug
A10: BEREL 3.0 | B10: exp06_ready | C10: Fusion Regular+Cascaded (Ready) | D10: 0.71525238 | E10: 0.0096972908 | F10: 0.73881673 | G10: 0.012072209 | H10: 0.71044712 | I10: 0.012985059 | J10: 0.82288888 | K10: 0.010719325 | L10: 0.84783113 | M10: 0.0075188101 | N10: 0.83552703 | O10: 0.0094922487 | P10: 0.84783113 | Q10: Multilabel stratified (paper-style) + Aug
A11: BEREL 3.0 | B11: exp06_svm_ready | C11: SVM Router Fusion (Ready) | D11: 0.78997538 | E11: 0.028101796 | F11: 0.79533462 | G11: 0.030389165 | H11: 0.77142141 | I11: 0.024770366 | J11: 0.84437107 | K11: 0.011922921 | L11: 0.85182051 | M11: 0.0079883507 | N11: 0.85735749 | O11: 0.0077227635 | P11: 0.85735749 | Q11: Baseline (simple random split) + Aug
A12: HeRo | B12: exp01 | C12: Regular NER | D12: 0.75482094 | E12: 2.2781296e-16 | F12: 0.76923077 | G12: 3.4171944e-16 | H12: 0.74452227 | I12: 0.0095200987 | J12: 0.79677005 | K12: 0.0146156 | L12: 0.82132976 | M12: 0.0088822939 | N12: 0.79216157 | O12: 0.010749116 | P12: 0.82132976 | Q12: Multilabel stratified (paper-style) + Aug
A13: HeRo | B13: exp04 | C13: AUC Cascaded Pipeline | D13: 0.75913558 | E13: 0.018095096 | F13: 0.74842778 | G13: 0.022968839 | H13: 0.73960007 | I13: 0.02659911 | J13: 0.78420892 | K13: 0.018413735 | L13: 0.82312822 | M13: 0.012964657 | N13: 0.79025983 | O13: 0.011076741 | P13: 0.82312822 | Q13: Multilabel stratified (paper-style) + Aug
... A21: AlephBERT-Gimmel | B21: exp06_svm_ready | C21: SVM Router Fusion (Ready) | D21: 0.76258496 | E21: 0.011092408 | F21: 0.76638495 | G21: 0.015200145 | H21: 0.73863344 | I21: 0.017172612 | J21: 0.84055849 | K21: 0.012323308 | L21: 0.84660585 | M21: 0.007827796 | N21: 0.80922192 | O21: 0.010329266 | P21: 0.84660585 | Q21: Multilabel stratified (paper-style) + Aug

Sheet deltas_exp07
A1: model | B1: experiment_id | C1: experiment_name | D1: variant | E1: baseline_f1 | F1: variant_f1 | G1: delta_f1 | H1: baseline_precision | I1: variant_precision | J1: baseline_recall | K1: variant_recall
A2: DictaBERT | B2: exp01 | C2: Regular NER | D2: Label-aware greedy | E2: 0.67181552 | F2: 0.75409836 | G2: 0.082282842 | H2: 0.62317247 | I2: 0.70050761 | J2: 0.72869565 | K2: 0.81656805
A3: DictaBERT | B3: exp01 | C3: Regular NER | D3: Multilabel stratified (paper-style) | E3: 0.67181552 | F3: 0.73799127 | G3: 0.066175748 | H3: 0.62317247 | I3: 0.71610169 | J3: 0.72869565 | K3: 0.76126126
A4: DictaBERT | B4: exp04 | C4: AUC Cascaded Pipeline | D4: Label-aware greedy | E4: 0.73106191 | F4: 0.72685318 | G4: -0.0042087309
A5: DictaBERT | B5: exp04 | C5: AUC Cascaded Pipeline | D5: Multilabel stratified (paper-style) | E5: 0.73106191 | F5: 0.76418619 | G5: 0.033124275
A6: DictaBERT | B6: exp05_ready | C6: AUC Cascaded Step-3 Consistency (Ready) | D6: Label-aware greedy | E6: 0.73744218 | F6: 0.73443891 | G6: -0.0030032691 | H6: 0.70629028 | I6: 0.69016433 | J6: 0.77326087 | K6: 0.78579882
A7: DictaBERT | B7: exp05_ready | C7: AUC Cascaded Step-3 Consistency (Ready) | D7: Multilabel stratified (paper-style) | E7: 0.73744218 | F7: 0.76395529 | G7: 0.02651311 | H7: 0.70629028 | I7: 0.73058927 | J7: 0.77326087 | K7: 0.8027027
A8: DictaBERT | B8: exp06_ready | C8: Fusion Regular+Cascaded (Ready) | D8: Label-aware greedy | E8: 0.68608841 | F8: 0.73789067 | G8: 0.05180226 | H8: 0.66145053 | I8: 0.69268504 | J8: 0.71304348 | K8: 0.78964497
A9: DictaBERT | B9: exp06_ready | C9: Fusion Regular+Cascaded (Ready) | D9: Multilabel stratified (paper-style) | E9: 0.68608841 | F9: 0.74547408 | G9: 0.059385671 | H9: 0.66145053 | I9: 0.7376467 | J9: 0.71304348 | K9: 0.7536036
A10: DictaBERT | B10: exp06_svm_ready | C10: SVM Router Fusion (Ready) | D10: Label-aware greedy | E10: 0.76571232 | F10: 0.81102868 | G10: 0.045316364 | H10: 0.7336966 | I10: 0.77879083 | J10: 0.80086957 | K10: 0.84615385
A11: DictaBERT | B11: exp06_svm_ready | C11: SVM Router Fusion (Ready) | D11: Multilabel stratified (paper-style) | E11: 0.76571232 | F11: 0.80724124 | G11: 0.041528914 | H11: 0.7336966 | I11: 0.79198191 | J11: 0.80086957 | K11: 0.8231982
A12: BEREL 3.0 | B12: exp01 | C12: Regular NER | D12: Label-aware greedy | E12: 0.70511025 | F12: 0.70744681 | G12: 0.0023365566 | H12: 0.64499456 | I12: 0.64251208 | J12: 0.7776087 | K12: 0.78698225
A13: BEREL 3.0 | B13: exp01 | C13: Regular NER | D13: Multilabel stratified (paper-style) | E13: 0.70511025 | F13: 0.73057105 | G13: 0.025460794 | H13: 0.64499456 | I13: 0.69366792 | J13: 0.7776087 | K13: 0.77162162
A14: BEREL 3.0 | B14: exp04 | C14: AUC Cascaded Pipeline | D14: Label-aware greedy | E14: 0.62779773 | F14: 0.64704888 | G14: 0.01925115
A15: BEREL 3.0 | B15: exp04 | C15: AUC Cascaded Pipeline | D15: Multilabel stratified (paper-style) | E15: 0.62779773 | F15: 0.63439021 | G15: 0.0065924868
A16: BEREL 3.0 | B16: exp05_ready | C16: AUC Cascaded Step-3 Consistency (Ready) | D16: Label-aware greedy | E16: 0.63513909 | F16: 0.6522487 | G16: 0.017109608 | H16: 0.61015776 | I16: 0.60532742 | J16: 0.6676087 | K16: 0.70798817
A17: BEREL 3.0 | B17: exp05_ready | C17: AUC Cascaded Step-3 Consistency (Ready) | D17: Multilabel stratified (paper-style) | E17: 0.63513909 | F17: 0.63902807 | G17: 0.0038889815 | H17: 0.61015776 | I17: 0.60735366 | J17: 0.6676087 | K17: 0.68108108
A18: BEREL 3.0 | B18: exp06_ready | C18: Fusion Regular+Cascaded (Ready) | D18: Label-aware greedy | E18: 0.71044712 | F18: 0.71525238 | G18: 0.0048052684 | H18: 0.69649941 | I18: 0.67073467 | J18: 0.7273913 | K18: 0.76715976
A19: BEREL 3.0 | B19: exp06_ready | C19: Fusion Regular+Cascaded (Ready) | D19: Multilabel stratified (paper-style) | E19: 0.71044712 | F19: 0.73881673 | G19: 0.028369616 | H19: 0.69649941 | I19: 0.73617241 | J19: 0.7273913 | K19: 0.74391892
A20: BEREL 3.0 | B20: exp06_svm_ready | C20: SVM Router Fusion (Ready) | D20: Label-aware greedy | E20: 0.77142141 | F20: 0.78997538 | G20: 0.018553973 | H20: 0.75011689 | I20: 0.76383709 | J20: 0.79456522 | K20: 0.81893491
A21: BEREL 3.0 | B21: exp06_svm_ready | C21: SVM Router Fusion (Ready) | D21: Multilabel stratified (paper-style) | E21: 0.77142141 | F21: 0.79533462 | G21: 0.023913214 | H21: 0.75011689 | I21: 0.78076811 | J21: 0.79456522 | K21: 0.81126126
A22: HeRo | B22: exp01 | C22: Regular NER | D22: Label-aware greedy | E22: 0.74452227 | F22: 0.75482094 | G22: 0.010298669 | H22: 0.69877762 | I22: 0.70618557 | J22: 0.79673913 | K22: 0.81065089
A23: HeRo | B23: exp01 | C23: Regular NER | D23: Multilabel stratified (paper-style) | E23: 0.74452227 | F23: 0.76923077 | G23: 0.024708501 | H23: 0.69877762 | I23: 0.75107296 | J23: 0.79673913 | K23: 0.78828829
A24: HeRo | B24: exp04 | C24: AUC Cascaded Pipeline | D24: Label-aware greedy | E24: 0.73960007 | F24: 0.75913558 | G24: 0.019535518
A25: HeRo | B25: exp04 | C25: AUC Cascaded Pipeline | D25: Multilabel stratified (paper-style) | E25: 0.73960007 | F25: 0.74842778 | G25: 0.0088277105
A26: HeRo | B26: exp05_ready | C26: AUC Cascaded Step-3 Consistency (Ready) | D26: Label-aware greedy | E26: 0.73872243 | F26: 0.76025622 | G26: 0.021533797 | H26: 0.70813732 | I26: 0.72089331 | J26: 0.77456522 | K26: 0.80502959
A27: HeRo | B27: exp05_ready | C27: AUC Cascaded Step-3 Consistency (Ready) | D27: Multilabel stratified (paper-style) | E27: 0.73872243 | F27: 0.75022813 | G27: 0.011505701 | H27: 0.70813732 | I27: 0.70928033 | J27: 0.77456522 | K27: 0.79774775
A28: HeRo | B28: exp06_ready | C28: Fusion Regular+Cascaded (Ready) | D28: Label-aware greedy | E28: 0.75261349 | F28: 0.75805551 | G28: 0.0054420208 | H28: 0.72761881 | I28: 0.71893055 | J28: 0.77956522 | K28: 0.80177515
A29: HeRo | B29: exp06_ready | C29: Fusion Regular+Cascaded (Ready) | D29: Multilabel stratified (paper-style) | E29: 0.75261349 | F29: 0.77648238 | G29: 0.023868897 | H29: 0.72761881 | I29: 0.76400739 | J29: 0.77956522 | K29: 0.78941441
A30: HeRo | B30: exp06_svm_ready | C30: SVM Router Fusion (Ready) | D30: Label-aware greedy | E30: 0.79453784 | F30: 0.79907826 | G30: 0.0045404129 | H30: 0.75987096 | I30: 0.76309829 | J30: 0.8326087 | K30: 0.8387574
A31: HeRo | B31: exp06_svm_ready | C31: SVM Router Fusion (Ready) | D31: Multilabel stratified (paper-style) | E31: 0.79453784 | F31: 0.80450812 | G31: 0.0099702778 | H31: 0.75987096 | I31: 0.78691214 | J31: 0.8326087 | K31: 0.82297297
A32: AlephBERT-Gimmel | B32: exp01 | C32: Regular NER | D32: Label-aware greedy | E32: 0.66407607 | F32: 0.65753425 | G32: -0.0065418278 | H32: 0.64267289 | I32: 0.6122449 | J32: 0.68695652 | K32: 0.71005917
A33: AlephBERT-Gimmel | B33: exp01 | C33: Regular NER | D33: Multilabel stratified (paper-style) | E33: 0.66407607 | F33: 0.62735344 | G33: -0.036722636 | H33: 0.64267289 | I33: 0.60274831 | J33: 0.68695652 | K33: 0.65405405
A34: AlephBERT-Gimmel | B34: exp04 | C34: AUC Cascaded Pipeline | D34: Label-aware greedy | E34: 0.68910043 | F34: 0.71846002 | G34: 0.029359592
A35: AlephBERT-Gimmel | B35: exp04 | C35: AUC Cascaded Pipeline | D35: Multilabel stratified (paper-style) | E35: 0.68910043 | F35: 0.72815697 | G35: 0.03905654
A36: AlephBERT-Gimmel | B36: exp05_ready | C36: AUC Cascaded Step-3 Consistency (Ready) | D36: Label-aware greedy | E36: 0.68951942 | F36: 0.72315463 | G36: 0.033635202 | H36: 0.662043 | I36: 0.68485114 | J36: 0.72021739 | K36: 0.7683432
A37: AlephBERT-Gimmel | B37: exp05_ready | C37: AUC Cascaded Step-3 Consistency (Ready) | D37: Multilabel stratified (paper-style) | E37: 0.68951942 | F37: 0.72819086 | G37: 0.038671433 | H37: 0.662043 | I37: 0.70758257 | J37: 0.72021739 | K37: 0.7518018
A38: AlephBERT-Gimmel | B38: exp06_ready | C38: Fusion Regular+Cascaded (Ready) | D38: Label-aware greedy | E38: 0.6912304 | F38: 0.70971459 | G38: 0.018484188 | H38: 0.68801269 | I38: 0.68892678 | J38: 0.69521739 | K38: 0.73254438
A39: AlephBERT-Gimmel | B39: exp06_ready | C39: Fusion Regular+Cascaded (Ready) | D39: Multilabel stratified (paper-style) | E39: 0.6912304 | F39: 0.70211746 | G39: 0.010887062 | H39: 0.68801269 | I39: 0.70065025 | J39: 0.69521739 | K39: 0.70405405
A40: AlephBERT-Gimmel | B40: exp06_svm_ready | C40: SVM Router Fusion (Ready) | D40: Label-aware greedy | E40: 0.73863344 | F40: 0.76258496 | G40: 0.023951526 | H40: 0.71939418 | I40: 0.73824759 | J40: 0.75913043 | K40: 0.7887574
...

Sheet deltas_exp07_aug
A1: model | B1: experiment_id | C1: experiment_name | D1: split_variant | E1: split_only_f1 | F1: split_plus_aug_f1 | G1: delta_f1
A2: DictaBERT | B2: exp01 | C2: Regular NER | D2: Label-aware greedy | E2: 0.75409836 | F2: 0.80152098 | G2: 0.047422619
A3: DictaBERT | B3: exp01 | C3: Regular NER | D3: Multilabel stratified (paper-style) | E3: 0.73799127 | F3: 0.8082628 | G3: 0.070271537
A4: DictaBERT | B4: exp01 | C4: Regular NER | D4: Baseline (simple random split) | E4: 0.67181552 | F4: 0.78054156 | G4: 0.10872605
A5: DictaBERT | B5: exp04 | C5: AUC Cascaded Pipeline | D5: Label-aware greedy | E5: 0.72685318 | F5: 0.79726934 | G5: 0.07041616
A6: DictaBERT | B6: exp04 | C6: AUC Cascaded Pipeline | D6: Multilabel stratified (paper-style) | E6: 0.76418619 | F6: 0.8231002 | G6: 0.058914008
A7: DictaBERT | B7: exp04 | C7: AUC Cascaded Pipeline | D7: Baseline (simple random split) | E7: 0.73106191 | F7: 0.78903842 | G7: 0.057976502
A8: DictaBERT | B8: exp05_ready | C8: AUC Cascaded Step-3 Consistency (Ready) | D8: Label-aware greedy | E8: 0.73443891 | F8: 0.80508365 | G8: 0.070644734
A9: DictaBERT | B9: exp05_ready | C9: AUC Cascaded Step-3 Consistency (Ready) | D9: Multilabel stratified (paper-style) | E9: 0.76395529 | F9: 0.82769692 | G9: 0.063741624
A10: DictaBERT | B10: exp05_ready | C10: AUC Cascaded Step-3 Consistency (Ready) | D10: Baseline (simple random split) | E10: 0.73744218 | F10: 0.78995314 | G10: 0.052510957
A11: DictaBERT | B11: exp06_ready | C11: Fusion Regular+Cascaded (Ready) | D11: Label-aware greedy | E11: 0.73789067 | F11: 0.8068222 | G11: 0.068931527
A12: DictaBERT | B12: exp06_ready | C12: Fusion Regular+Cascaded (Ready) | D12: Multilabel stratified (paper-style) | E12: 0.74547408 | F12: 0.81407098 | G12: 0.068596899
A13: DictaBERT | B13: exp06_ready | C13: Fusion Regular+Cascaded (Ready) | D13: Baseline (simple random split) | E13: 0.68608841 | F13: 0.78834552 | G13: 0.10225711
... A61: AlephBERT-Gimmel | B61: exp06_svm_ready | C61: SVM Router Fusion (Ready) | D61: Baseline (simple random split) | E61: 0.73863344 | F61: 0.80922192 | G61: 0.070588482

Sheet paired_tests
A1: model | B1: experiment_id | C1: comparison | D1: condition | E1: n_pairs | F1: split_only_f1_mean | G1: split_only_f1_sd | H1: split_plus_aug_f1_mean | I1: split_plus_aug_f1_sd | J1: delta_mean_f1 | K1: t_statistic | L1: t_p_value | M1: t_p_lt_0_05 | N1: wilcoxon_statistic | O1: wilcoxon_p_value | P1: wilcoxon_p_lt_0_05
A2: AlephBERT-Gimmel | B2: exp01 | C2: exp07+aug vs exp07 | D2: after_label_aware_split | E2: 20 | F2: 0.65753425 | G2: 2.2781296e-16 | H2: 0.81278979 | I2: 0.010493311 | J2: 0.15525555 | K2: 66.168241 | L2: 6.2467389e-24 | M2: TRUE | N2: 0 | O2: 8.807368e-05 | P2: TRUE
A3: AlephBERT-Gimmel | B3: exp01 | C3: exp07+aug vs exp07 | D3: after_multilabel_iterative_paper | E3: 20 | F3: 0.62735344 | G3: 0.0044879969 | H3: 0.83362573 | I3: 0.0062291992 | J3: 0.20627229 | K3: 107.04308 | L3: 6.868897e-28 | M3: TRUE | N3: 0 | O3: 8.8198702e-05 | P3: TRUE
A4: AlephBERT-Gimmel | B4: exp01 | C4: exp07+aug vs exp07 | D4: before_exp01_baseline | E4: 20 | F4: 0.66407607 | G4: 0.00094151067 | H4: 0.78109951 | I4: 0.0079348035 | J4: 0.11702343 | K4: 68.899396 | L4: 2.9055089e-24 | M4: TRUE | N4: 0 | O4: 8.8323859e-05 | P4: TRUE
A5: AlephBERT-Gimmel | B5: exp04 | C5: exp07+aug vs exp07 | D5: after_label_aware_split | E5: 20 | F5: 0.71846002 | G5: 0.023684015 | H5: 0.79948866 | I5: 0.012902439 | J5: 0.081028634 | K5: 16.251209 | L5: 1.3340278e-12 | M5: TRUE | N5: 0 | O5: 1.9073486e-06 | P5: TRUE
A6: AlephBERT-Gimmel | B6: exp04 | C6: exp07+aug vs exp07 | D6: after_multilabel_iterative_paper | E6: 20 | F6: 0.72815697 | G6: 0.030732392 | H6: 0.83754064 | I6: 0.0090291163 | J6: 0.10938367 | K6: 14.303595 | L6: 1.2663179e-11 | M6: TRUE | N6: 0 | O6: 1.9073486e-06 | P6: TRUE
A7: AlephBERT-Gimmel | B7: exp04 | C7: exp07+aug vs exp07 | D7: before_exp01_baseline | E7: 20 | F7: 0.68910043 | G7: 0.036390663 | H7: 0.77985129 | I7: 0.012173331 | J7: 0.090750853 | K7: 11.601964 | L7: 4.5702535e-10 | M7: TRUE | N7: 0 | O7: 1.9073486e-06 | P7: TRUE
A8: AlephBERT-Gimmel | B8: exp05_ready | C8: exp07+aug vs exp07 | D8: after_label_aware_split | E8: 20 | F8: 0.72315463 | G8: 0.024964895 | H8: 0.79900579 | I8: 0.011169069 | J8: 0.075851163 | K8: 13.198678 | L8: 5.1060264e-11 | M8: TRUE | N8: 0 | O8: 1.9073486e-06 | P8: TRUE
A9: AlephBERT-Gimmel | B9: exp05_ready | C9: exp07+aug vs exp07 | D9: after_multilabel_iterative_paper | E9: 20 | F9: 0.72819086 | G9: 0.030997996 | H9: 0.83896085 | I9: 0.009740644 | J9: 0.11076999 | K9: 15.042204 | L9: 5.238555e-12 | M9: TRUE | N9: 0 | O9: 1.9073486e-06 | P9: TRUE
A10: AlephBERT-Gimmel | B10: exp05_ready | C10: exp07+aug vs exp07 | D10: before_exp01_baseline | E10: 20 | F10: 0.68951942 | G10: 0.035452766 | H10: 0.78390506 | I10: 0.011048798 | J10: 0.09438563 | K10: 12.334953 | L10: 1.6252034e-10 | M10: TRUE | N10: 0 | O10: 1.9073486e-06 | P10: TRUE
A11: AlephBERT-Gimmel | B11: exp06_ready | C11: exp07+aug vs exp07 | D11: after_label_aware_split | E11: 20 | F11: 0.70971459 | G11: 0.022044055 | H11: 0.81492869 | I11: 0.011708687 | J11: 0.10521411 | K11: 18.465594 | L11: 1.3521231e-13 | M11: TRUE | N11: 0 | O11: 1.9073486e-06 | P11: TRUE
A12: AlephBERT-Gimmel | B12: exp06_ready | C12: exp07+aug vs exp07 | D12: after_multilabel_iterative_paper | E12: 20 | F12: 0.70211746 | G12: 0.020099577 | H12: 0.83203844 | I12: 0.0082406378 | J12: 0.12992098 | K12: 26.822115 | L12: 1.4494762e-16 | M12: TRUE | N12: 0 | O12: 1.9073486e-06 | P12: TRUE
A13: AlephBERT-Gimmel | B13: exp06_ready | C13: exp07+aug vs exp07 | D13: before_exp01_baseline | E13: 20 | F13: 0.6912304 | G13: 0.019936274 | H13: 0.78457273 | I13: 0.012871956 | J13: 0.093342329 | K13: 19.44426 | L13: 5.3124027e-14 | M13: TRUE | N13: 0 | O13: 1.9073486e-06 | P13: TRUE
... A61: HeRo | B61: exp06_svm_ready | C61: exp07+aug vs exp07 | D61: before_exp01_baseline | E61: 20 | F61: 0.79453784 | G61: 0.013230104 | H61: 0.82468309 | I61: 0.015499907 | J61: 0.030145249 | K61: 6.010045 | L61: 8.7898533e-06 | M61: TRUE | N61: 10 | O61: 8.2015991e-05 | P61: TRUE

Sheet variant_summary
A1: data_source | B1: condition | C1: description | D1: num_runs | E1: f1_mean | F1: f1_std | G1: f1_min | H1: f1_max
A2: exp07+aug | B2: Multilabel stratified (paper-style) + Aug | C2: Paper-style iterative stratification: rarest-label-first with tie-breaks by per-label need, then fold capacity, then random + LLM mask-fill augmentation | D2: 400 | E2: 0.83299913 | F2: 0.014863415 | G2: 0.78761062 | H2: 0.86343612
A3: exp07+aug | B3: Label-aware greedy + Aug | C3: Statistical stratified sentence split preserving non-O label distribution (with best-effort train coverage) + LLM mask-fill augmentation | D3: 400 | E3: 0.81154145 | F3: 0.022225046 | G3: 0.73684211 | H3: 0.86956522
A4: exp07+aug | B4: Baseline (simple random split) + Aug | C4: Regular NER with DictaBERT + LLM mask-fill augmentation | D4: 400 | E4: 0.80420411 | F4: 0.025839717 | G4: 0.74468085 | H4: 0.87136929
A5: exp07 | B5: Multilabel stratified (paper-style) | C5: Paper-style iterative stratification: rarest-label-first with tie-breaks by per-label need, then fold capacity, then random | D5: 400 | E5: 0.73790348 | F5: 0.069968795 | G5: 0.4 | H5: 0.84140969
A6: exp07 | B6: Label-aware greedy | C6: Statistical stratified sentence split preserving non-O label distribution (with best-effort train coverage) | D6: 400 | E6: 0.73395385 | F6: 0.05867002 | G6: 0.40883978 | H6: 0.83286119
A7: exp07 | B7: Baseline (simple random split) | C7: Regular NER with DictaBERT | D7: 400 | E7: 0.71422959 | F7: 0.058126405 | G7: 0.46330275 | H7: 0.81912682

Sheet experiment_details
A1: model_name | B1: experiment_id | C1: experiment_name | D1: data_source | E1: condition_group_key | F1: condition_group_short | G1: condition_label | H1: condition_description | I1: seed | J1: f1 | K1: precision | L1: recall | M1: status | N1: result_file | O1: metrics_file | P1: elapsed_seconds
A2: DictaBERT | B2: exp01 | C2: Regular NER | D2: exp07 | E2: exp07_before_exp01_baseline | F2: Baseline (simple random split) | G2: [Exp07] Baseline (simple random split) [seed 42] | H2: Regular NER with DictaBERT | I2: 42 | J2: 0.7188755 | K2: 0.66791045 | L2: 0.77826087 | M2: ok | N2: /content/drive/MyDrive/thesis_project/thesis/outputs/exp01/regular_ner_20260601_205916.json | O2: /content/drive/MyDrive/thesis_project/thesis/outputs/exp01/regular_ner_results_20260601_205916.xlsx | P2: 69.6
A3: DictaBERT | B3: exp01 | C3: Regular NER | D3: exp07 | E3: exp07_before_exp01_baseline | F3: Baseline (simple random split) | G3: [Exp07] Baseline (simple random split) [seed 43] | H3: Regular NER with DictaBERT | I3: 43 | J3: 0.66933868 | K3: 0.62081784 | L3: 0.72608696 | M3: ok | N3: /content/drive/MyDrive/thesis_project/thesis/outputs/exp01/regular_ner_20260601_210114.json | O3: /content/drive/MyDrive/thesis_project/thesis/outputs/exp01/regular_ner_results_20260601_210104.xlsx | P3: 119.2
A4: DictaBERT | B4: exp01 | C4: Regular NER | D4: exp07 | E4: exp07_before_exp01_baseline | F4: Baseline (simple random split) | G4: [Exp07] Baseline (simple random split) [seed 44] | H4: Regular NER with DictaBERT | I4: 44 | J4: 0.66933868 | K4: 0.62081784 | L4: 0.72608696 | M4: ok | N4: /content/drive/MyDrive/thesis_project/thesis/outputs/exp01/regular_ner_20260601_210348.json | O4: /content/drive/MyDrive/thesis_project/thesis/outputs/exp01/regular_ner_results_20260601_210348.xlsx | P4: 159.5
A5: DictaBERT | B5: exp01 | C5: Regular NER | D5: exp07 | E5: exp07_before_exp01_baseline | F5: Baseline (simple random split) | G5: [Exp07] Baseline (simple random split) [seed 45] | H5: Regular NER with DictaBERT | I5: 45 | J5: 0.66933868 | K5: 0.62081784 | L5: 0.72608696 | M5: ok | N5: /content/drive/MyDrive/thesis_project/thesis/outputs/exp01/regular_ner_20260601_210627.json | O5: /content/drive/MyDrive/thesis_project/thesis/outputs/exp01/regular_ner_results_20260601_210616.xlsx | P5: 155.6
A6: DictaBERT | B6: exp01 | C6: Regular NER | D6: exp07 | E6: exp07_before_exp01_baseline | F6: Baseline (simple random split) | G6: [Exp07] Baseline (simple random split) [seed 46] | H6: Regular NER with DictaBERT | I6: 46 | J6: 0.66933868 | K6: 0.62081784 | L6: 0.72608696 | M6: ok | N6: /content/drive/MyDrive/thesis_project/thesis/outputs/exp01/regular_ner_20260601_210903.json | O6: /content/drive/MyDrive/thesis_project/thesis/outputs/exp01/regular_ner_results_20260601_210851.xlsx | P6: 166.9
A7: DictaBERT | B7: exp01 | C7: Regular NER | D7: exp07 | E7: exp07_before_exp01_baseline | F7: Baseline (simple random split) | G7: [Exp07] Baseline (simple random split) [seed 47] | H7: Regular NER with DictaBERT | I7: 47 | J7: 0.66933868 | K7: 0.62081784 | L7: 0.72608696 | M7: ok | N7: /content/drive/MyDrive/thesis_project/thesis/outputs/exp01/regular_ner_20260601_211152.json | O7: /content/drive/MyDrive/thesis_project/thesis/outputs/exp01/regular_ner_results_20260601_211141.xlsx | P7: 180.9
A8: DictaBERT | B8: exp01 | C8: Regular NER | D8: exp07 | E8: exp07_before_exp01_baseline | F8: Baseline (simple random split) | G8: [Exp07] Baseline (simple random split) [seed 48] | H8: Regular NER with DictaBERT | I8: 48 | J8: 0.66933868 | K8: 0.62081784 | L8: 0.72608696 | M8: ok | N8: /content/drive/MyDrive/thesis_project/thesis/outputs/exp01/regular_ner_20260601_211437.json | O8: /content/drive/MyDrive/thesis_project/thesis/outputs/exp01/regular_ner_results_20260601_211428.xlsx | P8: 164.8
A9: DictaBERT | B9: exp01 | C9: Regular NER | D9: exp07 | E9: exp07_before_exp01_baseline | F9: Baseline (simple random split) | G9: [Exp07] Baseline (simple random split) [seed 49] | H9: Regular NER with DictaBERT | I9: 49 | J9: 0.66933868 | K9: 0.62081784 | L9: 0.72608696 | M9: ok | N9: /content/drive/MyDrive/thesis_project/thesis/outputs/exp01/regular_ner_20260601_211724.json | O9: /content/drive/MyDrive/thesis_project/thesis/outputs/exp01/regular_ner_results_20260601_211723.xlsx | P9: 161.6
A10: DictaBERT | B10: exp01 | C10: Regular NER | D10: exp07 | E10: exp07_before_exp01_baseline | F10: Baseline (simple random split) | G10: [Exp07] Baseline (simple random split) [seed 50] | H10: Regular NER with DictaBERT | I10: 50 | J10: 0.66933868 | K10: 0.62081784 | L10: 0.72608696 | M10: ok | N10: /content/drive/MyDrive/thesis_project/thesis/outputs/exp01/regular_ner_20260601_212004.json | O10: /content/drive/MyDrive/thesis_project/thesis/outputs/exp01/regular_ner_results_20260601_212003.xlsx | P10: 157.8
A11: DictaBERT | B11: exp01 | C11: Regular NER | D11: exp07 | E11: exp07_before_exp01_baseline | F11: Baseline (simple random split) | G11: [Exp07] Baseline (simple random split) [seed 51] | H11: Regular NER with DictaBERT | I11: 51 | J11: 0.66933868 | K11: 0.62081784 | L11: 0.72608696 | M11: ok | N11: /content/drive/MyDrive/thesis_project/thesis/outputs/exp01/regular_ner_20260601_212256.json | O11: /content/drive/MyDrive/thesis_project/thesis/outputs/exp01/regular_ner_results_20260601_212246.xlsx | P11: 183.9
A12: DictaBERT | B12: exp01 | C12: Regular NER | D12: exp07 | E12: exp07_before_exp01_baseline | F12: Baseline (simple random split) | G12: [Exp07] Baseline (simple random split) [seed 52] | H12: Regular NER with DictaBERT | I12: 52 | J12: 0.66933868 | K12: 0.62081784 | L12: 0.72608696 | M12: ok | N12: /content/drive/MyDrive/thesis_project/thesis/outputs/exp01/regular_ner_20260601_212556.json | O12: /content/drive/MyDrive/thesis_project/thesis/outputs/exp01/regular_ner_results_20260601_212546.xlsx | P12: 170.9
A13: DictaBERT | B13: exp01 | C13: Regular NER | D13: exp07 | E13: exp07_before_exp01_baseline | F13: Baseline (simple random split) | G13: [Exp07] Baseline (simple random split) [seed 53] | H13: Regular NER with DictaBERT | I13: 53 | J13: 0.66933868 | K13: 0.62081784 | L13: 0.72608696 | M13: ok | N13: /content/drive/MyDrive/thesis_project/thesis/outputs/exp01/regular_ner_20260601_212841.json | O13: /content/drive/MyDrive/thesis_project/thesis/outputs/exp01/regular_ner_results_20260601_212832.xlsx | P13: 145
... A121: DictaBERT | B121: exp01 | C121: Regular NER | D121: exp07+aug | E121: exp07aug_after_multilabel_iterative_paper | F121: Multilabel stratified (paper-style) + Aug | G121: [Exp07+Aug] Multilabel stratified (paper-style) + Augmented [seed 61] | H121: Paper-style iterative stratification: rarest-label-first with tie-breaks by per-label need, then fold capacity, then random + LLM mask-fill augmentation | I121: 61 | J121: 0.80525164 | K121: 0.78297872 | L121: 0.82882883 | M121: ok | N121: /content/drive/MyDrive/thesis_project/thesis/outputs/exp01/regular_ner_20260602_202416.json | O121: /content/drive/MyDrive/thesis_project/thesis/outputs/exp01/regular_ner_results_20260602_202416.xlsx | P121: 263.7
A122: DictaBERT | B122: exp04 | C122: AUC Cascaded Pipeline | D122: exp07 | E122: exp07_before_exp01_baseline | F122: Baseline (simple random split) | G122: [Exp07] Baseline (simple random split) [seed 42] | H122: Regular NER with DictaBERT | I122: 42 | J122: 0.74895397 | M122: ok_reused_base | N122: /content/drive/MyDrive/thesis_project/thesis/outputs/exp04/auc_cascaded_pipeline_20260601_210001.json | O122: /content/drive/MyDrive/thesis_project/thesis/outputs/exp04/cascaded_pipeline_results_20260601_210000.xlsx | P122: 0.6
A123: DictaBERT | B123: exp04 | C123: AUC Cascaded Pipeline | D123: exp07 | E123: exp07_before_exp01_baseline | F123: Baseline (simple random split) | G123: [Exp07] Baseline (simple random split) [seed 43] | H123: Regular NER with DictaBERT | I123: 43 | J123: 0.71910112 | M123: ok_reused_base | N123: /content/drive/MyDrive/thesis_project/thesis/outputs/exp04/auc_cascaded_pipeline_20260601_210200.json | O123: /content/drive/MyDrive/thesis_project/thesis/outputs/exp04/cascaded_pipeline_results_20260601_210159.xlsx | P123: 1
A124: DictaBERT | B124: exp04 | C124: AUC Cascaded Pipeline | D124: exp07 | E124: exp07_before_exp01_baseline | F124: Baseline (simple random split) | G124: [Exp07] Baseline (simple random split) [seed 44] | H124: Regular NER with DictaBERT | I124: 44 | J124: 0.70229008 | M124: ok_reused_base | N124: /content/drive/MyDrive/thesis_project/thesis/outputs/exp04/auc_cascaded_pipeline_20260601_210439.json | O124: /content/drive/MyDrive/thesis_project/thesis/outputs/exp04/cascaded_pipeline_results_20260601_210438.xlsx | P124: 0.7
A125: DictaBERT | B125: exp04 | C125: AUC Cascaded Pipeline | D125: exp07 | E125: exp07_before_exp01_baseline | F125: Baseline (simple random split) | G125: [Exp07] Baseline (simple random split) [seed 45] | H125: Regular NER with DictaBERT | I125: 45 | J125: 0.72881356 | M125: ok_reused_base | N125: /content/drive/MyDrive/thesis_project/thesis/outputs/exp04/auc_cascaded_pipeline_20260601_210715.json | O125: /content/drive/MyDrive/thesis_project/thesis/outputs/exp04/cascaded_pipeline_results_20260601_210714.xlsx | P125: 1
A126: DictaBERT | B126: exp04 | C126: AUC Cascaded Pipeline | D126: exp07 | E126: exp07_before_exp01_baseline | F126: Baseline (simple random split) | G126: [Exp07] Baseline (simple random split) [seed 46] | H126: Regular NER with DictaBERT | I126: 46 | J126: 0.69767442 | M126: ok_reused_base | N126: /content/drive/MyDrive/thesis_project/thesis/outputs/exp04/auc_cascaded_pipeline_20260601_211002.json | O126: /content/drive/MyDrive/thesis_project/thesis/outputs/exp04/cascaded_pipeline_results_20260601_211001.xlsx | P126: 0.7
A127: DictaBERT | B127: exp04 | C127: AUC Cascaded Pipeline | D127: exp07 | E127: exp07_before_exp01_baseline | F127: Baseline (simple random split) | G127: [Exp07] Baseline (simple random split) [seed 47] | H127: Regular NER with DictaBERT | I127: 47 | J127: 0.75527426 | M127: ok_reused_base | N127: /content/drive/MyDrive/thesis_project/thesis/outputs/exp04/auc_cascaded_pipeline_20260601_211301.json | O127: /content/drive/MyDrive/thesis_project/thesis/outputs/exp04/cascaded_pipeline_results_20260601_211251.xlsx | P127: 1
A128: DictaBERT | B128: exp04 | C128: AUC Cascaded Pipeline | D128: exp07 | E128: exp07_before_exp01_baseline | F128: Baseline (simple random split) | G128: [Exp07] Baseline (simple random split) [seed 48] | H128: Regular NER with DictaBERT | I128: 48 | J128: 0.73221757 | M128: ok_reused_base | N128: /content/drive/MyDrive/thesis_project/thesis/outputs/exp04/auc_cascaded_pipeline_20260601_211546.json | O128: /content/drive/MyDrive/thesis_project/thesis/outputs/exp04/cascaded_pipeline_results_20260601_211536.xlsx | P128: 0.8
A129: DictaBERT | B129: exp04 | C129: AUC Cascaded Pipeline | D129: exp07 | E129: exp07_before_exp01_baseline | F129: Baseline (simple random split) | G129: [Exp07] Baseline (simple random split) [seed 49] | H129: Regular NER with DictaBERT | I129: 49 | J129: 0.7348643 | M129: ok_reused_base | N129: /content/drive/MyDrive/thesis_project/thesis/outputs/exp04/auc_cascaded_pipeline_20260601_211829.json | O129: /content/drive/MyDrive/thesis_project/thesis/outputs/exp04/cascaded_pipeline_results_20260601_211828.xlsx | P129: 0.9
A130: DictaBERT | B130: exp04 | C130: AUC Cascaded Pipeline | D130: exp07 | E130: exp07_before_exp01_baseline | F130: Baseline (simple random split) | G130: [Exp07] Baseline (simple random split) [seed 50] | H130: Regular NER with DictaBERT | I130: 50 | J130: 0.74895397 | M130: ok_reused_base | N130: /content/drive/MyDrive/thesis_project/thesis/outputs/exp04/auc_cascaded_pipeline_20260601_212107.json | O130: /content/drive/MyDrive/thesis_project/thesis/outputs/exp04/cascaded_pipeline_results_20260601_212106.xlsx | P130: 0.7
A131: DictaBERT | B131: exp04 | C131: AUC Cascaded Pipeline | D131: exp07 | E131: exp07_before_exp01_baseline | F131: Baseline (simple random split) | G131: [Exp07] Baseline (simple random split) [seed 51] | H131: Regular NER with DictaBERT | I131: 51 | J131: 0.71398747 | M131: ok_reused_base | N131: /content/drive/MyDrive/thesis_project/thesis/outputs/exp04/auc_cascaded_pipeline_20260601_212411.json | O131: /content/drive/MyDrive/thesis_project/thesis/outputs/exp04/cascaded_pipeline_results_20260601_212400.xlsx | P131: 1
A132: DictaBERT | B132: exp04 | C132: AUC Cascaded Pipeline | D132: exp07 | E132: exp07_before_exp01_baseline | F132: Baseline (simple random split) | G132: [Exp07] Baseline (simple random split) [seed 52] | H132: Regular NER with DictaBERT | I132: 52 | J132: 0.71092077 | M132: ok_reused_base | N132: /content/drive/MyDrive/thesis_project/thesis/outputs/exp04/auc_cascaded_pipeline_20260601_212702.json | O132: /content/drive/MyDrive/thesis_project/thesis/outputs/exp04/cascaded_pipeline_results_20260601_212701.xlsx | P132: 0.7
A133: DictaBERT | B133: exp04 | C133: AUC Cascaded Pipeline | D133: exp07 | E133: exp07_before_exp01_baseline | F133: Baseline (simple random split) | G133: [Exp07] Baseline (simple random split) [seed 53] | H133: Regular NER with DictaBERT | I133: 53 | J133: 0.74369748 | M133: ok_reused_base | N133: /content/drive/MyDrive/thesis_project/thesis/outputs/exp04/auc_cascaded_pipeline_20260601_212927.json | O133: /content/drive/MyDrive/thesis_project/thesis/outputs/exp04/cascaded_pipeline_results_20260601_212926.xlsx | P133: 0.9
... A241: DictaBERT | B241: exp04 | C241: AUC Cascaded Pipeline | D241: exp07+aug | E241: exp07aug_after_multilabel_iterative_paper | F241: Multilabel stratified (paper-style) + Aug | G241: [Exp07+Aug] Multilabel stratified (paper-style) + Augmented [seed 61] | H241: Paper-style iterative stratification: rarest-label-first with tie-breaks by per-label need, then fold capacity, then random + LLM mask-fill augmentation | I241: 61 | J241: 0.81127983 | M241: ok_reused_base | N241: /content/drive/MyDrive/thesis_project/thesis/outputs/exp04/auc_cascaded_pipeline_20260602_202652.json | O241: /content/drive/MyDrive/thesis_project/thesis/outputs/exp04/cascaded_pipeline_results_20260602_202651.xlsx | P241: 0
A242: DictaBERT | B242: exp05_ready | C242: AUC Cascaded Step-3 Consistency (Ready) | D242: exp07 | E242: exp07_before_exp01_baseline | F242: Baseline (simple random split) | G242: [Exp07] Baseline (simple random split) [seed 42] | H242: Regular NER with DictaBERT | I242: 42 | J242: 0.75156576 | K242: 0.72289157 | L242: 0.7826087 | M242: ok | N242: /content/drive/MyDrive/thesis_project/thesis/outputs/exp05_ready/cascaded_step3_consistent_ready_20260602_202815.json | O242: /content/drive/MyDrive/thesis_project/thesis/outputs/exp05_ready/cascaded_step3_consistent_ready_results_20260602_202815.xlsx | P242: 4.2
A243: DictaBERT | B243: exp05_ready | C243: AUC Cascaded Step-3 Consistency (Ready) | D243: exp07 | E243: exp07_before_exp01_baseline | F243: Baseline (simple random split) | G243: [Exp07] Baseline (simple random split) [seed 43] | H243: Regular NER with DictaBERT | I243: 43 | J243: 0.7309417 | K243: 0.75462963 | L243: 0.70869565 | M243: ok | N243: /content/drive/MyDrive/thesis_project/thesis/outputs/exp05_ready/cascaded_step3_consistent_ready_20260602_202818.json | O243: /content/drive/MyDrive/thesis_project/thesis/outputs/exp05_ready/cascaded_step3_consistent_ready_results_20260602_202817.xlsx | P243: 2.3
A244: DictaBERT | B244: exp05_ready | C244: AUC Cascaded Step-3 Consistency (Ready) | D244: exp07 | E244: exp07_before_exp01_baseline | F244: Baseline (simple random split) | G244: [Exp07] Baseline (simple random split) [seed 44] | H244: Regular NER with DictaBERT | I244: 44 | J244: 0.71102662 | K244: 0.63175676 | L244: 0.81304348 | M244: ok | N244: /content/drive/MyDrive/thesis_project/thesis/outputs/exp05_ready/cascaded_step3_consistent_ready_20260602_202820.json | O244: /content/drive/MyDrive/thesis_project/thesis/outputs/exp05_ready/cascaded_step3_consistent_ready_results_20260602_202819.xlsx | P244: 1.9
A245: DictaBERT | B245: exp05_ready | C245: AUC Cascaded Step-3 Consistency (Ready) | D245: exp07 | E245: exp07_before_exp01_baseline | F245: Baseline (simple random split) | G245: [Exp07] Baseline (simple random split) [seed 45] | H245: Regular NER with DictaBERT | I245: 45 | J245: 0.73572939 | K245: 0.71604938 | L245: 0.75652174 | M245: ok | N245: /content/drive/MyDrive/thesis_project/thesis/outputs/exp05_ready/cascaded_step3_consistent_ready_20260602_202822.json | O245: /content/drive/MyDrive/thesis_project/thesis/outputs/exp05_ready/cascaded_step3_consistent_ready_results_20260602_202822.xlsx | P245: 2.4
A246: DictaBERT | B246: exp05_ready | C246: AUC Cascaded Step-3 Consistency (Ready) | D246: exp07 | E246: exp07_before_exp01_baseline | F246: Baseline (simple random split) | G246: [Exp07] Baseline (simple random split) [seed 46] | H246: Regular NER with DictaBERT | I246: 46 | J246: 0.70315789 | K246: 0.68163265 | L246: 0.72608696 | M246: ok | N246: /content/drive/MyDrive/thesis_project/thesis/outputs/exp05_ready/cascaded_step3_consistent_ready_20260602_202824.json | O246: /content/drive/MyDrive/thesis_project/thesis/outputs/exp05_ready/cascaded_step3_consistent_ready_results_20260602_202824.xlsx | P246: 2.3
A247: DictaBERT | B247: exp05_ready | C247: AUC Cascaded Step-3 Consistency (Ready) | D247: exp07 | E247: exp07_before_exp01_baseline | F247: Baseline (simple random split) | G247: [Exp07] Baseline (simple random split) [seed 47] | H247: Regular NER with DictaBERT | I247: 47 | J247: 0.7605042 | K247: 0.73577236 | L247: 0.78695652 | M247: ok | N247: /content/drive/MyDrive/thesis_project/thesis/outputs/exp05_ready/cascaded_step3_consistent_ready_20260602_202826.json | O247: /content/drive/MyDrive/thesis_project/thesis/outputs/exp05_ready/cascaded_step3_consistent_ready_results_20260602_202825.xlsx | P247: 1.4
A248: DictaBERT | B248: exp05_ready | C248: AUC Cascaded Step-3 Consistency (Ready) | D248: exp07 | E248: exp07_before_exp01_baseline | F248: Baseline (simple random split) | G248: [Exp07] Baseline (simple random split) [seed 48] | H248: Regular NER with DictaBERT | I248: 48 | J248: 0.73903967 | K248: 0.71084337 | L248: 0.76956522 | M248: ok | N248: /content/drive/MyDrive/thesis_project/thesis/outputs/exp05_ready/cascaded_step3_consistent_ready_20260602_202827.json | O248: /content/drive/MyDrive/thesis_project/thesis/outputs/exp05_ready/cascaded_step3_consistent_ready_results_20260602_202827.xlsx | P248: 1.4
A249: DictaBERT | B249: exp05_ready | C249: AUC Cascaded Step-3 Consistency (Ready) | D249: exp07 | E249: exp07_before_exp01_baseline | F249: Baseline (simple random split) | G249: [Exp07] Baseline (simple random split) [seed 49] | H249: Regular NER with DictaBERT | I249: 49 | J249: 0.74166667 | K249: 0.712 | L249: 0.77391304 | M249: ok | N249: /content/drive/MyDrive/thesis_project/thesis/outputs/exp05_ready/cascaded_step3_consistent_ready_20260602_202828.json | O249: /content/drive/MyDrive/thesis_project/thesis/outputs/exp05_ready/cascaded_step3_consistent_ready_results_20260602_202828.xlsx | P249: 1.4
A250: DictaBERT | B250: exp05_ready | C250: AUC Cascaded Step-3 Consistency (Ready) | D250: exp07 | E250: exp07_before_exp01_baseline | F250: Baseline (simple random split) | G250: [Exp07] Baseline (simple random split) [seed 50] | H250: Regular NER with DictaBERT | I250: 50 | J250: 0.75991649 | K250: 0.73092369 | L250: 0.79130435 | M250: ok | N250: /content/drive/MyDrive/thesis_project/thesis/outputs/exp05_ready/cascaded_step3_consistent_ready_20260602_202830.json | O250: /content/drive/MyDrive/thesis_project/thesis/outputs/exp05_ready/cascaded_step3_consistent_ready_results_20260602_202830.xlsx | P250: 1.4
A251: DictaBERT | B251: exp05_ready | C251: AUC Cascaded Step-3 Consistency (Ready) | D251: exp07 | E251: exp07_before_exp01_baseline | F251: Baseline (simple random split) | G251: [Exp07] Baseline (simple random split) [seed 51] | H251: Regular NER with DictaBERT | I251: 51 | J251: 0.71666667 | K251: 0.688 | L251: 0.74782609 | M251: ok | N251: /content/drive/MyDrive/thesis_project/thesis/outputs/exp05_ready/cascaded_step3_consistent_ready_20260602_202832.json | O251: /content/drive/MyDrive/thesis_project/thesis/outputs/exp05_ready/cascaded_step3_consistent_ready_results_20260602_202831.xlsx | P251: 1.8
A252: DictaBERT | B252: exp05_ready | C252: AUC Cascaded Step-3 Consistency (Ready) | D252: exp07 | E252: exp07_before_exp01_baseline | F252: Baseline (simple random split) | G252: [Exp07] Baseline (simple random split) [seed 52] | H252: Regular NER with DictaBERT | I252: 52 | J252: 0.72649573 | K252: 0.71428571 | L252: 0.73913043 | M252: ok | N252: /content/drive/MyDrive/thesis_project/thesis/outputs/exp05_ready/cascaded_step3_consistent_ready_20260602_202833.json | O252: /content/drive/MyDrive/thesis_project/thesis/outputs/exp05_ready/cascaded_step3_consistent_ready_results_20260602_202833.xlsx | P252: 1.6
A253: DictaBERT | B253: exp05_ready | C253: AUC Cascaded Step-3 Consistency (Ready) | D253: exp07 | E253: exp07_before_exp01_baseline | F253: Baseline (simple random split) | G253: [Exp07] Baseline (simple random split) [seed 53] | H253: Regular NER with DictaBERT | I253: 53 | J253: 0.74633124 | K253: 0.72064777 | L253: 0.77391304 | M253: ok | N253: /content/drive/MyDrive/thesis_project/thesis/outputs/exp05_ready/cascaded_step3_consistent_ready_20260602_202835.json | O253: /content/drive/MyDrive/thesis_project/thesis/outputs/exp05_ready/cascaded_step3_consistent_ready_results_20260602_202834.xlsx | P253: 1.3
... A721: BEREL 3.0 | B721: exp01 | C721: Regular NER | D721: exp07+aug | E721: exp07aug_after_multilabel_iterative_paper | F721: Multilabel stratified (paper-style) + Aug | G721: [Exp07+Aug] Multilabel stratified (paper-style) + Augmented [seed 61] | H721: Paper-style iterative stratification: rarest-label-first with tie-breaks by per-label need, then fold capacity, then random + LLM mask-fill augmentation | I721: 61 | J721: 0.84257206 | K721: 0.82969432 | L721: 0.85585586 | M721: ok | N721: /content/drive/MyDrive/thesis_project/thesis/outputs/exp01/regular_ner_20260603_112254.json | O721: /content/drive/MyDrive/thesis_project/thesis/outputs/exp01/regular_ner_results_20260603_112254.xlsx | P721: 253.8
...

Sheet documentation
A1: Section | B1: Key | C1: Value
A2: Experiment | B2: ID | C2: cross_comparison
A3: Experiment | B3: Name | C3: Cross-Data × Multi-Model Comparison (Ready Setup)
A4: Dataset | B4: Source | C4: ner_dataset.csv (Hebrew NER corpus)
A5: Dataset | B5: Format | C5: Token-level BIO tags (B-TYPE, I-TYPE, O)
A6: Split Protocol | B6: Train / Eval Ratio | C6: 70% / 30%
A7: Split Protocol | B7: Split Granularity | C7: Sentence-level (no token leakage)
A8: Split Protocol | B8: Seeds | C8: 5 independent random seeds (42–46)
A9: Split Protocol | B9: Stratification | C9: Non-O label distribution preserved via greedy optimisation
A10: Model | B10: Base Model | C10: DictaBERT (dicta-il/dictabert)
A11: Model | B11: Language | C11: Hebrew
A12: Evaluation | B12: Primary Metric | C12: Entity-level F1 (seqeval strict)
... A38: Sheets | B38: documentation | C38: This sheet — describes columns and interpretation guidelines

Sheet all_runs
A1: model_key | B1: model_id | C1: model_name | D1: experiment_id | E1: experiment_name | F1: data_source | G1: condition_key | H1: condition_group_key | I1: condition_group_short | J1: condition_label | K1: condition_short | L1: condition_description | M1: seed | N1: is_baseline | O1: f1 | P1: precision | Q1: recall | R1: status | S1: result_file | T1: metrics_file | U1: base_artifacts_reused | V1: base_mode | W1: elapsed_seconds
A2: dictabert | B2: dicta-il/dictabert | C2: DictaBERT | D2: exp01 | E2: Regular NER | F2: exp07 | G2: exp07_before_exp01_baseline__seed42 | H2: exp07_before_exp01_baseline | I2: Baseline (simple random split) | J2: [Exp07] Baseline (simple random split) [seed 42] | K2: Baseline (simple random split) [s42] | L2: Regular NER with DictaBERT | M2: 42 | N2: TRUE | O2: 0.7188755 | P2: 0.66791045 | Q2: 0.77826087 | R2: ok | S2: /content/drive/MyDrive/thesis_project/thesis/outputs/exp01/regular_ner_20260601_205916.json | T2: /content/drive/MyDrive/thesis_project/thesis/outputs/exp01/regular_ner_results_20260601_205916.xlsx | U2: FALSE | V2: auto | W2: 69.6
A3: dictabert | B3: dicta-il/dictabert | C3: DictaBERT | D3: exp01 | E3: Regular NER | F3: exp07 | G3: exp07_after_label_aware_split__seed42 | H3: exp07_after_label_aware_split | I3: Label-aware greedy | J3: [Exp07] Label-aware greedy [seed 42] | K3: Label-aware greedy [s42] | L3: Statistical stratified sentence split preserving non-O label distribution (with best-effort train coverage) | M3: 42 | N3: FALSE | O3: 0.75409836 | P3: 0.70050761 | Q3: 0.81656805 | R3: ok | S3: /content/drive/MyDrive/thesis_project/thesis/outputs/exp01/regular_ner_20260601_213924.json | T3: /content/drive/MyDrive/thesis_project/thesis/outputs/exp01/regular_ner_results_20260601_213924.xlsx | U3: FALSE | V3: auto | W3: 65.4
A4: dictabert | B4: dicta-il/dictabert | C4: DictaBERT | D4: exp01 | E4: Regular NER | F4: exp07 | G4: exp07_after_multilabel_iterative_paper__seed42 | H4: exp07_after_multilabel_iterative_paper | I4: Multilabel stratified (paper-style) | J4: [Exp07] Multilabel stratified (paper-style) [seed 42] | K4: Multilabel stratified (paper-style) [s42] | L4: Paper-style iterative stratification: rarest-label-first with tie-breaks by per-label need, then fold capacity, then random | M4: 42 | N4: FALSE | O4: 0.73799127 | P4: 0.71610169 | Q4: 0.76126126 | R4: ok | S4: /content/drive/MyDrive/thesis_project/thesis/outputs/exp01/regular_ner_20260601_220032.json | T4: /content/drive/MyDrive/thesis_project/thesis/outputs/exp01/regular_ner_results_20260601_220031.xlsx | U4: FALSE | V4: auto | W4: 67.3
A5: dictabert | B5: dicta-il/dictabert | C5: DictaBERT | D5: exp01 | E5: Regular NER | F5: exp07+aug | G5: exp07aug_before_exp01_baseline__seed42 | H5: exp07aug_before_exp01_baseline | I5: Baseline (simple random split) + Aug | J5: [Exp07+Aug] Baseline (simple random split) + Augmented [seed 42] | K5: Baseline (simple random split) + Aug [s42] | L5: Regular NER with DictaBERT + LLM mask-fill augmentation | M5: 42 | N5: FALSE | O5: 0.8 | P5: 0.768 | Q5: 0.83478261 | R5: ok | S5: /content/drive/MyDrive/thesis_project/thesis/outputs/exp01/regular_ner_20260601_222439.json | T5: /content/drive/MyDrive/thesis_project/thesis/outputs/exp01/regular_ner_results_20260601_222439.xlsx | U5: FALSE | V5: auto | W5: 327.9
A6: dictabert | B6: dicta-il/dictabert | C6: DictaBERT | D6: exp01 | E6: Regular NER | F6: exp07+aug | G6: exp07aug_after_label_aware_split__seed42 | H6: exp07aug_after_label_aware_split | I6: Label-aware greedy + Aug | J6: [Exp07+Aug] Label-aware greedy + Augmented [seed 42] | K6: Label-aware greedy + Aug [s42] | L6: Statistical stratified sentence split preserving non-O label distribution (with best-effort train coverage) + LLM mask-fill augmentation | M6: 42 | N6: FALSE | O6: 0.79886686 | P6: 0.76630435 | Q6: 0.83431953 | R6: ok | S6: /content/drive/MyDrive/thesis_project/thesis/outputs/exp01/regular_ner_20260602_000257.json | T6: /content/drive/MyDrive/thesis_project/thesis/outputs/exp01/regular_ner_results_20260602_000257.xlsx | U6: FALSE | V6: auto | W6: 329.6
A7: dictabert | B7: dicta-il/dictabert | C7: DictaBERT | D7: exp01 | E7: Regular NER | F7: exp07+aug | G7: exp07aug_after_multilabel_iterative_paper__seed42 | H7: exp07aug_after_multilabel_iterative_paper | I7: Multilabel stratified (paper-style) + Aug | J7: [Exp07+Aug] Multilabel stratified (paper-style) + Augmented [seed 42] | K7: Multilabel stratified (paper-style) + Aug [s42] | L7: Paper-style iterative stratification: rarest-label-first with tie-breaks by per-label need, then fold capacity, then random + LLM mask-fill augmentation | M7: 42 | N7: FALSE | O7: 0.78761062 | P7: 0.77391304 | Q7: 0.8018018 | R7: ok | S7: /content/drive/MyDrive/thesis_project/thesis/outputs/exp01/regular_ner_20260602_134226.json | T7: /content/drive/MyDrive/thesis_project/thesis/outputs/exp01/regular_ner_results_20260602_134225.xlsx | U7: FALSE | V7: auto | W7: 234.9
A8: dictabert | B8: dicta-il/dictabert | C8: DictaBERT | D8: exp01 | E8: Regular NER | F8: exp07 | G8: exp07_before_exp01_baseline__seed43 | H8: exp07_before_exp01_baseline | I8: Baseline (simple random split) | J8: [Exp07] Baseline (simple random split) [seed 43] | K8: Baseline (simple random split) [s43] | L8: Regular NER with DictaBERT | M8: 43 | N8: TRUE | O8: 0.66933868 | P8: 0.62081784 | Q8: 0.72608696 | R8: ok | S8: /content/drive/MyDrive/thesis_project/thesis/outputs/exp01/regular_ner_20260601_210114.json | T8: /content/drive/MyDrive/thesis_project/thesis/outputs/exp01/regular_ner_results_20260601_210104.xlsx | U8: FALSE | V8: auto | W8: 119.2
A9: dictabert | B9: dicta-il/dictabert | C9: DictaBERT | D9: exp01 | E9: Regular NER | F9: exp07 | G9: exp07_after_label_aware_split__seed43 | H9: exp07_after_label_aware_split | I9: Label-aware greedy | J9: [Exp07] Label-aware greedy [seed 43] | K9: Label-aware greedy [s43] | L9: Statistical stratified sentence split preserving non-O label distribution (with best-effort train coverage) | M9: 43 | N9: FALSE | O9: 0.75409836 | P9: 0.70050761 | Q9: 0.81656805 | R9: ok | S9: /content/drive/MyDrive/thesis_project/thesis/outputs/exp01/regular_ner_20260601_214028.json | T9: /content/drive/MyDrive/thesis_project/thesis/outputs/exp01/regular_ner_results_20260601_214028.xlsx | U9: FALSE | V9: auto | W9: 64.4
A10: dictabert | B10: dicta-il/dictabert | C10: DictaBERT | D10: exp01 | E10: Regular NER | F10: exp07 | G10: exp07_after_multilabel_iterative_paper__seed43 | H10: exp07_after_multilabel_iterative_paper | I10: Multilabel stratified (paper-style) | J10: [Exp07] Multilabel stratified (paper-style) [seed 43] | K10: Multilabel stratified (paper-style) [s43] | L10: Paper-style iterative stratification: rarest-label-first with tie-breaks by per-label need, then fold capacity, then random | M10: 43 | N10: FALSE | O10: 0.73799127 | P10: 0.71610169 | Q10: 0.76126126 | R10: ok | S10: /content/drive/MyDrive/thesis_project/thesis/outputs/exp01/regular_ner_20260601_220137.json | T10: /content/drive/MyDrive/thesis_project/thesis/outputs/exp01/regular_ner_results_20260601_220137.xlsx | U10: FALSE | V10: auto | W10: 64.6
A11: dictabert | B11: dicta-il/dictabert | C11: DictaBERT | D11: exp01 | E11: Regular NER | F11: exp07+aug | G11: exp07aug_before_exp01_baseline__seed43 | H11: exp07aug_before_exp01_baseline | I11: Baseline (simple random split) + Aug | J11: [Exp07+Aug] Baseline (simple random split) + Augmented [seed 43] | K11: Baseline (simple random split) + Aug [s43] | L11: Regular NER with DictaBERT + LLM mask-fill augmentation | M11: 43 | N11: FALSE | O11: 0.78131635 | P11: 0.76348548 | Q11: 0.8 | R11: ok | S11: /content/drive/MyDrive/thesis_project/thesis/outputs/exp01/regular_ner_20260601_223008.json | T11: /content/drive/MyDrive/thesis_project/thesis/outputs/exp01/regular_ner_results_20260601_223008.xlsx | U11: FALSE | V11: auto | W11: 274.5
A12: dictabert | B12: dicta-il/dictabert | C12: DictaBERT | D12: exp01 | E12: Regular NER | F12: exp07+aug | G12: exp07aug_after_label_aware_split__seed43 | H12: exp07aug_after_label_aware_split | I12: Label-aware greedy + Aug | J12: [Exp07+Aug] Label-aware greedy + Augmented [seed 43] | K12: Label-aware greedy + Aug [s43] | L12: Statistical stratified sentence split preserving non-O label distribution (with best-effort train coverage) + LLM mask-fill augmentation | M12: 43 | N12: FALSE | O12: 0.80112045 | P12: 0.7606383 | Q12: 0.84615385 | R12: ok | S12: /content/drive/MyDrive/thesis_project/thesis/outputs/exp01/regular_ner_20260602_000824.json | T12: /content/drive/MyDrive/thesis_project/thesis/outputs/exp01/regular_ner_results_20260602_000824.xlsx | U12: FALSE | V12: auto | W12: 267.8
A13: dictabert | B13: dicta-il/dictabert | C13: DictaBERT | D13: exp01 | E13: Regular NER | F13: exp07+aug | G13: exp07aug_after_multilabel_iterative_paper__seed43 | H13: exp07aug_after_multilabel_iterative_paper | I13: Multilabel stratified (paper-style) + Aug | J13: [Exp07+Aug] Multilabel stratified (paper-style) + Augmented [seed 43] | K13: Multilabel stratified (paper-style) + Aug [s43] | L13: Paper-style iterative stratification: rarest-label-first with tie-breaks by per-label need, then fold capacity, then random + LLM mask-fill augmentation | M13: 43 | N13: FALSE | O13: 0.79111111 | P13: 0.78070175 | Q13: 0.8018018 | R13: ok | S13: /content/drive/MyDrive/thesis_project/thesis/outputs/exp01/regular_ner_20260602_134620.json | T13: /content/drive/MyDrive/thesis_project/thesis/outputs/exp01/regular_ner_results_20260602_134620.xlsx | U13: FALSE | V13: auto | W13: 263
... A121: dictabert | B121: dicta-il/dictabert | C121: DictaBERT | D121: exp01 | E121: Regular NER | F121: exp07+aug | G121: exp07aug_after_multilabel_iterative_paper__seed61 | H121: exp07aug_after_multilabel_iterative_paper | I121: Multilabel stratified (paper-style) + Aug | J121: [Exp07+Aug] Multilabel stratified (paper-style) + Augmented [seed 61] | K121: Multilabel stratified (paper-style) + Aug [s61] | L121: Paper-style iterative stratification: rarest-label-first with tie-breaks by per-label need, then fold capacity, then random + LLM mask-fill augmentation | M121: 61 | N121: FALSE | O121: 0.80525164 | P121: 0.78297872 | Q121: 0.82882883 | R121: ok | S121: /content/drive/MyDrive/thesis_project/thesis/outputs/exp01/regular_ner_20260602_202416.json | T121: /content/drive/MyDrive/thesis_project/thesis/outputs/exp01/regular_ner_results_20260602_202416.xlsx | U121: FALSE | V121: auto | W121: 263.7
A122: dictabert | B122: dicta-il/dictabert | C122: DictaBERT | D122: exp04 | E122: AUC Cascaded Pipeline | F122: exp07 | G122: exp07_before_exp01_baseline__seed42 | H122: exp07_before_exp01_baseline | I122: Baseline (simple random split) | J122: [Exp07] Baseline (simple random split) [seed 42] | K122: Baseline (simple random split) [s42] | L122: Regular NER with DictaBERT | M122: 42 | N122: TRUE | O122: 0.74895397 | R122: ok_reused_base | S122: /content/drive/MyDrive/thesis_project/thesis/outputs/exp04/auc_cascaded_pipeline_20260601_210001.json | T122: /content/drive/MyDrive/thesis_project/thesis/outputs/exp04/cascaded_pipeline_results_20260601_210000.xlsx | U122: TRUE | V122: auto | W122: 0.6
A123: dictabert | B123: dicta-il/dictabert | C123: DictaBERT | D123: exp04 | E123: AUC Cascaded Pipeline | F123: exp07 | G123: exp07_before_exp01_baseline__seed43 | H123: exp07_before_exp01_baseline | I123: Baseline (simple random split) | J123: [Exp07] Baseline (simple random split) [seed 43] | K123: Baseline (simple random split) [s43] | L123: Regular NER with DictaBERT | M123: 43 | N123: TRUE | O123: 0.71910112 | R123: ok_reused_base | S123: /content/drive/MyDrive/thesis_project/thesis/outputs/exp04/auc_cascaded_pipeline_20260601_210200.json | T123: /content/drive/MyDrive/thesis_project/thesis/outputs/exp04/cascaded_pipeline_results_20260601_210159.xlsx | U123: TRUE | V123: auto | W123: 1
A124: dictabert | B124: dicta-il/dictabert | C124: DictaBERT | D124: exp04 | E124: AUC Cascaded Pipeline | F124: exp07 | G124: exp07_before_exp01_baseline__seed44 | H124: exp07_before_exp01_baseline | I124: Baseline (simple random split) | J124: [Exp07] Baseline (simple random split) [seed 44] | K124: Baseline (simple random split) [s44] | L124: Regular NER with DictaBERT | M124: 44 | N124: TRUE | O124: 0.70229008 | R124: ok_reused_base | S124: /content/drive/MyDrive/thesis_project/thesis/outputs/exp04/auc_cascaded_pipeline_20260601_210439.json | T124: /content/drive/MyDrive/thesis_project/thesis/outputs/exp04/cascaded_pipeline_results_20260601_210438.xlsx | U124: TRUE | V124: auto | W124: 0.7
A125: dictabert | B125: dicta-il/dictabert | C125: DictaBERT | D125: exp04 | E125: AUC Cascaded Pipeline | F125: exp07 | G125: exp07_before_exp01_baseline__seed45 | H125: exp07_before_exp01_baseline | I125: Baseline (simple random split) | J125: [Exp07] Baseline (simple random split) [seed 45] | K125: Baseline (simple random split) [s45] | L125: Regular NER with DictaBERT | M125: 45 | N125: TRUE | O125: 0.72881356 | R125: ok_reused_base | S125: /content/drive/MyDrive/thesis_project/thesis/outputs/exp04/auc_cascaded_pipeline_20260601_210715.json | T125: /content/drive/MyDrive/thesis_project/thesis/outputs/exp04/cascaded_pipeline_results_20260601_210714.xlsx | U125: TRUE | V125: auto | W125: 1
A126: dictabert | B126: dicta-il/dictabert | C126: DictaBERT | D126: exp04 | E126: AUC Cascaded Pipeline | F126: exp07 | G126: exp07_before_exp01_baseline__seed46 | H126: exp07_before_exp01_baseline | I126: Baseline (simple random split) | J126: [Exp07] Baseline (simple random split) [seed 46] | K126: Baseline (simple random split) [s46] | L126: Regular NER with DictaBERT | M126: 46 | N126: TRUE | O126: 0.69767442 | R126: ok_reused_base | S126: /content/drive/MyDrive/thesis_project/thesis/outputs/exp04/auc_cascaded_pipeline_20260601_211002.json | T126: /content/drive/MyDrive/thesis_project/thesis/outputs/exp04/cascaded_pipeline_results_20260601_211001.xlsx | U126: TRUE | V126: auto | W126: 0.7
A127: dictabert | B127: dicta-il/dictabert | C127: DictaBERT | D127: exp04 | E127: AUC Cascaded Pipeline | F127: exp07 | G127: exp07_before_exp01_baseline__seed47 | H127: exp07_before_exp01_baseline | I127: Baseline (simple random split) | J127: [Exp07] Baseline (simple random split) [seed 47] | K127: Baseline (simple random split) [s47] | L127: Regular NER with DictaBERT | M127: 47 | N127: TRUE | O127: 0.75527426 | R127: ok_reused_base | S127: /content/drive/MyDrive/thesis_project/thesis/outputs/exp04/auc_cascaded_pipeline_20260601_211301.json | T127: /content/drive/MyDrive/thesis_project/thesis/outputs/exp04/cascaded_pipeline_results_20260601_211251.xlsx | U127: TRUE | V127: auto | W127: 1
A128: dictabert | B128: dicta-il/dictabert | C128: DictaBERT | D128: exp04 | E128: AUC Cascaded Pipeline | F128: exp07 | G128: exp07_before_exp01_baseline__seed48 | H128: exp07_before_exp01_baseline | I128: Baseline (simple random split) | J128: [Exp07] Baseline (simple random split) [seed 48] | K128: Baseline (simple random split) [s48] | L128: Regular NER with DictaBERT | M128: 48 | N128: TRUE | O128: 0.73221757 | R128: ok_reused_base | S128: /content/drive/MyDrive/thesis_project/thesis/outputs/exp04/auc_cascaded_pipeline_20260601_211546.json | T128: /content/drive/MyDrive/thesis_project/thesis/outputs/exp04/cascaded_pipeline_results_20260601_211536.xlsx | U128: TRUE | V128: auto | W128: 0.8
